{
    "registryname": "Ultimate_zhongzi",
    "localizedname": "终极中子收集器",
    "failure-action": "still",
    "requires-blueprint": false,
    "color": "A9A9A9",
        "parts": [
            {
                "x": -1,
                "y": 0,
                "z": 0,
                "elements": [
                    "mekanism:reinforcedplasticblock@7"
                ]
            },
            {
                "x": 0,
                "y": 0,
                "z": 0,
                "elements": [
                    "modularmachinery:blockcontroller@2"
                ]
            },
            {
                "x": 3,
                "y": 6,
                "z": 3,
                "elements": [
                    "thermalfoundation:glass@7"
                ]
            },
            {
                "x": -2,
                "y": 0,
                "z": 0,
                "elements": [
                    "mekanism:reinforcedplasticblock@7"
                ]
            },
            {
                "x": 1,
                "y": 0,
                "z": 0,
                "elements": [
                    "mekanism:reinforcedplasticblock@7"
                ]
            },
            {
                "x": 4,
                "y": 6,
                "z": 3,
                "elements": [
                    "mekanism:reinforcedplasticblock@7"
                ]
            },
            {
                "x": -3,
                "y": 0,
                "z": 0,
                "elements": [
                    "mekanism:reinforcedplasticblock@7"
                ]
            },
            {
                "x": 2,
                "y": 0,
                "z": 0,
                "elements": [
                    "mekanism:reinforcedplasticblock@7"
                ]
            },
            {
                "x": 4,
                "y": 4,
                "z": 2,
                "elements": [
                    "minecraft:iron_bars@0"
                ]
            },
            {
                "x": -4,
                "y": 0,
                "z": 0,
                "elements": [
                    "mekanism:reinforcedplasticblock@7"
                ]
            },
            {
                "x": 3,
                "y": 0,
                "z": 0,
                "elements": [
                    "mekanism:reinforcedplasticblock@7"
                ]
            },
            {
                "x": 4,
                "y": 2,
                "z": 1,
                "elements": [
                    "minecraft:iron_bars@0"
                ]
            },
            {
                "x": 4,
                "y": 0,
                "z": 0,
                "elements": [
                    "mekanism:reinforcedplasticblock@7"
                ]
            },
            {
                "x": -4,
                "y": 5,
                "z": 2,
                "elements": [
                    "minecraft:iron_bars@0"
                ]
            },
            {
                "x": -4,
                "y": 3,
                "z": 1,
                "elements": [
                    "minecraft:iron_bars@0"
                ]
            },
            {
                "x": -4,
                "y": 1,
                "z": 0,
                "elements": [
                    "mekanism:reinforcedplasticblock@7"
                ]
            },
            {
                "x": -3,
                "y": 1,
                "z": 0,
                "elements": [
                    "minecraft:iron_bars@0"
                ]
            },
            {
                "x": -2,
                "y": 1,
                "z": 0,
                "elements": [
                    "minecraft:iron_bars@0"
                ]
            },
            {
                "x": 0,
                "y": 5,
                "z": 2,
                "elements": [
                    "minecraft:purpur_pillar@0"
                ]
            },
            {
                "x": -1,
                "y": 1,
                "z": 0,
                "elements": [
                    "minecraft:iron_bars@0"
                ]
            },
            {
                "x": 0,
                "y": 1,
                "z": 0,
                "elements": [
                    "avaritia:block_resource@2"
                ]
            },
            {
                "x": 1,
                "y": 1,
                "z": 0,
                "elements": [
                    "minecraft:iron_bars@0"
                ]
            },
            {
                "x": 2,
                "y": 1,
                "z": 0,
                "elements": [
                    "minecraft:iron_bars@0"
                ]
            },
            {
                "x": 4,
                "y": 5,
                "z": 2,
                "elements": [
                    "minecraft:iron_bars@0"
                ]
            },
            {
                "x": 3,
                "y": 1,
                "z": 0,
                "elements": [
                    "minecraft:iron_bars@0"
                ]
            },
            {
                "x": 4,
                "y": 3,
                "z": 1,
                "elements": [
                    "minecraft:iron_bars@0"
                ]
            },
            {
                "x": 4,
                "y": 1,
                "z": 0,
                "elements": [
                    "mekanism:reinforcedplasticblock@7"
                ]
            },
            {
                "x": -4,
                "y": 6,
                "z": 2,
                "elements": [
                    "mekanism:reinforcedplasticblock@7"
                ]
            },
            {
                "x": -4,
                "y": 4,
                "z": 1,
                "elements": [
                    "minecraft:iron_bars@0"
                ]
            },
            {
                "x": -3,
                "y": 6,
                "z": 2,
                "elements": [
                    "thermalfoundation:glass@7"
                ]
            },
            {
                "x": -4,
                "y": 2,
                "z": 0,
                "elements": [
                    "mekanism:reinforcedplasticblock@7"
                ]
            },
            {
                "x": -2,
                "y": 6,
                "z": 2,
                "elements": [
                    "thermalfoundation:glass@7"
                ]
            },
            {
                "x": -3,
                "y": 2,
                "z": 0,
                "elements": [
                    "minecraft:iron_bars@0"
                ]
            },
            {
                "x": -1,
                "y": 6,
                "z": 2,
                "elements": [
                    "thermalfoundation:glass@7"
                ]
            },
            {
                "x": -2,
                "y": 2,
                "z": 0,
                "elements": [
                    "minecraft:iron_bars@0"
                ]
            },
            {
                "x": 0,
                "y": 6,
                "z": 2,
                "elements": [
                    "tconstruct:metal@0"
                ]
            },
            {
                "x": -1,
                "y": 2,
                "z": 0,
                "elements": [
                    "minecraft:iron_bars@0"
                ]
            },
            {
                "x": 1,
                "y": 6,
                "z": 2,
                "elements": [
                    "thermalfoundation:glass@7"
                ]
            },
            {
                "x": 0,
                "y": 2,
                "z": 0,
                "elements": [
                    "avaritia:block_resource@0"
                ]
            },
            {
                "x": 2,
                "y": 6,
                "z": 2,
                "elements": [
                    "thermalfoundation:glass@7"
                ]
            },
            {
                "x": 1,
                "y": 2,
                "z": 0,
                "elements": [
                    "minecraft:iron_bars@0"
                ]
            },
            {
                "x": 3,
                "y": 6,
                "z": 2,
                "elements": [
                    "thermalfoundation:glass@7"
                ]
            },
            {
                "x": 2,
                "y": 2,
                "z": 0,
                "elements": [
                    "minecraft:iron_bars@0"
                ]
            },
            {
                "x": 4,
                "y": 6,
                "z": 2,
                "elements": [
                    "mekanism:reinforcedplasticblock@7"
                ]
            },
            {
                "x": 3,
                "y": 2,
                "z": 0,
                "elements": [
                    "minecraft:iron_bars@0"
                ]
            },
            {
                "x": 4,
                "y": 4,
                "z": 1,
                "elements": [
                    "minecraft:iron_bars@0"
                ]
            },
            {
                "x": 4,
                "y": 2,
                "z": 0,
                "elements": [
                    "mekanism:reinforcedplasticblock@7"
                ]
            },
            {
                "x": -4,
                "y": 0,
                "z": 15,
                "elements": [
                    "mekanism:reinforcedplasticblock@7"
                ]
            },
            {
                "x": -3,
                "y": 0,
                "z": 15,
                "elements": [
                    "mekanism:reinforcedplasticblock@7"
                ]
            },
            {
                "x": -2,
                "y": 0,
                "z": 15,
                "elements": [
                    "mekanism:reinforcedplasticblock@7"
                ]
            },
            {
                "x": -1,
                "y": 0,
                "z": 15,
                "elements": [
                    "mekanism:reinforcedplasticblock@7"
                ]
            },
            {
                "x": 0,
                "y": 0,
                "z": 15,
                "elements": [
                    "mekanism:reinforcedplasticblock@7"
                ]
            },
            {
                "x": 1,
                "y": 0,
                "z": 15,
                "elements": [
                    "mekanism:reinforcedplasticblock@7"
                ]
            },
            {
                "x": 2,
                "y": 0,
                "z": 15,
                "elements": [
                    "mekanism:reinforcedplasticblock@7"
                ]
            },
            {
                "x": 3,
                "y": 0,
                "z": 15,
                "elements": [
                    "mekanism:reinforcedplasticblock@7"
                ]
            },
            {
                "x": 4,
                "y": 0,
                "z": 15,
                "elements": [
                    "mekanism:reinforcedplasticblock@7"
                ]
            },
            {
                "x": -4,
                "y": 5,
                "z": 1,
                "elements": [
                    "minecraft:iron_bars@0"
                ]
            },
            {
                "x": -4,
                "y": 3,
                "z": 0,
                "elements": [
                    "avaritia:block_resource@2"
                ]
            },
            {
                "x": -3,
                "y": 3,
                "z": 0,
                "elements": [
                    "avaritia:block_resource@0"
                ]
            },
            {
                "x": -2,
                "y": 3,
                "z": 0,
                "elements": [
                    "avaritia:block_resource@0"
                ]
            },
            {
                "x": -1,
                "y": 3,
                "z": 0,
                "elements": [
                    "avaritia:block_resource@0"
                ]
            },
            {
                "x": 0,
                "y": 3,
                "z": 0,
                "elements": [
                    "modularmachinery:blockoutputbus"
                ]
            },
            {
                "x": 1,
                "y": 3,
                "z": 0,
                "elements": [
                    "avaritia:block_resource@0"
                ]
            },
            {
                "x": 2,
                "y": 3,
                "z": 0,
                "elements": [
                    "avaritia:block_resource@0"
                ]
            },
            {
                "x": 3,
                "y": 3,
                "z": 0,
                "elements": [
                    "avaritia:block_resource@0"
                ]
            },
            {
                "x": 4,
                "y": 5,
                "z": 1,
                "elements": [
                    "minecraft:iron_bars@0"
                ]
            },
            {
                "x": 4,
                "y": 3,
                "z": 0,
                "elements": [
                    "avaritia:block_resource@2"
                ]
            },
            {
                "x": -4,
                "y": 1,
                "z": 15,
                "elements": [
                    "mekanism:reinforcedplasticblock@7"
                ]
            },
            {
                "x": -3,
                "y": 1,
                "z": 15,
                "elements": [
                    "minecraft:iron_bars@0"
                ]
            },
            {
                "x": -2,
                "y": 1,
                "z": 15,
                "elements": [
                    "minecraft:iron_bars@0"
                ]
            },
            {
                "x": -1,
                "y": 1,
                "z": 15,
                "elements": [
                    "minecraft:iron_bars@0"
                ]
            },
            {
                "x": 0,
                "y": 1,
                "z": 15,
                "elements": [
                    "minecraft:iron_bars@0"
                ]
            },
            {
                "x": 1,
                "y": 1,
                "z": 15,
                "elements": [
                    "minecraft:iron_bars@0"
                ]
            },
            {
                "x": 2,
                "y": 1,
                "z": 15,
                "elements": [
                    "minecraft:iron_bars@0"
                ]
            },
            {
                "x": 3,
                "y": 1,
                "z": 15,
                "elements": [
                    "minecraft:iron_bars@0"
                ]
            },
            {
                "x": 4,
                "y": 1,
                "z": 15,
                "elements": [
                    "mekanism:reinforcedplasticblock@7"
                ]
            },
            {
                "x": -4,
                "y": 6,
                "z": 1,
                "elements": [
                    "mekanism:reinforcedplasticblock@7"
                ]
            },
            {
                "x": -4,
                "y": 4,
                "z": 0,
                "elements": [
                    "mekanism:reinforcedplasticblock@7"
                ]
            },
            {
                "x": -3,
                "y": 6,
                "z": 1,
                "elements": [
                    "thermalfoundation:glass@7"
                ]
            },
            {
                "x": -3,
                "y": 4,
                "z": 0,
                "elements": [
                    "minecraft:iron_bars@0"
                ]
            },
            {
                "x": -2,
                "y": 6,
                "z": 1,
                "elements": [
                    "thermalfoundation:glass@7"
                ]
            },
            {
                "x": -2,
                "y": 4,
                "z": 0,
                "elements": [
                    "minecraft:iron_bars@0"
                ]
            },
            {
                "x": -1,
                "y": 6,
                "z": 1,
                "elements": [
                    "thermalfoundation:glass@7"
                ]
            },
            {
                "x": -1,
                "y": 4,
                "z": 0,
                "elements": [
                    "minecraft:iron_bars@0"
                ]
            },
            {
                "x": 0,
                "y": 6,
                "z": 1,
                "elements": [
                    "tconstruct:metal@0"
                ]
            },
            {
                "x": 0,
                "y": 4,
                "z": 0,
                "elements": [
                    "avaritia:block_resource@0"
                ]
            },
            {
                "x": 1,
                "y": 6,
                "z": 1,
                "elements": [
                    "thermalfoundation:glass@7"
                ]
            },
            {
                "x": 1,
                "y": 4,
                "z": 0,
                "elements": [
                    "minecraft:iron_bars@0"
                ]
            },
            {
                "x": 2,
                "y": 6,
                "z": 1,
                "elements": [
                    "thermalfoundation:glass@7"
                ]
            },
            {
                "x": 2,
                "y": 4,
                "z": 0,
                "elements": [
                    "minecraft:iron_bars@0"
                ]
            },
            {
                "x": 3,
                "y": 6,
                "z": 1,
                "elements": [
                    "thermalfoundation:glass@7"
                ]
            },
            {
                "x": 3,
                "y": 4,
                "z": 0,
                "elements": [
                    "minecraft:iron_bars@0"
                ]
            },
            {
                "x": 4,
                "y": 6,
                "z": 1,
                "elements": [
                    "mekanism:reinforcedplasticblock@7"
                ]
            },
            {
                "x": 4,
                "y": 4,
                "z": 0,
                "elements": [
                    "mekanism:reinforcedplasticblock@7"
                ]
            },
            {
                "x": -4,
                "y": 2,
                "z": 15,
                "elements": [
                    "mekanism:reinforcedplasticblock@7"
                ]
            },
            {
                "x": -4,
                "y": 0,
                "z": 14,
                "elements": [
                    "mekanism:reinforcedplasticblock@7"
                ]
            },
            {
                "x": -3,
                "y": 2,
                "z": 15,
                "elements": [
                    "minecraft:iron_bars@0"
                ]
            },
            {
                "x": -3,
                "y": 0,
                "z": 14,
                "elements": [
                    "minecraft:stained_hardened_clay@7"
                ]
            },
            {
                "x": -2,
                "y": 2,
                "z": 15,
                "elements": [
                    "minecraft:iron_bars@0"
                ]
            },
            {
                "x": -2,
                "y": 0,
                "z": 14,
                "elements": [
                    "minecraft:stained_hardened_clay@7"
                ]
            },
            {
                "x": -1,
                "y": 2,
                "z": 15,
                "elements": [
                    "minecraft:iron_bars@0"
                ]
            },
            {
                "x": -1,
                "y": 0,
                "z": 14,
                "elements": [
                    "minecraft:stained_hardened_clay@15"
                ]
            },
            {
                "x": 0,
                "y": 2,
                "z": 15,
                "elements": [
                    "minecraft:iron_bars@0"
                ]
            },
            {
                "x": 0,
                "y": 0,
                "z": 14,
                "elements": [
                    "tconstruct:metal@0"
                ]
            },
            {
                "x": 1,
                "y": 2,
                "z": 15,
                "elements": [
                    "minecraft:iron_bars@0"
                ]
            },
            {
                "x": 1,
                "y": 0,
                "z": 14,
                "elements": [
                    "minecraft:stained_hardened_clay@15"
                ]
            },
            {
                "x": 2,
                "y": 2,
                "z": 15,
                "elements": [
                    "minecraft:iron_bars@0"
                ]
            },
            {
                "x": 2,
                "y": 0,
                "z": 14,
                "elements": [
                    "minecraft:stained_hardened_clay@7"
                ]
            },
            {
                "x": 3,
                "y": 2,
                "z": 15,
                "elements": [
                    "minecraft:iron_bars@0"
                ]
            },
            {
                "x": 3,
                "y": 0,
                "z": 14,
                "elements": [
                    "minecraft:stained_hardened_clay@7"
                ]
            },
            {
                "x": 4,
                "y": 2,
                "z": 15,
                "elements": [
                    "mekanism:reinforcedplasticblock@7"
                ]
            },
            {
                "x": 4,
                "y": 0,
                "z": 14,
                "elements": [
                    "mekanism:reinforcedplasticblock@7"
                ]
            },
            {
                "x": -4,
                "y": 5,
                "z": 0,
                "elements": [
                    "mekanism:reinforcedplasticblock@7"
                ]
            },
            {
                "x": -3,
                "y": 5,
                "z": 0,
                "elements": [
                    "minecraft:iron_bars@0"
                ]
            },
            {
                "x": -2,
                "y": 5,
                "z": 0,
                "elements": [
                    "minecraft:iron_bars@0"
                ]
            },
            {
                "x": -1,
                "y": 5,
                "z": 0,
                "elements": [
                    "minecraft:iron_bars@0"
                ]
            },
            {
                "x": 0,
                "y": 5,
                "z": 0,
                "elements": [
                    "avaritia:block_resource@2"
                ]
            },
            {
                "x": 1,
                "y": 5,
                "z": 0,
                "elements": [
                    "minecraft:iron_bars@0"
                ]
            },
            {
                "x": 2,
                "y": 5,
                "z": 0,
                "elements": [
                    "minecraft:iron_bars@0"
                ]
            },
            {
                "x": 3,
                "y": 5,
                "z": 0,
                "elements": [
                    "minecraft:iron_bars@0"
                ]
            },
            {
                "x": 4,
                "y": 5,
                "z": 0,
                "elements": [
                    "mekanism:reinforcedplasticblock@7"
                ]
            },
            {
                "x": -4,
                "y": 3,
                "z": 15,
                "elements": [
                    "mekanism:reinforcedplasticblock@7"
                ]
            },
            {
                "x": -4,
                "y": 1,
                "z": 14,
                "elements": [
                    "minecraft:iron_bars@0"
                ]
            },
            {
                "x": -3,
                "y": 3,
                "z": 15,
                "elements": [
                    "minecraft:iron_bars@0"
                ]
            },
            {
                "x": -2,
                "y": 3,
                "z": 15,
                "elements": [
                    "minecraft:iron_bars@0"
                ]
            },
            {
                "x": -1,
                "y": 3,
                "z": 15,
                "elements": [
                    "minecraft:iron_bars@0"
                ]
            },
            {
                "x": 0,
                "y": 3,
                "z": 15,
                "elements": [
                    "minecraft:iron_bars@0"
                ]
            },
            {
                "x": 1,
                "y": 3,
                "z": 15,
                "elements": [
                    "minecraft:iron_bars@0"
                ]
            },
            {
                "x": 2,
                "y": 3,
                "z": 15,
                "elements": [
                    "minecraft:iron_bars@0"
                ]
            },
            {
                "x": 3,
                "y": 3,
                "z": 15,
                "elements": [
                    "minecraft:iron_bars@0"
                ]
            },
            {
                "x": 4,
                "y": 3,
                "z": 15,
                "elements": [
                    "mekanism:reinforcedplasticblock@7"
                ]
            },
            {
                "x": 4,
                "y": 1,
                "z": 14,
                "elements": [
                    "minecraft:iron_bars@0"
                ]
            },
            {
                "x": -4,
                "y": 6,
                "z": 0,
                "elements": [
                    "mekanism:reinforcedplasticblock@7"
                ]
            },
            {
                "x": -3,
                "y": 6,
                "z": 0,
                "elements": [
                    "mekanism:reinforcedplasticblock@7"
                ]
            },
            {
                "x": -2,
                "y": 6,
                "z": 0,
                "elements": [
                    "mekanism:reinforcedplasticblock@7"
                ]
            },
            {
                "x": -1,
                "y": 6,
                "z": 0,
                "elements": [
                    "mekanism:reinforcedplasticblock@7"
                ]
            },
            {
                "x": 0,
                "y": 6,
                "z": 0,
                "elements": [
                    "gugu-utils:environmenthatch@0"
                ]
            },
            {
                "x": 1,
                "y": 6,
                "z": 0,
                "elements": [
                    "mekanism:reinforcedplasticblock@7"
                ]
            },
            {
                "x": 2,
                "y": 6,
                "z": 0,
                "elements": [
                    "mekanism:reinforcedplasticblock@7"
                ]
            },
            {
                "x": 3,
                "y": 6,
                "z": 0,
                "elements": [
                    "mekanism:reinforcedplasticblock@7"
                ]
            },
            {
                "x": 4,
                "y": 6,
                "z": 0,
                "elements": [
                    "mekanism:reinforcedplasticblock@7"
                ]
            },
            {
                "x": -4,
                "y": 4,
                "z": 15,
                "elements": [
                    "mekanism:reinforcedplasticblock@7"
                ]
            },
            {
                "x": -4,
                "y": 2,
                "z": 14,
                "elements": [
                    "minecraft:iron_bars@0"
                ]
            },
            {
                "x": -3,
                "y": 4,
                "z": 15,
                "elements": [
                    "minecraft:iron_bars@0"
                ]
            },
            {
                "x": -4,
                "y": 0,
                "z": 13,
                "elements": [
                    "mekanism:reinforcedplasticblock@7"
                ]
            },
            {
                "x": -2,
                "y": 4,
                "z": 15,
                "elements": [
                    "minecraft:iron_bars@0"
                ]
            },
            {
                "x": -3,
                "y": 0,
                "z": 13,
                "elements": [
                    "minecraft:stained_hardened_clay@7"
                ]
            },
            {
                "x": -1,
                "y": 4,
                "z": 15,
                "elements": [
                    "minecraft:iron_bars@0"
                ]
            },
            {
                "x": -2,
                "y": 0,
                "z": 13,
                "elements": [
                    "enderio:block_alloy_endergy@2"
                ]
            },
            {
                "x": 0,
                "y": 4,
                "z": 15,
                "elements": [
                    "minecraft:iron_bars@0"
                ]
            },
            {
                "x": -1,
                "y": 0,
                "z": 13,
                "elements": [
                    "minecraft:stained_hardened_clay@15"
                ]
            },
            {
                "x": 1,
                "y": 4,
                "z": 15,
                "elements": [
                    "minecraft:iron_bars@0"
                ]
            },
            {
                "x": 0,
                "y": 0,
                "z": 13,
                "elements": [
                    "tconstruct:metal@0"
                ]
            },
            {
                "x": 2,
                "y": 4,
                "z": 15,
                "elements": [
                    "minecraft:iron_bars@0"
                ]
            },
            {
                "x": 1,
                "y": 0,
                "z": 13,
                "elements": [
                    "minecraft:stained_hardened_clay@15"
                ]
            },
            {
                "x": 3,
                "y": 4,
                "z": 15,
                "elements": [
                    "minecraft:iron_bars@0"
                ]
            },
            {
                "x": 2,
                "y": 0,
                "z": 13,
                "elements": [
                    "enderio:block_alloy_endergy@2"
                ]
            },
            {
                "x": 4,
                "y": 4,
                "z": 15,
                "elements": [
                    "mekanism:reinforcedplasticblock@7"
                ]
            },
            {
                "x": 3,
                "y": 0,
                "z": 13,
                "elements": [
                    "minecraft:stained_hardened_clay@7"
                ]
            },
            {
                "x": 4,
                "y": 2,
                "z": 14,
                "elements": [
                    "minecraft:iron_bars@0"
                ]
            },
            {
                "x": 4,
                "y": 0,
                "z": 13,
                "elements": [
                    "mekanism:reinforcedplasticblock@7"
                ]
            },
            {
                "x": -4,
                "y": 5,
                "z": 15,
                "elements": [
                    "mekanism:reinforcedplasticblock@7"
                ]
            },
            {
                "x": -4,
                "y": 3,
                "z": 14,
                "elements": [
                    "minecraft:iron_bars@0"
                ]
            },
            {
                "x": -3,
                "y": 5,
                "z": 15,
                "elements": [
                    "minecraft:iron_bars@0"
                ]
            },
            {
                "x": -4,
                "y": 1,
                "z": 13,
                "elements": [
                    "minecraft:iron_bars@0"
                ]
            },
            {
                "x": -2,
                "y": 5,
                "z": 15,
                "elements": [
                    "minecraft:iron_bars@0"
                ]
            },
            {
                "x": -1,
                "y": 5,
                "z": 15,
                "elements": [
                    "minecraft:iron_bars@0"
                ]
            },
            {
                "x": 0,
                "y": 5,
                "z": 15,
                "elements": [
                    "minecraft:iron_bars@0"
                ]
            },
            {
                "x": 1,
                "y": 5,
                "z": 15,
                "elements": [
                    "minecraft:iron_bars@0"
                ]
            },
            {
                "x": 0,
                "y": 1,
                "z": 13,
                "elements": [
                    "minecraft:purpur_pillar@0"
                ]
            },
            {
                "x": 2,
                "y": 5,
                "z": 15,
                "elements": [
                    "minecraft:iron_bars@0"
                ]
            },
            {
                "x": 3,
                "y": 5,
                "z": 15,
                "elements": [
                    "minecraft:iron_bars@0"
                ]
            },
            {
                "x": 4,
                "y": 5,
                "z": 15,
                "elements": [
                    "mekanism:reinforcedplasticblock@7"
                ]
            },
            {
                "x": 4,
                "y": 3,
                "z": 14,
                "elements": [
                    "minecraft:iron_bars@0"
                ]
            },
            {
                "x": 4,
                "y": 1,
                "z": 13,
                "elements": [
                    "minecraft:iron_bars@0"
                ]
            },
            {
                "x": -4,
                "y": 6,
                "z": 15,
                "elements": [
                    "mekanism:reinforcedplasticblock@7"
                ]
            },
            {
                "x": -4,
                "y": 4,
                "z": 14,
                "elements": [
                    "minecraft:iron_bars@0"
                ]
            },
            {
                "x": -3,
                "y": 6,
                "z": 15,
                "elements": [
                    "mekanism:reinforcedplasticblock@7"
                ]
            },
            {
                "x": -4,
                "y": 2,
                "z": 13,
                "elements": [
                    "minecraft:iron_bars@0"
                ]
            },
            {
                "x": -2,
                "y": 6,
                "z": 15,
                "elements": [
                    "mekanism:reinforcedplasticblock@7"
                ]
            },
            {
                "x": -4,
                "y": 0,
                "z": 12,
                "elements": [
                    "mekanism:reinforcedplasticblock@7"
                ]
            },
            {
                "x": -1,
                "y": 6,
                "z": 15,
                "elements": [
                    "mekanism:reinforcedplasticblock@7"
                ]
            },
            {
                "x": -3,
                "y": 0,
                "z": 12,
                "elements": [
                    "minecraft:stained_hardened_clay@7"
                ]
            },
            {
                "x": 0,
                "y": 6,
                "z": 15,
                "elements": [
                    "mekanism:reinforcedplasticblock@7"
                ]
            },
            {
                "x": -2,
                "y": 0,
                "z": 12,
                "elements": [
                    "minecraft:stained_hardened_clay@15"
                ]
            },
            {
                "x": 1,
                "y": 6,
                "z": 15,
                "elements": [
                    "mekanism:reinforcedplasticblock@7"
                ]
            },
            {
                "x": -1,
                "y": 0,
                "z": 12,
                "elements": [
                    "minecraft:stained_hardened_clay@15"
                ]
            },
            {
                "x": 0,
                "y": 2,
                "z": 13,
                "elements": [
                    "minecraft:purpur_pillar@0"
                ]
            },
            {
                "x": 2,
                "y": 6,
                "z": 15,
                "elements": [
                    "mekanism:reinforcedplasticblock@7"
                ]
            },
            {
                "x": 0,
                "y": 0,
                "z": 12,
                "elements": [
                    "tconstruct:metal@0"
                ]
            },
            {
                "x": 3,
                "y": 6,
                "z": 15,
                "elements": [
                    "mekanism:reinforcedplasticblock@7"
                ]
            },
            {
                "x": 1,
                "y": 0,
                "z": 12,
                "elements": [
                    "minecraft:stained_hardened_clay@15"
                ]
            },
            {
                "x": 4,
                "y": 6,
                "z": 15,
                "elements": [
                    "mekanism:reinforcedplasticblock@7"
                ]
            },
            {
                "x": 2,
                "y": 0,
                "z": 12,
                "elements": [
                    "minecraft:stained_hardened_clay@15"
                ]
            },
            {
                "x": 4,
                "y": 4,
                "z": 14,
                "elements": [
                    "minecraft:iron_bars@0"
                ]
            },
            {
                "x": 3,
                "y": 0,
                "z": 12,
                "elements": [
                    "minecraft:stained_hardened_clay@7"
                ]
            },
            {
                "x": 4,
                "y": 2,
                "z": 13,
                "elements": [
                    "minecraft:iron_bars@0"
                ]
            },
            {
                "x": 4,
                "y": 0,
                "z": 12,
                "elements": [
                    "mekanism:reinforcedplasticblock@7"
                ]
            },
            {
                "x": -4,
                "y": 5,
                "z": 14,
                "elements": [
                    "minecraft:iron_bars@0"
                ]
            },
            {
                "x": -4,
                "y": 3,
                "z": 13,
                "elements": [
                    "minecraft:iron_bars@0"
                ]
            },
            {
                "x": -4,
                "y": 1,
                "z": 12,
                "elements": [
                    "minecraft:iron_bars@0"
                ]
            },
            {
                "x": 0,
                "y": 3,
                "z": 13,
                "elements": [
                    "minecraft:purpur_pillar@0"
                ]
            },
            {
                "x": 4,
                "y": 5,
                "z": 14,
                "elements": [
                    "minecraft:iron_bars@0"
                ]
            },
            {
                "x": 4,
                "y": 3,
                "z": 13,
                "elements": [
                    "minecraft:iron_bars@0"
                ]
            },
            {
                "x": 4,
                "y": 1,
                "z": 12,
                "elements": [
                    "minecraft:iron_bars@0"
                ]
            },
            {
                "x": -4,
                "y": 6,
                "z": 14,
                "elements": [
                    "mekanism:reinforcedplasticblock@7"
                ]
            },
            {
                "x": -4,
                "y": 4,
                "z": 13,
                "elements": [
                    "minecraft:iron_bars@0"
                ]
            },
            {
                "x": -3,
                "y": 6,
                "z": 14,
                "elements": [
                    "thermalfoundation:glass@7"
                ]
            },
            {
                "x": -4,
                "y": 2,
                "z": 12,
                "elements": [
                    "minecraft:iron_bars@0"
                ]
            },
            {
                "x": -2,
                "y": 6,
                "z": 14,
                "elements": [
                    "thermalfoundation:glass@7"
                ]
            },
            {
                "x": -4,
                "y": 0,
                "z": 11,
                "elements": [
                    "mekanism:reinforcedplasticblock@7"
                ]
            },
            {
                "x": -1,
                "y": 6,
                "z": 14,
                "elements": [
                    "thermalfoundation:glass@7"
                ]
            },
            {
                "x": -3,
                "y": 0,
                "z": 11,
                "elements": [
                    "tconstruct:metal@0"
                ]
            },
            {
                "x": 0,
                "y": 6,
                "z": 14,
                "elements": [
                    "tconstruct:metal@0"
                ]
            },
            {
                "x": -2,
                "y": 0,
                "z": 11,
                "elements": [
                    "tconstruct:metal@0"
                ]
            },
            {
                "x": 0,
                "y": 4,
                "z": 13,
                "elements": [
                    "minecraft:purpur_pillar@0"
                ]
            },
            {
                "x": 1,
                "y": 6,
                "z": 14,
                "elements": [
                    "thermalfoundation:glass@7"
                ]
            },
            {
                "x": -1,
                "y": 0,
                "z": 11,
                "elements": [
                    "tconstruct:metal@0"
                ]
            },
            {
                "x": 2,
                "y": 6,
                "z": 14,
                "elements": [
                    "thermalfoundation:glass@7"
                ]
            },
            {
                "x": 0,
                "y": 0,
                "z": 11,
                "elements": [
                    "tconstruct:metal@0"
                ]
            },
            {
                "x": 3,
                "y": 6,
                "z": 14,
                "elements": [
                    "thermalfoundation:glass@7"
                ]
            },
            {
                "x": 1,
                "y": 0,
                "z": 11,
                "elements": [
                    "tconstruct:metal@0"
                ]
            },
            {
                "x": 4,
                "y": 6,
                "z": 14,
                "elements": [
                    "mekanism:reinforcedplasticblock@7"
                ]
            },
            {
                "x": 2,
                "y": 0,
                "z": 11,
                "elements": [
                    "tconstruct:metal@0"
                ]
            },
            {
                "x": 4,
                "y": 4,
                "z": 13,
                "elements": [
                    "minecraft:iron_bars@0"
                ]
            },
            {
                "x": 3,
                "y": 0,
                "z": 11,
                "elements": [
                    "tconstruct:metal@0"
                ]
            },
            {
                "x": 4,
                "y": 2,
                "z": 12,
                "elements": [
                    "minecraft:iron_bars@0"
                ]
            },
            {
                "x": 4,
                "y": 0,
                "z": 11,
                "elements": [
                    "mekanism:reinforcedplasticblock@7"
                ]
            },
            {
                "x": -4,
                "y": 5,
                "z": 13,
                "elements": [
                    "minecraft:iron_bars@0"
                ]
            },
            {
                "x": -4,
                "y": 3,
                "z": 12,
                "elements": [
                    "minecraft:iron_bars@0"
                ]
            },
            {
                "x": -4,
                "y": 1,
                "z": 11,
                "elements": [
                    "minecraft:iron_bars@0"
                ]
            },
            {
                "x": -2,
                "y": 1,
                "z": 11,
                "elements": [
                    "minecraft:purpur_pillar@0"
                ]
            },
            {
                "x": 0,
                "y": 5,
                "z": 13,
                "elements": [
                    "minecraft:purpur_pillar@0"
                ]
            },
            {
                "x": 0,
                "y": 3,
                "z": 12,
                "elements": [
                    "minecraft:end_rod@2"
                ]
            },
            {
                "x": 0,
                "y": 1,
                "z": 11,
                "elements": [
                    "ic2:fence@0"
                ]
            },
            {
                "x": 2,
                "y": 1,
                "z": 11,
                "elements": [
                    "minecraft:purpur_pillar@0"
                ]
            },
            {
                "x": 4,
                "y": 5,
                "z": 13,
                "elements": [
                    "minecraft:iron_bars@0"
                ]
            },
            {
                "x": 4,
                "y": 3,
                "z": 12,
                "elements": [
                    "minecraft:iron_bars@0"
                ]
            },
            {
                "x": 4,
                "y": 1,
                "z": 11,
                "elements": [
                    "minecraft:iron_bars@0"
                ]
            },
            {
                "x": -4,
                "y": 6,
                "z": 13,
                "elements": [
                    "mekanism:reinforcedplasticblock@7"
                ]
            },
            {
                "x": -4,
                "y": 4,
                "z": 12,
                "elements": [
                    "minecraft:iron_bars@0"
                ]
            },
            {
                "x": -3,
                "y": 6,
                "z": 13,
                "elements": [
                    "thermalfoundation:glass@7"
                ]
            },
            {
                "x": -4,
                "y": 2,
                "z": 11,
                "elements": [
                    "minecraft:iron_bars@0"
                ]
            },
            {
                "x": -2,
                "y": 6,
                "z": 13,
                "elements": [
                    "thermalfoundation:glass@7"
                ]
            },
            {
                "x": -4,
                "y": 0,
                "z": 10,
                "elements": [
                    "mekanism:reinforcedplasticblock@7"
                ]
            },
            {
                "x": -1,
                "y": 6,
                "z": 13,
                "elements": [
                    "thermalfoundation:glass@7"
                ]
            },
            {
                "x": -3,
                "y": 0,
                "z": 10,
                "elements": [
                    "minecraft:stained_hardened_clay@7"
                ]
            },
            {
                "x": -2,
                "y": 2,
                "z": 11,
                "elements": [
                    "minecraft:purpur_pillar@0"
                ]
            },
            {
                "x": 0,
                "y": 6,
                "z": 13,
                "elements": [
                    "tconstruct:metal@0"
                ]
            },
            {
                "x": -2,
                "y": 0,
                "z": 10,
                "elements": [
                    "minecraft:stained_hardened_clay@7"
                ]
            },
            {
                "x": 1,
                "y": 6,
                "z": 13,
                "elements": [
                    "thermalfoundation:glass@7"
                ]
            },
            {
                "x": -1,
                "y": 0,
                "z": 10,
                "elements": [
                    "minecraft:stained_hardened_clay@15"
                ]
            },
            {
                "x": 0,
                "y": 2,
                "z": 11,
                "elements": [
                    "minecraft:end_rod@1"
                ]
            },
            {
                "x": 2,
                "y": 6,
                "z": 13,
                "elements": [
                    "thermalfoundation:glass@7"
                ]
            },
            {
                "x": 0,
                "y": 0,
                "z": 10,
                "elements": [
                    "tconstruct:metal@0"
                ]
            },
            {
                "x": 3,
                "y": 6,
                "z": 13,
                "elements": [
                    "thermalfoundation:glass@7"
                ]
            },
            {
                "x": 1,
                "y": 0,
                "z": 10,
                "elements": [
                    "minecraft:stained_hardened_clay@15"
                ]
            },
            {
                "x": 2,
                "y": 2,
                "z": 11,
                "elements": [
                    "minecraft:purpur_pillar@0"
                ]
            },
            {
                "x": 4,
                "y": 6,
                "z": 13,
                "elements": [
                    "mekanism:reinforcedplasticblock@7"
                ]
            },
            {
                "x": 2,
                "y": 0,
                "z": 10,
                "elements": [
                    "minecraft:stained_hardened_clay@7"
                ]
            },
            {
                "x": 4,
                "y": 4,
                "z": 12,
                "elements": [
                    "minecraft:iron_bars@0"
                ]
            },
            {
                "x": 3,
                "y": 0,
                "z": 10,
                "elements": [
                    "minecraft:stained_hardened_clay@7"
                ]
            },
            {
                "x": 4,
                "y": 2,
                "z": 11,
                "elements": [
                    "minecraft:iron_bars@0"
                ]
            },
            {
                "x": 4,
                "y": 0,
                "z": 10,
                "elements": [
                    "mekanism:reinforcedplasticblock@7"
                ]
            },
            {
                "x": -4,
                "y": 5,
                "z": 12,
                "elements": [
                    "minecraft:iron_bars@0"
                ]
            },
            {
                "x": -4,
                "y": 3,
                "z": 11,
                "elements": [
                    "minecraft:iron_bars@0"
                ]
            },
            {
                "x": -4,
                "y": 1,
                "z": 10,
                "elements": [
                    "minecraft:iron_bars@0"
                ]
            },
            {
                "x": -2,
                "y": 3,
                "z": 11,
                "elements": [
                    "minecraft:purpur_pillar@0"
                ]
            },
            {
                "x": -1,
                "y": 3,
                "z": 11,
                "elements": [
                    "minecraft:end_rod@5"
                ]
            },
            {
                "x": 0,
                "y": 3,
                "z": 11,
                "elements": [
                    "avaritia:block_resource@2"
                ]
            },
            {
                "x": 1,
                "y": 3,
                "z": 11,
                "elements": [
                    "minecraft:end_rod@4"
                ]
            },
            {
                "x": 2,
                "y": 3,
                "z": 11,
                "elements": [
                    "minecraft:purpur_pillar@0"
                ]
            },
            {
                "x": 4,
                "y": 5,
                "z": 12,
                "elements": [
                    "minecraft:iron_bars@0"
                ]
            },
            {
                "x": 4,
                "y": 3,
                "z": 11,
                "elements": [
                    "minecraft:iron_bars@0"
                ]
            },
            {
                "x": 4,
                "y": 1,
                "z": 10,
                "elements": [
                    "minecraft:iron_bars@0"
                ]
            },
            {
                "x": -4,
                "y": 6,
                "z": 12,
                "elements": [
                    "mekanism:reinforcedplasticblock@7"
                ]
            },
            {
                "x": -4,
                "y": 4,
                "z": 11,
                "elements": [
                    "minecraft:iron_bars@0"
                ]
            },
            {
                "x": -3,
                "y": 6,
                "z": 12,
                "elements": [
                    "thermalfoundation:glass@7"
                ]
            },
            {
                "x": -4,
                "y": 2,
                "z": 10,
                "elements": [
                    "minecraft:iron_bars@0"
                ]
            },
            {
                "x": -2,
                "y": 6,
                "z": 12,
                "elements": [
                    "thermalfoundation:glass@7"
                ]
            },
            {
                "x": -4,
                "y": 0,
                "z": 9,
                "elements": [
                    "mekanism:reinforcedplasticblock@7"
                ]
            },
            {
                "x": -2,
                "y": 4,
                "z": 11,
                "elements": [
                    "minecraft:purpur_pillar@0"
                ]
            },
            {
                "x": -1,
                "y": 6,
                "z": 12,
                "elements": [
                    "thermalfoundation:glass@7"
                ]
            },
            {
                "x": -3,
                "y": 0,
                "z": 9,
                "elements": [
                    "minecraft:stained_hardened_clay@7"
                ]
            },
            {
                "x": 0,
                "y": 6,
                "z": 12,
                "elements": [
                    "tconstruct:metal@0"
                ]
            },
            {
                "x": -2,
                "y": 0,
                "z": 9,
                "elements": [
                    "minecraft:stained_hardened_clay@15"
                ]
            },
            {
                "x": 0,
                "y": 4,
                "z": 11,
                "elements": [
                    "minecraft:end_rod@0"
                ]
            },
            {
                "x": 1,
                "y": 6,
                "z": 12,
                "elements": [
                    "thermalfoundation:glass@7"
                ]
            },
            {
                "x": -1,
                "y": 0,
                "z": 9,
                "elements": [
                    "minecraft:stained_hardened_clay@7"
                ]
            },
            {
                "x": 2,
                "y": 6,
                "z": 12,
                "elements": [
                    "thermalfoundation:glass@7"
                ]
            },
            {
                "x": 0,
                "y": 0,
                "z": 9,
                "elements": [
                    "tconstruct:metal@0"
                ]
            },
            {
                "x": 2,
                "y": 4,
                "z": 11,
                "elements": [
                    "minecraft:purpur_pillar@0"
                ]
            },
            {
                "x": 3,
                "y": 6,
                "z": 12,
                "elements": [
                    "thermalfoundation:glass@7"
                ]
            },
            {
                "x": 1,
                "y": 0,
                "z": 9,
                "elements": [
                    "minecraft:stained_hardened_clay@7"
                ]
            },
            {
                "x": 4,
                "y": 6,
                "z": 12,
                "elements": [
                    "mekanism:reinforcedplasticblock@7"
                ]
            },
            {
                "x": 2,
                "y": 0,
                "z": 9,
                "elements": [
                    "minecraft:stained_hardened_clay@15"
                ]
            },
            {
                "x": 4,
                "y": 4,
                "z": 11,
                "elements": [
                    "minecraft:iron_bars@0"
                ]
            },
            {
                "x": 3,
                "y": 0,
                "z": 9,
                "elements": [
                    "minecraft:stained_hardened_clay@7"
                ]
            },
            {
                "x": 4,
                "y": 2,
                "z": 10,
                "elements": [
                    "minecraft:iron_bars@0"
                ]
            },
            {
                "x": 4,
                "y": 0,
                "z": 9,
                "elements": [
                    "mekanism:reinforcedplasticblock@7"
                ]
            },
            {
                "x": -4,
                "y": 5,
                "z": 11,
                "elements": [
                    "minecraft:iron_bars@0"
                ]
            },
            {
                "x": -4,
                "y": 3,
                "z": 10,
                "elements": [
                    "minecraft:iron_bars@0"
                ]
            },
            {
                "x": -4,
                "y": 1,
                "z": 9,
                "elements": [
                    "minecraft:iron_bars@0"
                ]
            },
            {
                "x": -2,
                "y": 5,
                "z": 11,
                "elements": [
                    "minecraft:purpur_pillar@0"
                ]
            },
            {
                "x": 0,
                "y": 5,
                "z": 11,
                "elements": [
                    "ic2:fence@0"
                ]
            },
            {
                "x": 0,
                "y": 3,
                "z": 10,
                "elements": [
                    "minecraft:end_rod@3"
                ]
            },
            {
                "x": 0,
                "y": 1,
                "z": 9,
                "elements": [
                    "minecraft:purpur_pillar@0"
                ]
            },
            {
                "x": 2,
                "y": 5,
                "z": 11,
                "elements": [
                    "minecraft:purpur_pillar@0"
                ]
            },
            {
                "x": 4,
                "y": 5,
                "z": 11,
                "elements": [
                    "minecraft:iron_bars@0"
                ]
            },
            {
                "x": 4,
                "y": 3,
                "z": 10,
                "elements": [
                    "minecraft:iron_bars@0"
                ]
            },
            {
                "x": 4,
                "y": 1,
                "z": 9,
                "elements": [
                    "minecraft:iron_bars@0"
                ]
            },
            {
                "x": -4,
                "y": 6,
                "z": 11,
                "elements": [
                    "mekanism:reinforcedplasticblock@7"
                ]
            },
            {
                "x": -4,
                "y": 4,
                "z": 10,
                "elements": [
                    "minecraft:iron_bars@0"
                ]
            },
            {
                "x": -3,
                "y": 6,
                "z": 11,
                "elements": [
                    "tconstruct:metal@0"
                ]
            },
            {
                "x": -4,
                "y": 2,
                "z": 9,
                "elements": [
                    "minecraft:iron_bars@0"
                ]
            },
            {
                "x": -2,
                "y": 6,
                "z": 11,
                "elements": [
                    "tconstruct:metal@0"
                ]
            },
            {
                "x": -4,
                "y": 0,
                "z": 8,
                "elements": [
                    "mekanism:reinforcedplasticblock@7"
                ]
            },
            {
                "x": -1,
                "y": 6,
                "z": 11,
                "elements": [
                    "tconstruct:metal@0"
                ]
            },
            {
                "x": -3,
                "y": 0,
                "z": 8,
                "elements": [
                    "minecraft:stained_hardened_clay@15"
                ]
            },
            {
                "x": 0,
                "y": 6,
                "z": 11,
                "elements": [
                    "tconstruct:metal@0"
                ]
            },
            {
                "x": -2,
                "y": 0,
                "z": 8,
                "elements": [
                    "enderio:block_alloy_endergy@2"
                ]
            },
            {
                "x": 1,
                "y": 6,
                "z": 11,
                "elements": [
                    "tconstruct:metal@0"
                ]
            },
            {
                "x": -1,
                "y": 0,
                "z": 8,
                "elements": [
                    "minecraft:stained_hardened_clay@7"
                ]
            },
            {
                "x": 0,
                "y": 2,
                "z": 9,
                "elements": [
                    "minecraft:purpur_pillar@0"
                ]
            },
            {
                "x": 2,
                "y": 6,
                "z": 11,
                "elements": [
                    "tconstruct:metal@0"
                ]
            },
            {
                "x": 0,
                "y": 0,
                "z": 8,
                "elements": [
                    "tconstruct:metal@0"
                ]
            },
            {
                "x": 3,
                "y": 6,
                "z": 11,
                "elements": [
                    "tconstruct:metal@0"
                ]
            },
            {
                "x": 1,
                "y": 0,
                "z": 8,
                "elements": [
                    "minecraft:stained_hardened_clay@7"
                ]
            },
            {
                "x": 4,
                "y": 6,
                "z": 11,
                "elements": [
                    "mekanism:reinforcedplasticblock@7"
                ]
            },
            {
                "x": 2,
                "y": 0,
                "z": 8,
                "elements": [
                    "enderio:block_alloy_endergy@2"
                ]
            },
            {
                "x": 4,
                "y": 4,
                "z": 10,
                "elements": [
                    "minecraft:iron_bars@0"
                ]
            },
            {
                "x": 3,
                "y": 0,
                "z": 8,
                "elements": [
                    "minecraft:stained_hardened_clay@7"
                ]
            },
            {
                "x": 4,
                "y": 2,
                "z": 9,
                "elements": [
                    "minecraft:iron_bars@0"
                ]
            },
            {
                "x": 4,
                "y": 0,
                "z": 8,
                "elements": [
                    "mekanism:reinforcedplasticblock@7"
                ]
            },
            {
                "x": -4,
                "y": 5,
                "z": 10,
                "elements": [
                    "minecraft:iron_bars@0"
                ]
            },
            {
                "x": -4,
                "y": 3,
                "z": 9,
                "elements": [
                    "minecraft:iron_bars@0"
                ]
            },
            {
                "x": -4,
                "y": 1,
                "z": 8,
                "elements": [
                    "mekanism:reinforcedplasticblock@7"
                ]
            },
            {
                "x": 0,
                "y": 3,
                "z": 9,
                "elements": [
                    "minecraft:purpur_pillar@0"
                ]
            },
            {
                "x": 4,
                "y": 5,
                "z": 10,
                "elements": [
                    "minecraft:iron_bars@0"
                ]
            },
            {
                "x": 4,
                "y": 3,
                "z": 9,
                "elements": [
                    "minecraft:iron_bars@0"
                ]
            },
            {
                "x": 4,
                "y": 1,
                "z": 8,
                "elements": [
                    "mekanism:reinforcedplasticblock@7"
                ]
            },
            {
                "x": -4,
                "y": 6,
                "z": 10,
                "elements": [
                    "mekanism:reinforcedplasticblock@7"
                ]
            },
            {
                "x": -4,
                "y": 4,
                "z": 9,
                "elements": [
                    "minecraft:iron_bars@0"
                ]
            },
            {
                "x": -3,
                "y": 6,
                "z": 10,
                "elements": [
                    "thermalfoundation:glass@7"
                ]
            },
            {
                "x": -4,
                "y": 2,
                "z": 8,
                "elements": [
                    "mekanism:reinforcedplasticblock@7"
                ]
            },
            {
                "x": -2,
                "y": 6,
                "z": 10,
                "elements": [
                    "thermalfoundation:glass@7"
                ]
            },
            {
                "x": -4,
                "y": 0,
                "z": 7,
                "elements": [
                    "mekanism:reinforcedplasticblock@7"
                ]
            },
            {
                "x": -1,
                "y": 6,
                "z": 10,
                "elements": [
                    "thermalfoundation:glass@7"
                ]
            },
            {
                "x": -3,
                "y": 0,
                "z": 7,
                "elements": [
                    "minecraft:stained_hardened_clay@15"
                ]
            },
            {
                "x": 0,
                "y": 6,
                "z": 10,
                "elements": [
                    "tconstruct:metal@0"
                ]
            },
            {
                "x": -2,
                "y": 0,
                "z": 7,
                "elements": [
                    "enderio:block_alloy_endergy@2"
                ]
            },
            {
                "x": 0,
                "y": 4,
                "z": 9,
                "elements": [
                    "minecraft:purpur_pillar@0"
                ]
            },
            {
                "x": 1,
                "y": 6,
                "z": 10,
                "elements": [
                    "thermalfoundation:glass@7"
                ]
            },
            {
                "x": -1,
                "y": 0,
                "z": 7,
                "elements": [
                    "minecraft:stained_hardened_clay@7"
                ]
            },
            {
                "x": 2,
                "y": 6,
                "z": 10,
                "elements": [
                    "thermalfoundation:glass@7"
                ]
            },
            {
                "x": 0,
                "y": 0,
                "z": 7,
                "elements": [
                    "tconstruct:metal@0"
                ]
            },
            {
                "x": 3,
                "y": 6,
                "z": 10,
                "elements": [
                    "thermalfoundation:glass@7"
                ]
            },
            {
                "x": 1,
                "y": 0,
                "z": 7,
                "elements": [
                    "minecraft:stained_hardened_clay@7"
                ]
            },
            {
                "x": 4,
                "y": 6,
                "z": 10,
                "elements": [
                    "mekanism:reinforcedplasticblock@7"
                ]
            },
            {
                "x": 2,
                "y": 0,
                "z": 7,
                "elements": [
                    "enderio:block_alloy_endergy@2"
                ]
            },
            {
                "x": 4,
                "y": 4,
                "z": 9,
                "elements": [
                    "minecraft:iron_bars@0"
                ]
            },
            {
                "x": 3,
                "y": 0,
                "z": 7,
                "elements": [
                    "minecraft:stained_hardened_clay@7"
                ]
            },
            {
                "x": 4,
                "y": 2,
                "z": 8,
                "elements": [
                    "mekanism:reinforcedplasticblock@7"
                ]
            },
            {
                "x": 4,
                "y": 0,
                "z": 7,
                "elements": [
                    "mekanism:reinforcedplasticblock@7"
                ]
            },
            {
                "x": -4,
                "y": 5,
                "z": 9,
                "elements": [
                    "minecraft:iron_bars@0"
                ]
            },
            {
                "x": -4,
                "y": 3,
                "z": 8,
                "elements": [
                    "mekanism:reinforcedplasticblock@7"
                ]
            },
            {
                "x": -4,
                "y": 1,
                "z": 7,
                "elements": [
                    "mekanism:reinforcedplasticblock@7"
                ]
            },
            {
                "x": 0,
                "y": 5,
                "z": 9,
                "elements": [
                    "minecraft:purpur_pillar@0"
                ]
            },
            {
                "x": 4,
                "y": 5,
                "z": 9,
                "elements": [
                    "minecraft:iron_bars@0"
                ]
            },
            {
                "x": 4,
                "y": 3,
                "z": 8,
                "elements": [
                    "mekanism:reinforcedplasticblock@7"
                ]
            },
            {
                "x": 4,
                "y": 1,
                "z": 7,
                "elements": [
                    "mekanism:reinforcedplasticblock@7"
                ]
            },
            {
                "x": -4,
                "y": 6,
                "z": 9,
                "elements": [
                    "mekanism:reinforcedplasticblock@7"
                ]
            },
            {
                "x": -4,
                "y": 4,
                "z": 8,
                "elements": [
                    "mekanism:reinforcedplasticblock@7"
                ]
            },
            {
                "x": -3,
                "y": 6,
                "z": 9,
                "elements": [
                    "thermalfoundation:glass@7"
                ]
            },
            {
                "x": -4,
                "y": 2,
                "z": 7,
                "elements": [
                    "mekanism:reinforcedplasticblock@7"
                ]
            },
            {
                "x": -2,
                "y": 6,
                "z": 9,
                "elements": [
                    "thermalfoundation:glass@7"
                ]
            },
            {
                "x": -4,
                "y": 0,
                "z": 6,
                "elements": [
                    "mekanism:reinforcedplasticblock@7"
                ]
            },
            {
                "x": -1,
                "y": 6,
                "z": 9,
                "elements": [
                    "thermalfoundation:glass@7"
                ]
            },
            {
                "x": -3,
                "y": 0,
                "z": 6,
                "elements": [
                    "minecraft:stained_hardened_clay@7"
                ]
            },
            {
                "x": 0,
                "y": 6,
                "z": 9,
                "elements": [
                    "tconstruct:metal@0"
                ]
            },
            {
                "x": -2,
                "y": 0,
                "z": 6,
                "elements": [
                    "minecraft:stained_hardened_clay@15"
                ]
            },
            {
                "x": 1,
                "y": 6,
                "z": 9,
                "elements": [
                    "thermalfoundation:glass@7"
                ]
            },
            {
                "x": -1,
                "y": 0,
                "z": 6,
                "elements": [
                    "minecraft:stained_hardened_clay@7"
                ]
            },
            {
                "x": 2,
                "y": 6,
                "z": 9,
                "elements": [
                    "thermalfoundation:glass@7"
                ]
            },
            {
                "x": 0,
                "y": 0,
                "z": 6,
                "elements": [
                    "tconstruct:metal@0"
                ]
            },
            {
                "x": 3,
                "y": 6,
                "z": 9,
                "elements": [
                    "thermalfoundation:glass@7"
                ]
            },
            {
                "x": 1,
                "y": 0,
                "z": 6,
                "elements": [
                    "minecraft:stained_hardened_clay@7"
                ]
            },
            {
                "x": 4,
                "y": 6,
                "z": 9,
                "elements": [
                    "mekanism:reinforcedplasticblock@7"
                ]
            },
            {
                "x": 2,
                "y": 0,
                "z": 6,
                "elements": [
                    "minecraft:stained_hardened_clay@15"
                ]
            },
            {
                "x": 4,
                "y": 4,
                "z": 8,
                "elements": [
                    "mekanism:reinforcedplasticblock@7"
                ]
            },
            {
                "x": 3,
                "y": 0,
                "z": 6,
                "elements": [
                    "minecraft:stained_hardened_clay@7"
                ]
            },
            {
                "x": 4,
                "y": 2,
                "z": 7,
                "elements": [
                    "mekanism:reinforcedplasticblock@7"
                ]
            },
            {
                "x": 4,
                "y": 0,
                "z": 6,
                "elements": [
                    "mekanism:reinforcedplasticblock@7"
                ]
            },
            {
                "x": -4,
                "y": 5,
                "z": 8,
                "elements": [
                    "mekanism:reinforcedplasticblock@7"
                ]
            },
            {
                "x": -4,
                "y": 3,
                "z": 7,
                "elements": [
                    "mekanism:reinforcedplasticblock@7"
                ]
            },
            {
                "x": -4,
                "y": 1,
                "z": 6,
                "elements": [
                    "minecraft:iron_bars@0"
                ]
            },
            {
                "x": 0,
                "y": 1,
                "z": 6,
                "elements": [
                    "minecraft:purpur_pillar@0"
                ]
            },
            {
                "x": 4,
                "y": 5,
                "z": 8,
                "elements": [
                    "mekanism:reinforcedplasticblock@7"
                ]
            },
            {
                "x": 4,
                "y": 3,
                "z": 7,
                "elements": [
                    "mekanism:reinforcedplasticblock@7"
                ]
            },
            {
                "x": 4,
                "y": 1,
                "z": 6,
                "elements": [
                    "minecraft:iron_bars@0"
                ]
            },
            {
                "x": -4,
                "y": 6,
                "z": 8,
                "elements": [
                    "mekanism:reinforcedplasticblock@7"
                ]
            },
            {
                "x": -4,
                "y": 4,
                "z": 7,
                "elements": [
                    "mekanism:reinforcedplasticblock@7"
                ]
            },
            {
                "x": -3,
                "y": 6,
                "z": 8,
                "elements": [
                    "thermalfoundation:glass@7"
                ]
            },
            {
                "x": -4,
                "y": 2,
                "z": 6,
                "elements": [
                    "minecraft:iron_bars@0"
                ]
            },
            {
                "x": -2,
                "y": 6,
                "z": 8,
                "elements": [
                    "thermalfoundation:glass@7"
                ]
            },
            {
                "x": -4,
                "y": 0,
                "z": 5,
                "elements": [
                    "mekanism:reinforcedplasticblock@7"
                ]
            },
            {
                "x": -1,
                "y": 6,
                "z": 8,
                "elements": [
                    "thermalfoundation:glass@7"
                ]
            },
            {
                "x": -3,
                "y": 0,
                "z": 5,
                "elements": [
                    "minecraft:stained_hardened_clay@7"
                ]
            },
            {
                "x": 0,
                "y": 6,
                "z": 8,
                "elements": [
                    "tconstruct:metal@0"
                ]
            },
            {
                "x": -2,
                "y": 0,
                "z": 5,
                "elements": [
                    "minecraft:stained_hardened_clay@7"
                ]
            },
            {
                "x": 1,
                "y": 6,
                "z": 8,
                "elements": [
                    "thermalfoundation:glass@7"
                ]
            },
            {
                "x": -1,
                "y": 0,
                "z": 5,
                "elements": [
                    "minecraft:stained_hardened_clay@15"
                ]
            },
            {
                "x": 0,
                "y": 2,
                "z": 6,
                "elements": [
                    "minecraft:purpur_pillar@0"
                ]
            },
            {
                "x": 2,
                "y": 6,
                "z": 8,
                "elements": [
                    "thermalfoundation:glass@7"
                ]
            },
            {
                "x": 0,
                "y": 0,
                "z": 5,
                "elements": [
                    "tconstruct:metal@0"
                ]
            },
            {
                "x": 3,
                "y": 6,
                "z": 8,
                "elements": [
                    "thermalfoundation:glass@7"
                ]
            },
            {
                "x": 1,
                "y": 0,
                "z": 5,
                "elements": [
                    "minecraft:stained_hardened_clay@15"
                ]
            },
            {
                "x": 4,
                "y": 6,
                "z": 8,
                "elements": [
                    "mekanism:reinforcedplasticblock@7"
                ]
            },
            {
                "x": 2,
                "y": 0,
                "z": 5,
                "elements": [
                    "minecraft:stained_hardened_clay@7"
                ]
            },
            {
                "x": 4,
                "y": 4,
                "z": 7,
                "elements": [
                    "mekanism:reinforcedplasticblock@7"
                ]
            },
            {
                "x": 3,
                "y": 0,
                "z": 5,
                "elements": [
                    "minecraft:stained_hardened_clay@7"
                ]
            },
            {
                "x": 4,
                "y": 2,
                "z": 6,
                "elements": [
                    "minecraft:iron_bars@0"
                ]
            },
            {
                "x": 4,
                "y": 0,
                "z": 5,
                "elements": [
                    "mekanism:reinforcedplasticblock@7"
                ]
            },
            {
                "x": -4,
                "y": 5,
                "z": 7,
                "elements": [
                    "mekanism:reinforcedplasticblock@7"
                ]
            },
            {
                "x": -4,
                "y": 3,
                "z": 6,
                "elements": [
                    "minecraft:iron_bars@0"
                ]
            },
            {
                "x": -4,
                "y": 1,
                "z": 5,
                "elements": [
                    "minecraft:iron_bars@0"
                ]
            },
            {
                "x": 0,
                "y": 3,
                "z": 6,
                "elements": [
                    "minecraft:purpur_pillar@0"
                ]
            },
            {
                "x": 4,
                "y": 5,
                "z": 7,
                "elements": [
                    "mekanism:reinforcedplasticblock@7"
                ]
            },
            {
                "x": 4,
                "y": 3,
                "z": 6,
                "elements": [
                    "minecraft:iron_bars@0"
                ]
            },
            {
                "x": 4,
                "y": 1,
                "z": 5,
                "elements": [
                    "minecraft:iron_bars@0"
                ]
            },
            {
                "x": -4,
                "y": 6,
                "z": 7,
                "elements": [
                    "mekanism:reinforcedplasticblock@7"
                ]
            },
            {
                "x": -4,
                "y": 4,
                "z": 6,
                "elements": [
                    "minecraft:iron_bars@0"
                ]
            },
            {
                "x": -3,
                "y": 6,
                "z": 7,
                "elements": [
                    "thermalfoundation:glass@7"
                ]
            },
            {
                "x": -4,
                "y": 2,
                "z": 5,
                "elements": [
                    "minecraft:iron_bars@0"
                ]
            },
            {
                "x": -2,
                "y": 6,
                "z": 7,
                "elements": [
                    "thermalfoundation:glass@7"
                ]
            },
            {
                "x": -4,
                "y": 0,
                "z": 4,
                "elements": [
                    "mekanism:reinforcedplasticblock@7"
                ]
            },
            {
                "x": -1,
                "y": 6,
                "z": 7,
                "elements": [
                    "thermalfoundation:glass@7"
                ]
            },
            {
                "x": -3,
                "y": 0,
                "z": 4,
                "elements": [
                    "tconstruct:metal@0"
                ]
            },
            {
                "x": 0,
                "y": 6,
                "z": 7,
                "elements": [
                    "tconstruct:metal@0"
                ]
            },
            {
                "x": -2,
                "y": 0,
                "z": 4,
                "elements": [
                    "tconstruct:metal@0"
                ]
            },
            {
                "x": 0,
                "y": 4,
                "z": 6,
                "elements": [
                    "minecraft:purpur_pillar@0"
                ]
            },
            {
                "x": 1,
                "y": 6,
                "z": 7,
                "elements": [
                    "thermalfoundation:glass@7"
                ]
            },
            {
                "x": -1,
                "y": 0,
                "z": 4,
                "elements": [
                    "tconstruct:metal@0"
                ]
            },
            {
                "x": 2,
                "y": 6,
                "z": 7,
                "elements": [
                    "thermalfoundation:glass@7"
                ]
            },
            {
                "x": 0,
                "y": 0,
                "z": 4,
                "elements": [
                    "tconstruct:metal@0"
                ]
            },
            {
                "x": 3,
                "y": 6,
                "z": 7,
                "elements": [
                    "thermalfoundation:glass@7"
                ]
            },
            {
                "x": 1,
                "y": 0,
                "z": 4,
                "elements": [
                    "tconstruct:metal@0"
                ]
            },
            {
                "x": 4,
                "y": 6,
                "z": 7,
                "elements": [
                    "mekanism:reinforcedplasticblock@7"
                ]
            },
            {
                "x": 2,
                "y": 0,
                "z": 4,
                "elements": [
                    "tconstruct:metal@0"
                ]
            },
            {
                "x": 4,
                "y": 4,
                "z": 6,
                "elements": [
                    "minecraft:iron_bars@0"
                ]
            },
            {
                "x": 3,
                "y": 0,
                "z": 4,
                "elements": [
                    "tconstruct:metal@0"
                ]
            },
            {
                "x": 4,
                "y": 2,
                "z": 5,
                "elements": [
                    "minecraft:iron_bars@0"
                ]
            },
            {
                "x": 4,
                "y": 0,
                "z": 4,
                "elements": [
                    "mekanism:reinforcedplasticblock@7"
                ]
            },
            {
                "x": -4,
                "y": 5,
                "z": 6,
                "elements": [
                    "minecraft:iron_bars@0"
                ]
            },
            {
                "x": -4,
                "y": 3,
                "z": 5,
                "elements": [
                    "minecraft:iron_bars@0"
                ]
            },
            {
                "x": -4,
                "y": 1,
                "z": 4,
                "elements": [
                    "minecraft:iron_bars@0"
                ]
            },
            {
                "x": -2,
                "y": 1,
                "z": 4,
                "elements": [
                    "minecraft:purpur_pillar@0"
                ]
            },
            {
                "x": 0,
                "y": 5,
                "z": 6,
                "elements": [
                    "minecraft:purpur_pillar@0"
                ]
            },
            {
                "x": 0,
                "y": 3,
                "z": 5,
                "elements": [
                    "minecraft:end_rod@2"
                ]
            },
            {
                "x": 0,
                "y": 1,
                "z": 4,
                "elements": [
                    "ic2:fence@0"
                ]
            },
            {
                "x": 2,
                "y": 1,
                "z": 4,
                "elements": [
                    "minecraft:purpur_pillar@0"
                ]
            },
            {
                "x": 4,
                "y": 5,
                "z": 6,
                "elements": [
                    "minecraft:iron_bars@0"
                ]
            },
            {
                "x": 4,
                "y": 3,
                "z": 5,
                "elements": [
                    "minecraft:iron_bars@0"
                ]
            },
            {
                "x": 4,
                "y": 1,
                "z": 4,
                "elements": [
                    "minecraft:iron_bars@0"
                ]
            },
            {
                "x": -4,
                "y": 6,
                "z": 6,
                "elements": [
                    "mekanism:reinforcedplasticblock@7"
                ]
            },
            {
                "x": -4,
                "y": 4,
                "z": 5,
                "elements": [
                    "minecraft:iron_bars@0"
                ]
            },
            {
                "x": -3,
                "y": 6,
                "z": 6,
                "elements": [
                    "thermalfoundation:glass@7"
                ]
            },
            {
                "x": -4,
                "y": 2,
                "z": 4,
                "elements": [
                    "minecraft:iron_bars@0"
                ]
            },
            {
                "x": -2,
                "y": 6,
                "z": 6,
                "elements": [
                    "thermalfoundation:glass@7"
                ]
            },
            {
                "x": -4,
                "y": 0,
                "z": 3,
                "elements": [
                    "mekanism:reinforcedplasticblock@7"
                ]
            },
            {
                "x": -1,
                "y": 6,
                "z": 6,
                "elements": [
                    "thermalfoundation:glass@7"
                ]
            },
            {
                "x": -3,
                "y": 0,
                "z": 3,
                "elements": [
                    "minecraft:stained_hardened_clay@7"
                ]
            },
            {
                "x": -2,
                "y": 2,
                "z": 4,
                "elements": [
                    "minecraft:purpur_pillar@0"
                ]
            },
            {
                "x": 0,
                "y": 6,
                "z": 6,
                "elements": [
                    "tconstruct:metal@0"
                ]
            },
            {
                "x": -2,
                "y": 0,
                "z": 3,
                "elements": [
                    "minecraft:stained_hardened_clay@15"
                ]
            },
            {
                "x": 1,
                "y": 6,
                "z": 6,
                "elements": [
                    "thermalfoundation:glass@7"
                ]
            },
            {
                "x": -1,
                "y": 0,
                "z": 3,
                "elements": [
                    "minecraft:stained_hardened_clay@15"
                ]
            },
            {
                "x": 0,
                "y": 2,
                "z": 4,
                "elements": [
                    "minecraft:end_rod@1"
                ]
            },
            {
                "x": 2,
                "y": 6,
                "z": 6,
                "elements": [
                    "thermalfoundation:glass@7"
                ]
            },
            {
                "x": 0,
                "y": 0,
                "z": 3,
                "elements": [
                    "tconstruct:metal@0"
                ]
            },
            {
                "x": 3,
                "y": 6,
                "z": 6,
                "elements": [
                    "thermalfoundation:glass@7"
                ]
            },
            {
                "x": 1,
                "y": 0,
                "z": 3,
                "elements": [
                    "minecraft:stained_hardened_clay@15"
                ]
            },
            {
                "x": 2,
                "y": 2,
                "z": 4,
                "elements": [
                    "minecraft:purpur_pillar@0"
                ]
            },
            {
                "x": 4,
                "y": 6,
                "z": 6,
                "elements": [
                    "mekanism:reinforcedplasticblock@7"
                ]
            },
            {
                "x": 2,
                "y": 0,
                "z": 3,
                "elements": [
                    "minecraft:stained_hardened_clay@15"
                ]
            },
            {
                "x": 4,
                "y": 4,
                "z": 5,
                "elements": [
                    "minecraft:iron_bars@0"
                ]
            },
            {
                "x": 3,
                "y": 0,
                "z": 3,
                "elements": [
                    "minecraft:stained_hardened_clay@7"
                ]
            },
            {
                "x": 4,
                "y": 2,
                "z": 4,
                "elements": [
                    "minecraft:iron_bars@0"
                ]
            },
            {
                "x": 4,
                "y": 0,
                "z": 3,
                "elements": [
                    "mekanism:reinforcedplasticblock@7"
                ]
            },
            {
                "x": -4,
                "y": 5,
                "z": 5,
                "elements": [
                    "minecraft:iron_bars@0"
                ]
            },
            {
                "x": -4,
                "y": 3,
                "z": 4,
                "elements": [
                    "minecraft:iron_bars@0"
                ]
            },
            {
                "x": -4,
                "y": 1,
                "z": 3,
                "elements": [
                    "minecraft:iron_bars@0"
                ]
            },
            {
                "x": -2,
                "y": 3,
                "z": 4,
                "elements": [
                    "minecraft:purpur_pillar@0"
                ]
            },
            {
                "x": -1,
                "y": 3,
                "z": 4,
                "elements": [
                    "minecraft:end_rod@5"
                ]
            },
            {
                "x": 0,
                "y": 3,
                "z": 4,
                "elements": [
                    "avaritia:block_resource@2"
                ]
            },
            {
                "x": 1,
                "y": 3,
                "z": 4,
                "elements": [
                    "minecraft:end_rod@4"
                ]
            },
            {
                "x": 2,
                "y": 3,
                "z": 4,
                "elements": [
                    "minecraft:purpur_pillar@0"
                ]
            },
            {
                "x": 4,
                "y": 5,
                "z": 5,
                "elements": [
                    "minecraft:iron_bars@0"
                ]
            },
            {
                "x": 4,
                "y": 3,
                "z": 4,
                "elements": [
                    "minecraft:iron_bars@0"
                ]
            },
            {
                "x": 4,
                "y": 1,
                "z": 3,
                "elements": [
                    "minecraft:iron_bars@0"
                ]
            },
            {
                "x": -4,
                "y": 6,
                "z": 5,
                "elements": [
                    "mekanism:reinforcedplasticblock@7"
                ]
            },
            {
                "x": -4,
                "y": 4,
                "z": 4,
                "elements": [
                    "minecraft:iron_bars@0"
                ]
            },
            {
                "x": -3,
