{
    "registryname": "terminal_reactor",
    "localizedname": "§5终焉§6反应堆",
    "failure-action": "still",
    "requires-blueprint": false,
    "color": "2A312F",
    "parts": [
        {
            "x": 1,
            "y": 0,
            "z": 0,
            "elements": [
                "chisel:technicalnew@2"
            ]
        },
        {
            "x": -7,
            "y": 0,
            "z": 0,
            "elements": [
                "modularmachinery:blockfluidoutputhatch"
            ]
        },
        {
            "x": -8,
            "y": 0,
            "z": 0,
            "elements": [
                "chisel:technicalnew@2"
            ]
        },
        {
            "x": -8,
            "y": 1,
            "z": 0,
            "elements": [
                "chisel:technicalnew@2"
            ]
        },
        {
            "x": -7,
            "y": 1,
            "z": 0,
            "elements": [
                "rpsideas:dark_plate@11"
            ]
        },
        {
            "x": -6,
            "y": 1,
            "z": 0,
            "elements": [
                "rpsideas:dark_plate@11"
            ]
        },
        {
            "x": -5,
            "y": 1,
            "z": 0,
            "elements": [
                "appliedenergistics2:fluix_slab@8"
            ]
        },
        {
            "x": -4,
            "y": 1,
            "z": 0,
            "elements": [
                "appliedenergistics2:fluix_slab@8"
            ]
        },
        {
            "x": -3,
            "y": 1,
            "z": 0,
            "elements": [
                "appliedenergistics2:fluix_slab@8"
            ]
        },
        {
            "x": 1,
            "y": -1,
            "z": 0,
            "elements": [
                "chisel:technicalnew@2"
            ]
        },
        {
            "x": -2,
            "y": 1,
            "z": 0,
            "elements": [
                "appliedenergistics2:fluix_slab@8"
            ]
        },
        {
            "x": 0,
            "y": -1,
            "z": 0,
            "elements": [
                "modularmachinery:blockinputbus"
            ]
        },
        {
            "x": -1,
            "y": 1,
            "z": 0,
            "elements": [
                "rpsideas:dark_plate@11"
            ]
        },
        {
            "x": 0,
            "y": 1,
            "z": 0,
            "elements": [
                "rpsideas:dark_plate@11"
            ]
        },
        {
            "x": 1,
            "y": 1,
            "z": 0,
            "elements": [
                "chisel:technicalnew@2"
            ]
        },
        {
            "x": -7,
            "y": -1,
            "z": 0,
            "elements": [
                "modularmachinery:blockinputbus"
            ]
        },
        {
            "x": -8,
            "y": -1,
            "z": 0,
            "elements": [
                "chisel:technicalnew@2"
            ]
        },
        {
            "x": -9,
            "y": 2,
            "z": 0,
            "elements": [
                "appliedenergistics2:fluix_slab@8"
            ]
        },
        {
            "x": -8,
            "y": 2,
            "z": 0,
            "elements": [
                "matteroverdrive:industrial_glass@0"
            ]
        },
        {
            "x": -7,
            "y": 2,
            "z": 0,
            "elements": [
                "matteroverdrive:matter_plasma@0"
            ]
        },
        {
            "x": -6,
            "y": 2,
            "z": 0,
            "elements": [
                "matteroverdrive:matter_plasma@0"
            ]
        },
        {
            "x": -5,
            "y": 2,
            "z": 0,
            "elements": [
                "rpsideas:dark_plate@10"
            ]
        },
        {
            "x": 4,
            "y": -2,
            "z": 0,
            "elements": [
                "matteroverdrive:decorative.tritanium_plate_stripe@0"
            ]
        },
        {
            "x": 3,
            "y": -2,
            "z": 0,
            "elements": [
                "matteroverdrive:decorative.clean@0"
            ]
        },
        {
            "x": -4,
            "y": 2,
            "z": 0,
            "elements": [
                "rpsideas:dark_plate@10"
            ]
        },
        {
            "x": -3,
            "y": 2,
            "z": 0,
            "elements": [
                "rpsideas:dark_plate@10"
            ]
        },
        {
            "x": 2,
            "y": -2,
            "z": 0,
            "elements": [
                "chisel:technical@9"
            ]
        },
        {
            "x": 1,
            "y": -2,
            "z": 0,
            "elements": [
                "chisel:technical@9"
            ]
        },
        {
            "x": -2,
            "y": 2,
            "z": 0,
            "elements": [
                "rpsideas:dark_plate@10"
            ]
        },
        {
            "x": 0,
            "y": -2,
            "z": 0,
            "elements": [
                "chisel:technical@9"
            ]
        },
        {
            "x": -1,
            "y": 2,
            "z": 0,
            "elements": [
                "matteroverdrive:matter_plasma@0"
            ]
        },
        {
            "x": 0,
            "y": 2,
            "z": 0,
            "elements": [
                "matteroverdrive:matter_plasma@0"
            ]
        },
        {
            "x": -1,
            "y": -2,
            "z": 0,
            "elements": [
                "chisel:technical@9"
            ]
        },
        {
            "x": 1,
            "y": 2,
            "z": 0,
            "elements": [
                "matteroverdrive:industrial_glass@0"
            ]
        },
        {
            "x": -2,
            "y": -2,
            "z": 0,
            "elements": [
                "matteroverdrive:decorative.floor_tiles@8"
            ]
        },
        {
            "x": -3,
            "y": -2,
            "z": 0,
            "elements": [
                "matteroverdrive:decorative.clean@0"
            ]
        },
        {
            "x": 2,
            "y": 2,
            "z": 0,
            "elements": [
                "appliedenergistics2:fluix_slab@8"
            ]
        },
        {
            "x": -4,
            "y": -2,
            "z": 0,
            "elements": [
                "matteroverdrive:decorative.clean@0"
            ]
        },
        {
            "x": -5,
            "y": -2,
            "z": 0,
            "elements": [
                "matteroverdrive:decorative.floor_tiles@8"
            ]
        },
        {
            "x": -6,
            "y": -2,
            "z": 0,
            "elements": [
                "chisel:technical@9"
            ]
        },
        {
            "x": -7,
            "y": -2,
            "z": 0,
            "elements": [
                "chisel:technical@9"
            ]
        },
        {
            "x": -8,
            "y": -2,
            "z": 0,
            "elements": [
                "chisel:technical@9"
            ]
        },
        {
            "x": -9,
            "y": -2,
            "z": 0,
            "elements": [
                "chisel:technical@9"
            ]
        },
        {
            "x": -10,
            "y": -2,
            "z": 0,
            "elements": [
                "matteroverdrive:decorative.clean@0"
            ]
        },
        {
            "x": -11,
            "y": -2,
            "z": 0,
            "elements": [
                "matteroverdrive:decorative.tritanium_plate_stripe@0"
            ]
        },
        {
            "x": -10,
            "y": 3,
            "z": 0,
            "elements": [
                "matteroverdrive:fusion_reactor_coil@0"
            ]
        },
        {
            "x": -9,
            "y": 3,
            "z": 0,
            "elements": [
                "mekanismgenerators:generator@9"
            ]
        },
        {
            "x": -8,
            "y": 3,
            "z": 0,
            "elements": [
                "nuclearcraft:fluid_plasma@0"
            ]
        },
        {
            "x": -7,
            "y": 3,
            "z": 0,
            "elements": [
                "thermalfoundation:storage_alloy@7"
            ]
        },
        {
            "x": -6,
            "y": 3,
            "z": 0,
            "elements": [
                "thermalfoundation:storage_alloy@7"
            ]
        },
        {
            "x": -5,
            "y": 3,
            "z": 0,
            "elements": [
                "mekanism:plasticfence@15"
            ]
        },
        {
            "x": -4,
            "y": 3,
            "z": 0,
            "elements": [
                "mekanism:plasticfence@15"
            ]
        },
        {
            "x": -3,
            "y": 3,
            "z": 0,
            "elements": [
                "mekanism:plasticfence@15"
            ]
        },
        {
            "x": -2,
            "y": 3,
            "z": 0,
            "elements": [
                "mekanism:plasticfence@15"
            ]
        },
        {
            "x": -1,
            "y": 3,
            "z": 0,
            "elements": [
                "thermalfoundation:storage_alloy@7"
            ]
        },
        {
            "x": 0,
            "y": 3,
            "z": 0,
            "elements": [
                "thermalfoundation:storage_alloy@7"
            ]
        },
        {
            "x": 1,
            "y": 3,
            "z": 0,
            "elements": [
                "nuclearcraft:fluid_plasma@0"
            ]
        },
        {
            "x": 2,
            "y": 3,
            "z": 0,
            "elements": [
                "mekanismgenerators:generator@9"
            ]
        },
        {
            "x": 3,
            "y": 3,
            "z": 0,
            "elements": [
                "matteroverdrive:fusion_reactor_coil@0"
            ]
        },
        {
            "x": -9,
            "y": 4,
            "z": 0,
            "elements": [
                "appliedenergistics2:fluix_slab@0"
            ]
        },
        {
            "x": -8,
            "y": 4,
            "z": 0,
            "elements": [
                "matteroverdrive:industrial_glass@0"
            ]
        },
        {
            "x": -7,
            "y": 4,
            "z": 0,
            "elements": [
                "matteroverdrive:matter_plasma@0"
            ]
        },
        {
            "x": -6,
            "y": 4,
            "z": 0,
            "elements": [
                "matteroverdrive:matter_plasma@0"
            ]
        },
        {
            "x": -5,
            "y": 4,
            "z": 0,
            "elements": [
                "rpsideas:dark_plate@10"
            ]
        },
        {
            "x": -4,
            "y": 4,
            "z": 0,
            "elements": [
                "rpsideas:dark_plate@10"
            ]
        },
        {
            "x": -3,
            "y": 4,
            "z": 0,
            "elements": [
                "rpsideas:dark_plate@10"
            ]
        },
        {
            "x": -2,
            "y": 4,
            "z": 0,
            "elements": [
                "rpsideas:dark_plate@10"
            ]
        },
        {
            "x": -1,
            "y": 4,
            "z": 0,
            "elements": [
                "matteroverdrive:matter_plasma@0"
            ]
        },
        {
            "x": 0,
            "y": 4,
            "z": 0,
            "elements": [
                "matteroverdrive:matter_plasma@0"
            ]
        },
        {
            "x": 1,
            "y": 4,
            "z": 0,
            "elements": [
                "matteroverdrive:industrial_glass@0"
            ]
        },
        {
            "x": 2,
            "y": 4,
            "z": 0,
            "elements": [
                "appliedenergistics2:fluix_slab@0"
            ]
        },
        {
            "x": -7,
            "y": 5,
            "z": 0,
            "elements": [
                "rpsideas:dark_plate@11"
            ]
        },
        {
            "x": -6,
            "y": 5,
            "z": 0,
            "elements": [
                "rpsideas:dark_plate@11"
            ]
        },
        {
            "x": -5,
            "y": 5,
            "z": 0,
            "elements": [
                "appliedenergistics2:fluix_slab@0"
            ]
        },
        {
            "x": -4,
            "y": 5,
            "z": 0,
            "elements": [
                "appliedenergistics2:fluix_slab@0"
            ]
        },
        {
            "x": -3,
            "y": 5,
            "z": 0,
            "elements": [
                "appliedenergistics2:fluix_slab@0"
            ]
        },
        {
            "x": -2,
            "y": 5,
            "z": 0,
            "elements": [
                "appliedenergistics2:fluix_slab@0"
            ]
        },
        {
            "x": -1,
            "y": 5,
            "z": 0,
            "elements": [
                "rpsideas:dark_plate@11"
            ]
        },
        {
            "x": 0,
            "y": 5,
            "z": 0,
            "elements": [
                "rpsideas:dark_plate@11"
            ]
        },
        {
            "x": -2,
            "y": 3,
            "z": -11,
            "elements": [
                "matteroverdrive:fusion_reactor_coil@0"
            ]
        },
        {
            "x": -3,
            "y": 3,
            "z": -11,
            "elements": [
                "matteroverdrive:fusion_reactor_coil@0"
            ]
        },
        {
            "x": -4,
            "y": 3,
            "z": -11,
            "elements": [
                "matteroverdrive:fusion_reactor_coil@0"
            ]
        },
        {
            "x": -5,
            "y": 3,
            "z": -11,
            "elements": [
                "matteroverdrive:fusion_reactor_coil@0"
            ]
        },
        {
            "x": 0,
            "y": 4,
            "z": -9,
            "elements": [
                "appliedenergistics2:fluix_slab@0"
            ]
        },
        {
            "x": -1,
            "y": 4,
            "z": -9,
            "elements": [
                "appliedenergistics2:fluix_slab@0"
            ]
        },
        {
            "x": -2,
            "y": 4,
            "z": -9,
            "elements": [
                "matteroverdrive:industrial_glass@0"
            ]
        },
        {
            "x": -3,
            "y": 4,
            "z": -9,
            "elements": [
                "matteroverdrive:industrial_glass@0"
            ]
        },
        {
            "x": -4,
            "y": 4,
            "z": -9,
            "elements": [
                "matteroverdrive:industrial_glass@0"
            ]
        },
        {
            "x": -5,
            "y": 4,
            "z": -9,
            "elements": [
                "matteroverdrive:industrial_glass@0"
            ]
        },
        {
            "x": -6,
            "y": 4,
            "z": -9,
            "elements": [
                "appliedenergistics2:fluix_slab@0"
            ]
        },
        {
            "x": -7,
            "y": 4,
            "z": -9,
            "elements": [
                "appliedenergistics2:fluix_slab@0"
            ]
        },
        {
            "x": 1,
            "y": 3,
            "z": -9,
            "elements": [
                "matteroverdrive:fusion_reactor_coil@0"
            ]
        },
        {
            "x": 0,
            "y": 3,
            "z": -9,
            "elements": [
                "mekanismgenerators:generator@9"
            ]
        },
        {
            "x": -1,
            "y": 3,
            "z": -9,
            "elements": [
                "mekanismgenerators:generator@9"
            ]
        },
        {
            "x": -2,
            "y": 3,
            "z": -9,
            "elements": [
                "nuclearcraft:fluid_plasma@0"
            ]
        },
        {
            "x": -3,
            "y": 3,
            "z": -9,
            "elements": [
                "nuclearcraft:fluid_plasma@0"
            ]
        },
        {
            "x": -4,
            "y": 3,
            "z": -9,
            "elements": [
                "nuclearcraft:fluid_plasma@0"
            ]
        },
        {
            "x": -5,
            "y": 3,
            "z": -9,
            "elements": [
                "nuclearcraft:fluid_plasma@0"
            ]
        },
        {
            "x": -6,
            "y": 3,
            "z": -9,
            "elements": [
                "mekanismgenerators:generator@9"
            ]
        },
        {
            "x": -7,
            "y": 3,
            "z": -9,
            "elements": [
                "mekanismgenerators:generator@9"
            ]
        },
        {
            "x": -8,
            "y": 3,
            "z": -9,
            "elements": [
                "matteroverdrive:fusion_reactor_coil@0"
            ]
        },
        {
            "x": 1,
            "y": -2,
            "z": -11,
            "elements": [
                "matteroverdrive:decorative.tritanium_plate_stripe@0"
            ]
        },
        {
            "x": 0,
            "y": -2,
            "z": -11,
            "elements": [
                "matteroverdrive:decorative.tritanium_plate_stripe@0"
            ]
        },
        {
            "x": -1,
            "y": -2,
            "z": -11,
            "elements": [
                "matteroverdrive:decorative.tritanium_plate_stripe@0"
            ]
        },
        {
            "x": 0,
            "y": 2,
            "z": -9,
            "elements": [
                "appliedenergistics2:fluix_slab@8"
            ]
        },
        {
            "x": -2,
            "y": -2,
            "z": -11,
            "elements": [
                "matteroverdrive:decorative.tritanium_plate_stripe@0"
            ]
        },
        {
            "x": -3,
            "y": -2,
            "z": -11,
            "elements": [
                "matteroverdrive:decorative.tritanium_plate_stripe@0"
            ]
        },
        {
            "x": -1,
            "y": 2,
            "z": -9,
            "elements": [
                "appliedenergistics2:fluix_slab@8"
            ]
        },
        {
            "x": -4,
            "y": -2,
            "z": -11,
            "elements": [
                "matteroverdrive:decorative.tritanium_plate_stripe@0"
            ]
        },
        {
            "x": -2,
            "y": 2,
            "z": -9,
            "elements": [
                "matteroverdrive:industrial_glass@0"
            ]
        },
        {
            "x": -5,
            "y": -2,
            "z": -11,
            "elements": [
                "matteroverdrive:decorative.tritanium_plate_stripe@0"
            ]
        },
        {
            "x": -3,
            "y": 2,
            "z": -9,
            "elements": [
                "matteroverdrive:industrial_glass@0"
            ]
        },
        {
            "x": -6,
            "y": -2,
            "z": -11,
            "elements": [
                "matteroverdrive:decorative.tritanium_plate_stripe@0"
            ]
        },
        {
            "x": -4,
            "y": 2,
            "z": -9,
            "elements": [
                "matteroverdrive:industrial_glass@0"
            ]
        },
        {
            "x": -7,
            "y": -2,
            "z": -11,
            "elements": [
                "matteroverdrive:decorative.tritanium_plate_stripe@0"
            ]
        },
        {
            "x": -5,
            "y": 2,
            "z": -9,
            "elements": [
                "matteroverdrive:industrial_glass@0"
            ]
        },
        {
            "x": -8,
            "y": -2,
            "z": -11,
            "elements": [
                "matteroverdrive:decorative.tritanium_plate_stripe@0"
            ]
        },
        {
            "x": -6,
            "y": 2,
            "z": -9,
            "elements": [
                "appliedenergistics2:fluix_slab@8"
            ]
        },
        {
            "x": -7,
            "y": 2,
            "z": -9,
            "elements": [
                "appliedenergistics2:fluix_slab@8"
            ]
        },
        {
            "x": 0,
            "y": 5,
            "z": -7,
            "elements": [
                "rpsideas:dark_plate@11"
            ]
        },
        {
            "x": -1,
            "y": 5,
            "z": -7,
            "elements": [
                "rpsideas:dark_plate@11"
            ]
        },
        {
            "x": -2,
            "y": 5,
            "z": -7,
            "elements": [
                "appliedenergistics2:fluix_slab@0"
            ]
        },
        {
            "x": -3,
            "y": 5,
            "z": -7,
            "elements": [
                "appliedenergistics2:fluix_slab@0"
            ]
        },
        {
            "x": -4,
            "y": 5,
            "z": -7,
            "elements": [
                "appliedenergistics2:fluix_slab@0"
            ]
        },
        {
            "x": -5,
            "y": 5,
            "z": -7,
            "elements": [
                "appliedenergistics2:fluix_slab@0"
            ]
        },
        {
            "x": -6,
            "y": 5,
            "z": -7,
            "elements": [
                "rpsideas:dark_plate@11"
            ]
        },
        {
            "x": -7,
            "y": 5,
            "z": -7,
            "elements": [
                "rpsideas:dark_plate@11"
            ]
        },
        {
            "x": 2,
            "y": 4,
            "z": -7,
            "elements": [
                "appliedenergistics2:fluix_slab@0"
            ]
        },
        {
            "x": 1,
            "y": 4,
            "z": -7,
            "elements": [
                "matteroverdrive:industrial_glass@0"
            ]
        },
        {
            "x": 0,
            "y": 4,
            "z": -7,
            "elements": [
                "matteroverdrive:matter_plasma@0"
            ]
        },
        {
            "x": -1,
            "y": 4,
            "z": -7,
            "elements": [
                "matteroverdrive:matter_plasma@0"
            ]
        },
        {
            "x": -2,
            "y": 4,
            "z": -7,
            "elements": [
                "rpsideas:dark_plate@10"
            ]
        },
        {
            "x": -3,
            "y": 4,
            "z": -7,
            "elements": [
                "rpsideas:dark_plate@10"
            ]
        },
        {
            "x": -4,
            "y": 4,
            "z": -7,
            "elements": [
                "rpsideas:dark_plate@10"
            ]
        },
        {
            "x": -5,
            "y": 4,
            "z": -7,
            "elements": [
                "rpsideas:dark_plate@10"
            ]
        },
        {
            "x": -6,
            "y": 4,
            "z": -7,
            "elements": [
                "matteroverdrive:matter_plasma@0"
            ]
        },
        {
            "x": -7,
            "y": 4,
            "z": -7,
            "elements": [
                "matteroverdrive:matter_plasma@0"
            ]
        },
        {
            "x": -8,
            "y": 4,
            "z": -7,
            "elements": [
                "matteroverdrive:industrial_glass@0"
            ]
        },
        {
            "x": -9,
            "y": 4,
            "z": -7,
            "elements": [
                "appliedenergistics2:fluix_slab@0"
            ]
        },
        {
            "x": 3,
            "y": 3,
            "z": -7,
            "elements": [
                "matteroverdrive:fusion_reactor_coil@0"
            ]
        },
        {
            "x": 2,
            "y": 3,
            "z": -7,
            "elements": [
                "mekanismgenerators:generator@9"
            ]
        },
        {
            "x": 1,
            "y": 3,
            "z": -7,
            "elements": [
                "nuclearcraft:fluid_plasma@0"
            ]
        },
        {
            "x": 0,
            "y": 3,
            "z": -7,
            "elements": [
                "thermalfoundation:storage_alloy@7"
            ]
        },
        {
            "x": -1,
            "y": 3,
            "z": -7,
            "elements": [
                "thermalfoundation:storage_alloy@7"
            ]
        },
        {
            "x": -2,
            "y": 3,
            "z": -7,
            "elements": [
                "mekanism:plasticfence@15"
            ]
        },
        {
            "x": -3,
            "y": 3,
            "z": -7,
            "elements": [
                "mekanism:plasticfence@15"
            ]
        },
        {
            "x": -4,
            "y": 3,
            "z": -7,
            "elements": [
                "mekanism:plasticfence@15"
            ]
        },
        {
            "x": -5,
            "y": 3,
            "z": -7,
            "elements": [
                "mekanism:plasticfence@15"
            ]
        },
        {
            "x": -6,
            "y": 3,
            "z": -7,
            "elements": [
                "thermalfoundation:storage_alloy@7"
            ]
        },
        {
            "x": -7,
            "y": 3,
            "z": -7,
            "elements": [
                "thermalfoundation:storage_alloy@7"
            ]
        },
        {
            "x": -8,
            "y": 3,
            "z": -7,
            "elements": [
                "nuclearcraft:fluid_plasma@0"
            ]
        },
        {
            "x": -9,
            "y": 3,
            "z": -7,
            "elements": [
                "mekanismgenerators:generator@9"
            ]
        },
        {
            "x": -10,
            "y": 3,
            "z": -7,
            "elements": [
                "matteroverdrive:fusion_reactor_coil@0"
            ]
        },
        {
            "x": 3,
            "y": -2,
            "z": -9,
            "elements": [
                "matteroverdrive:decorative.tritanium_plate_stripe@0"
            ]
        },
        {
            "x": 2,
            "y": -2,
            "z": -9,
            "elements": [
                "chisel:technical@9"
            ]
        },
        {
            "x": 1,
            "y": -2,
            "z": -9,
            "elements": [
                "chisel:technical@9"
            ]
        },
        {
            "x": 0,
            "y": -2,
            "z": -9,
            "elements": [
                "chisel:technical@9"
            ]
        },
        {
            "x": 2,
            "y": 2,
            "z": -7,
            "elements": [
                "appliedenergistics2:fluix_slab@8"
            ]
        },
        {
            "x": -1,
            "y": -2,
            "z": -9,
            "elements": [
                "chisel:technical@9"
            ]
        },
        {
            "x": 1,
            "y": 2,
            "z": -7,
            "elements": [
                "matteroverdrive:industrial_glass@0"
            ]
        },
        {
            "x": 0,
            "y": 2,
            "z": -7,
            "elements": [
                "matteroverdrive:matter_plasma@0"
            ]
        },
        {
            "x": -2,
            "y": -2,
            "z": -9,
            "elements": [
                "matteroverdrive:decorative.floor_tiles@8"
            ]
        },
        {
            "x": -3,
            "y": -2,
            "z": -9,
            "elements": [
                "matteroverdrive:decorative.clean@0"
            ]
        },
        {
            "x": -1,
            "y": 2,
            "z": -7,
            "elements": [
                "matteroverdrive:matter_plasma@0"
            ]
        },
        {
            "x": -4,
            "y": -2,
            "z": -9,
            "elements": [
                "matteroverdrive:decorative.clean@0"
            ]
        },
        {
            "x": -2,
            "y": 2,
            "z": -7,
            "elements": [
                "rpsideas:dark_plate@10"
            ]
        },
        {
            "x": -5,
            "y": -2,
            "z": -9,
            "elements": [
                "matteroverdrive:decorative.floor_tiles@8"
            ]
        },
        {
            "x": -3,
            "y": 2,
            "z": -7,
            "elements": [
                "rpsideas:dark_plate@10"
            ]
        },
        {
            "x": -6,
            "y": -2,
            "z": -9,
            "elements": [
                "chisel:technical@9"
            ]
        },
        {
            "x": -4,
            "y": 2,
            "z": -7,
            "elements": [
                "rpsideas:dark_plate@10"
            ]
        },
        {
            "x": -7,
            "y": -2,
            "z": -9,
            "elements": [
                "chisel:technical@9"
            ]
        },
        {
            "x": -5,
            "y": 2,
            "z": -7,
            "elements": [
                "rpsideas:dark_plate@10"
            ]
        },
        {
            "x": -8,
            "y": -2,
            "z": -9,
            "elements": [
                "chisel:technical@9"
            ]
        },
        {
            "x": -6,
            "y": 2,
            "z": -7,
            "elements": [
                "matteroverdrive:matter_plasma@0"
            ]
        },
        {
            "x": -9,
            "y": -2,
            "z": -9,
            "elements": [
                "chisel:technical@9"
            ]
        },
        {
            "x": -7,
            "y": 2,
            "z": -7,
            "elements": [
                "matteroverdrive:matter_plasma@0"
            ]
        },
        {
            "x": -10,
            "y": -2,
            "z": -9,
            "elements": [
                "matteroverdrive:decorative.tritanium_plate_stripe@0"
            ]
        },
        {
            "x": -8,
            "y": 2,
            "z": -7,
            "elements": [
                "matteroverdrive:industrial_glass@0"
            ]
        },
        {
            "x": -9,
            "y": 2,
            "z": -7,
            "elements": [
                "appliedenergistics2:fluix_slab@8"
            ]
        },
        {
            "x": 1,
            "y": 1,
            "z": -7,
            "elements": [
                "chisel:technicalnew@2"
            ]
        },
        {
            "x": 0,
            "y": 1,
            "z": -7,
            "elements": [
                "rpsideas:dark_plate@11"
            ]
        },
        {
            "x": -1,
            "y": 1,
            "z": -7,
            "elements": [
                "rpsideas:dark_plate@11"
            ]
        },
        {
            "x": 1,
            "y": 5,
            "z": -5,
            "elements": [
                "rpsideas:dark_plate@11"
            ]
        },
        {
            "x": 0,
            "y": 5,
            "z": -5,
            "elements": [
                "appliedenergistics2:fluix_slab@0"
            ]
        },
        {
            "x": -2,
            "y": 1,
            "z": -7,
            "elements": [
                "appliedenergistics2:fluix_slab@8"
            ]
        },
        {
            "x": -3,
            "y": 1,
            "z": -7,
            "elements": [
                "appliedenergistics2:fluix_slab@8"
            ]
        },
        {
            "x": -4,
            "y": 1,
            "z": -7,
            "elements": [
                "appliedenergistics2:fluix_slab@8"
            ]
        },
        {
            "x": -5,
            "y": 1,
            "z": -7,
            "elements": [
                "appliedenergistics2:fluix_slab@8"
            ]
        },
        {
            "x": -6,
            "y": 1,
            "z": -7,
            "elements": [
                "rpsideas:dark_plate@11"
            ]
        },
        {
            "x": -7,
            "y": 1,
            "z": -7,
            "elements": [
                "rpsideas:dark_plate@11"
            ]
        },
        {
            "x": -8,
            "y": 1,
            "z": -7,
            "elements": [
                "chisel:technicalnew@2"
            ]
        },
        {
            "x": -7,
            "y": 5,
            "z": -5,
            "elements": [
                "appliedenergistics2:fluix_slab@0"
            ]
        },
        {
            "x": -8,
            "y": 5,
            "z": -5,
            "elements": [
                "rpsideas:dark_plate@11"
            ]
        },
        {
            "x": 3,
            "y": 4,
            "z": -5,
            "elements": [
                "appliedenergistics2:fluix_slab@0"
            ]
        },
        {
            "x": 1,
            "y": 0,
            "z": -7,
            "elements": [
                "chisel:technicalnew@2"
            ]
        },
        {
            "x": 2,
            "y": 4,
            "z": -5,
            "elements": [
                "matteroverdrive:industrial_glass@0"
            ]
        },
        {
            "x": 0,
            "y": 0,
            "z": -7,
            "elements": [
                "modularmachinery:blockfluidoutputhatch"
            ]
        },
        {
            "x": 1,
            "y": 4,
            "z": -5,
            "elements": [
                "matteroverdrive:matter_plasma@0"
            ]
        },
        {
            "x": 0,
            "y": 4,
            "z": -5,
            "elements": [
                "rpsideas:dark_plate@10"
            ]
        },
        {
            "x": -1,
            "y": 4,
            "z": -5,
            "elements": [
                "appliedenergistics2:quartz_slab@0"
            ]
        },
        {
            "x": -7,
            "y": 0,
            "z": -7,
            "elements": [
                "modularmachinery:blockfluidoutputhatch"
            ]
        },
        {
            "x": -8,
            "y": 0,
            "z": -7,
            "elements": [
                "chisel:technicalnew@2"
            ]
        },
        {
            "x": -6,
            "y": 4,
            "z": -5,
            "elements": [
                "appliedenergistics2:quartz_slab@0"
            ]
        },
        {
            "x": -7,
            "y": 4,
            "z": -5,
            "elements": [
                "rpsideas:dark_plate@10"
            ]
        },
        {
            "x": -8,
            "y": 4,
            "z": -5,
            "elements": [
                "matteroverdrive:matter_plasma@0"
            ]
        },
        {
            "x": -9,
            "y": 4,
            "z": -5,
            "elements": [
                "matteroverdrive:industrial_glass@0"
            ]
        },
        {
            "x": -10,
            "y": 4,
            "z": -5,
            "elements": [
                "appliedenergistics2:fluix_slab@0"
            ]
        },
        {
            "x": 4,
            "y": 3,
            "z": -5,
            "elements": [
                "matteroverdrive:fusion_reactor_coil@0"
            ]
        },
        {
            "x": 3,
            "y": 3,
            "z": -5,
            "elements": [
                "mekanismgenerators:generator@9"
            ]
        },
        {
            "x": 1,
            "y": -1,
            "z": -7,
            "elements": [
                "chisel:technicalnew@2"
            ]
        },
        {
            "x": 0,
            "y": -1,
            "z": -7,
            "elements": [
                "modularmachinery:blockenergyinputhatch"
            ]
        },
        {
            "x": 2,
            "y": 3,
            "z": -5,
            "elements": [
                "nuclearcraft:fluid_plasma@0"
            ]
        },
        {
            "x": 1,
            "y": 3,
            "z": -5,
            "elements": [
                "thermalfoundation:storage_alloy@7"
            ]
        },
        {
            "x": 0,
            "y": 3,
            "z": -5,
            "elements": [
                "mekanism:plasticfence@15"
            ]
        },
        {
            "x": -1,
            "y": 3,
            "z": -5,
            "elements": [
                "ebwizardry:crystal_block@2"
            ]
        },
        {
            "x": -7,
            "y": -1,
            "z": -7,
            "elements": [
                "modularmachinery:blockenergyinputhatch"
            ]
        },
        {
            "x": -8,
            "y": -1,
            "z": -7,
            "elements": [
                "chisel:technicalnew@2"
            ]
        },
        {
            "x": -6,
            "y": 3,
            "z": -5,
            "elements": [
                "ebwizardry:crystal_block@6"
            ]
        },
        {
            "x": -7,
            "y": 3,
            "z": -5,
            "elements": [
                "mekanism:plasticfence@15"
            ]
        },
        {
            "x": -8,
            "y": 3,
            "z": -5,
            "elements": [
                "thermalfoundation:storage_alloy@7"
            ]
        },
        {
            "x": -9,
            "y": 3,
            "z": -5,
            "elements": [
                "nuclearcraft:fluid_plasma@0"
            ]
        },
        {
            "x": -10,
            "y": 3,
            "z": -5,
            "elements": [
                "mekanismgenerators:generator@9"
            ]
        },
        {
            "x": -11,
            "y": 3,
            "z": -5,
            "elements": [
                "matteroverdrive:fusion_reactor_coil@0"
            ]
        },
        {
            "x": 4,
            "y": -2,
            "z": -7,
            "elements": [
                "matteroverdrive:decorative.tritanium_plate_stripe@0"
            ]
        },
        {
            "x": 3,
            "y": -2,
            "z": -7,
            "elements": [
                "matteroverdrive:decorative.clean@0"
            ]
        },
        {
            "x": 2,
            "y": -2,
            "z": -7,
            "elements": [
                "chisel:technical@9"
            ]
        },
        {
            "x": 3,
            "y": 2,
            "z": -5,
            "elements": [
                "appliedenergistics2:fluix_slab@8"
            ]
        },
        {
            "x": 1,
            "y": -2,
            "z": -7,
            "elements": [
                "chisel:technical@9"
            ]
        },
        {
            "x": 0,
            "y": -2,
            "z": -7,
            "elements": [
                "chisel:technical@9"
            ]
        },
        {
            "x": 2,
            "y": 2,
            "z": -5,
            "elements": [
                "matteroverdrive:industrial_glass@0"
            ]
        },
        {
            "x": -1,
            "y": -2,
            "z": -7,
            "elements": [
                "chisel:technical@9"
            ]
        },
        {
            "x": 1,
            "y": 2,
            "z": -5,
            "elements": [
                "matteroverdrive:matter_plasma@0"
            ]
        },
        {
            "x": 0,
            "y": 2,
            "z": -5,
            "elements": [
                "rpsideas:dark_plate@10"
            ]
        },
        {
            "x": -2,
            "y": -2,
            "z": -7,
            "elements": [
                "matteroverdrive:decorative.floor_tiles@8"
            ]
        },
        {
            "x": -3,
            "y": -2,
            "z": -7,
            "elements": [
                "matteroverdrive:decorative.clean@0"
            ]
        },
        {
            "x": -1,
            "y": 2,
            "z": -5,
            "elements": [
                "appliedenergistics2:quartz_slab@8"
            ]
        },
        {
            "x": -4,
            "y": -2,
            "z": -7,
            "elements": [
                "matteroverdrive:decorative.clean@0"
            ]
        },
        {
            "x": -5,
            "y": -2,
            "z": -7,
            "elements": [
                "matteroverdrive:decorative.floor_tiles@8"
            ]
        },
        {
            "x": -6,
            "y": -2,
            "z": -7,
            "elements": [
                "chisel:technical@9"
            ]
        },
        {
            "x": -7,
            "y": -2,
            "z": -7,
            "elements": [
                "chisel:technical@9"
            ]
        },
        {
            "x": -8,
            "y": -2,
            "z": -7,
            "elements": [
                "chisel:technical@9"
            ]
        },
        {
            "x": -6,
            "y": 2,
            "z": -5,
            "elements": [
                "appliedenergistics2:quartz_slab@8"
            ]
        },
        {
            "x": -9,
            "y": -2,
            "z": -7,
            "elements": [
                "chisel:technical@9"
            ]
        },
        {
            "x": -7,
            "y": 2,
            "z": -5,
            "elements": [
                "rpsideas:dark_plate@10"
            ]
        },
        {
            "x": -10,
            "y": -2,
            "z": -7,
            "elements": [
                "matteroverdrive:decorative.clean@0"
            ]
        },
        {
            "x": -8,
            "y": 2,
            "z": -5,
            "elements": [
                "matteroverdrive:matter_plasma@0"
            ]
        },
        {
            "x": -11,
            "y": -2,
            "z": -7,
            "elements": [
                "matteroverdrive:decorative.tritanium_plate_stripe@0"
            ]
        },
        {
            "x": -9,
            "y": 2,
            "z": -5,
            "elements": [
                "matteroverdrive:industrial_glass@0"
            ]
        },
        {
            "x": -10,
            "y": 2,
            "z": -5,
            "elements": [
                "appliedenergistics2:fluix_slab@8"
            ]
        },
        {
            "x": 1,
            "y": 1,
            "z": -5,
            "elements": [
                "rpsideas:dark_plate@11"
            ]
        },
        {
            "x": 0,
            "y": 1,
            "z": -5,
            "elements": [
                "appliedenergistics2:fluix_slab@8"
            ]
        },
        {
            "x": 1,
            "y": 5,
            "z": -3,
            "elements": [
                "rpsideas:dark_plate@11"
            ]
        },
        {
            "x": 0,
            "y": 5,
            "z": -3,
            "elements": [
                "appliedenergistics2:fluix_slab@0"
            ]
        },
        {
            "x": -7,
            "y": 1,
            "z": -5,
            "elements": [
                "appliedenergistics2:fluix_slab@8"
            ]
        },
        {
            "x": -8,
            "y": 1,
            "z": -5,
            "elements": [
                "rpsideas:dark_plate@11"
            ]
        },
        {
            "x": -7,
            "y": 5,
            "z": -3,
            "elements": [
                "appliedenergistics2:fluix_slab@0"
            ]
        },
        {
            "x": -8,
            "y": 5,
            "z": -3,
            "elements": [
                "rpsideas:dark_plate@11"
            ]
        },
        {
            "x": 3,
            "y": 4,
            "z": -3,
            "elements": [
                "appliedenergistics2:fluix_slab@0"
            ]
        },
        {
            "x": 2,
            "y": 4,
            "z": -3,
            "elements": [
                "matteroverdrive:industrial_glass@0"
            ]
        },
        {
            "x": 1,
            "y": 4,
            "z": -3,
            "elements": [
                "matteroverdrive:matter_plasma@0"
            ]
        },
        {
            "x": 0,
            "y": 4,
            "z": -3,
            "elements": [
                "rpsideas:dark_plate@10"
            ]
        },
        {
            "x": -1,
            "y": 4,
            "z": -3,
            "elements": [
                "appliedenergistics2:quartz_slab@0"
            ]
        },
        {
            "x": -6,
            "y": 4,
            "z": -3,
            "elements": [
                "appliedenergistics2:quartz_slab@0"
            ]
        },
        {
            "x": -7,
            "y": 4,
            "z": -3,
            "elements": [
                "rpsideas:dark_plate@10"
            ]
        },
        {
            "x": -8,
            "y": 4,
            "z": -3,
            "elements": [
                "matteroverdrive:matter_plasma@0"
            ]
        },
        {
            "x": -9,
            "y": 4,
            "z": -3,
            "elements": [
                "matteroverdrive:industrial_glass@0"
            ]
        },
        {
            "x": -10,
            "y": 4,
            "z": -3,
            "elements": [
                "appliedenergistics2:fluix_slab@0"
            ]
        },
        {
            "x": 4,
            "y": 3,
            "z": -3,
            "elements": [
                "matteroverdrive:fusion_reactor_coil@0"
            ]
        },
        {
            "x": 3,
            "y": 3,
            "z": -3,
            "elements": [
                "mekanismgenerators:generator@9"
            ]
        },
        {
            "x": 2,
            "y": 3,
            "z": -3,
            "elements": [
                "nuclearcraft:fluid_plasma@0"
            ]
        },
        {
            "x": 1,
            "y": 3,
            "z": -3,
            "elements": [
                "thermalfoundation:storage_alloy@7"
            ]
        },
        {
            "x": 0,
            "y": 3,
            "z": -3,
            "elements": [
                "mekanism:plasticfence@15"
            ]
        },
        {
            "x": -1,
            "y": 3,
            "z": -3,
            "elements": [
                "tconevo:metal_block@7"
            ]
        },
        {
            "x": -6,
            "y": 3,
            "z": -3,
            "elements": [
                "tconevo:metal_block@7"
            ]
        },
        {
            "x": -7,
            "y": 3,
            "z": -3,
            "elements": [
                "mekanism:plasticfence@15"
            ]
        },
        {
            "x": -8,
            "y": 3,
            "z": -3,
            "elements": [
                "thermalfoundation:storage_alloy@7"
            ]
        },
        {
            "x": -9,
            "y": 3,
            "z": -3,
            "elements": [
                "nuclearcraft:fluid_plasma@0"
            ]
        },
        {
            "x": -10,
            "y": 3,
            "z": -3,
            "elements": [
                "mekanismgenerators:generator@9"
            ]
        },
        {
            "x": -11,
            "y": 3,
            "z": -3,
            "elements": [
                "matteroverdrive:fusion_reactor_coil@0"
            ]
        },
        {
            "x": -10,
            "y": -2,
            "z": 3,
            "elements": [
                "matteroverdrive:decorative.tritanium_plate_stripe@0"
            ]
        },
        {
            "x": -9,
            "y": -2,
            "z": 3,
            "elements": [
                "matteroverdrive:decorative.tritanium_plate_stripe@0"
            ]
        },
        {
            "x": -8,
            "y": -2,
            "z": 3,
            "elements": [
                "matteroverdrive:decorative.clean@0"
            ]
        },
        {
            "x": -7,
            "y": -2,
            "z": 3,
            "elements": [
                "matteroverdrive:decorative.clean@0"
            ]
        },
        {
            "x": 4,
            "y": -2,
            "z": -5,
            "elements": [
                "matteroverdrive:decorative.tritanium_plate_stripe@0"
            ]
        },
        {
            "x": 3,
            "y": -2,
            "z": -5,
            "elements": [
                "matteroverdrive:decorative.floor_tiles@8"
            ]
        },
        {
            "x": -6,
            "y": -2,
            "z": 3,
            "elements": [
                "matteroverdrive:decorative.clean@0"
            ]
        },
        {
            "x": -5,
            "y": -2,
            "z": 3,
            "elements": [
                "matteroverdrive:decorative.floor_tiles@8"
            ]
        },
        {
            "x": 2,
            "y": -2,
            "z": -5,
            "elements": [
                "matteroverdrive:decorative.floor_tiles@8"
            ]
        },
        {
            "x": 3,
            "y": 2,
            "z": -3,
            "elements": [
                "appliedenergistics2:fluix_slab@8"
            ]
        },
        {
            "x": 1,
            "y": -2,
            "z": -5,
            "elements": [
                "matteroverdrive:decorative.floor_tiles@8"
            ]
        },
        {
            "x": -4,
            "y": -2,
            "z": 3,
            "elements": [
                "matteroverdrive:decorative.clean@0"
            ]
        },
        {
            "x": 0,
            "y": -2,
            "z": -5,
            "elements": [
                "matteroverdrive:decorative.floor_tiles@8"
            ]
        },
        {
            "x": -3,
            "y": -2,
            "z": 3,
            "elements": [
                "matteroverdrive:decorative.clean@0"
            ]
        },
        {
            "x": 2,
            "y": 2,
            "z": -3,
            "elements": [
                "matteroverdrive:industrial_glass@0"
            ]
        },
        {
            "x": -1,
            "y": -2,
            "z": -5,
            "elements": [
                "matteroverdrive:decorative.floor_tiles@8"
            ]
        },
        {
            "x": 1,
            "y": 2,
            "z": -3,
            "elements": [
                "matteroverdrive:matter_plasma@0"
            ]
        },
        {
            "x": -2,
            "y": -2,
            "z": 3,
            "elements": [
                "matteroverdrive:decorative.floor_tiles@8"
            ]
        },
        {
            "x": 0,
            "y": 2,
            "z": -3,
            "elements": [
                "rpsideas:dark_plate@10"
            ]
        },
        {
            "x": -1,
            "y": -2,
            "z": 3,
            "elements": [
                "matteroverdrive:decorative.clean@0"
            ]
        },
        {
            "x": -2,
            "y": -2,
            "z": -5,
            "elements": [
                "matteroverdrive:decorative.floor_tiles@8"
            ]
        },
        {
            "x": 0,
            "y": -2,
            "z": 3,
            "elements": [
                "matteroverdrive:decorative.clean@0"
            ]
        },
        {
            "x": -3,
            "y": -2,
            "z": -5,
            "elements": [
                "matteroverdrive:decorative.clean@0"
            ]
        },
        {
            "x": -1,
            "y": 2,
            "z": -3,
            "elements": [
                "appliedenergistics2:quartz_slab@8"
            ]
        },
        {
            "x": 1,
            "y": -2,
            "z": 3,
            "elements": [
                "matteroverdrive:decorative.clean@0"
            ]
        },
        {
            "x": -4,
            "y": -2,
            "z": -5,
            "elements": [
                "matteroverdrive:decorative.clean@0"
            ]
        },
        {
            "x": -5,
            "y": -2,
            "z": -5,
            "elements": [
                "matteroverdrive:decorative.floor_tiles@8"
            ]
        },
        {
            "x": 2,
            "y": -2,
            "z": 3,
            "elements": [
                "matteroverdrive:decorative.tritanium_plate_stripe@0"
            ]
        },
        {
            "x": 3,
            "y": -2,
            "z": 3,
            "elements": [
                "matteroverdrive:decorative.tritanium_plate_stripe@0"
            ]
        },
        {
            "x": -6,
            "y": -2,
            "z": -5,
            "elements": [
                "matteroverdrive:decorative.floor_tiles@8"
            ]
        },
        {
            "x": -7,
            "y": -2,
            "z": -5,
            "elements": [
                "matteroverdrive:decorative.floor_tiles@8"
            ]
        },
        {
            "x": -8,
            "y": -2,
            "z": -5,
            "elements": [
                "matteroverdrive:decorative.floor_tiles@8"
            ]
        },
        {
            "x": -6,
            "y": 2,
            "z": -3,
            "elements": [
                "appliedenergistics2:quartz_slab@8"
            ]
        },
        {
            "x": -9,
            "y": -2,
            "z": -5,
            "elements": [
                "matteroverdrive:decorative.floor_tiles@8"
            ]
        },
        {
            "x": -7,
            "y": 2,
            "z": -3,
            "elements": [
                "rpsideas:dark_plate@10"
            ]
        },
        {
            "x": -10,
            "y": -2,
            "z": -5,
            "elements": [
                "matteroverdrive:decorative.floor_tiles@8"
            ]
        },
        {
            "x": -8,
            "y": 2,
            "z": -3,
            "elements": [
                "matteroverdrive:matter_plasma@0"
            ]
        },
        {
            "x": -11,
            "y": -2,
            "z": -5,
            "elements": [
                "matteroverdrive:decorative.tritanium_plate_stripe@0"
            ]
        },
        {
            "x": -9,
            "y": 2,
            "z": -3,
            "elements": [
                "matteroverdrive:industrial_glass@0"
            ]
        },
        {
            "x": -10,
            "y": 2,
            "z": -3,
            "elements": [
                "appliedenergistics2:fluix_slab@8"
            ]
        },
        {
            "x": -6,
            "y": -1,
            "z": 3,
            "elements": [
                "matteroverdrive:decorative.separator@0"
            ]
        },
        {
            "x": 1,
            "y": 1,
            "z": -3,
            "elements": [
                "rpsideas:dark_plate@11"
            ]
        },
        {
            "x": 0,
            "y": 1,
            "z": -3,
            "elements": [
                "appliedenergistics2:fluix_slab@8"
            ]
        },
        {
            "x": -1,
            "y": -1,
            "z": 3,
            "elements": [
                "matteroverdrive:decorative.separator@0"
            ]
        },
        {
            "x": 0,
            "y": 5,
            "z": -1,
            "elements": [
                "rpsideas:dark_plate@11"
            ]
        },
        {
            "x": -1,
            "y": 5,
            "z": -1,
            "elements": [
                "appliedenergistics2:fluix_slab@0"
            ]
        },
        {
            "x": -7,
            "y": 1,
            "z": -3,
            "elements": [
                "appliedenergistics2:fluix_slab@8"
            ]
        },
        {
            "x": -8,
            "y": 1,
            "z": -3,
            "elements": [
                "rpsideas:dark_plate@11"
            ]
        },
        {
            "x": -6,
            "y": 5,
            "z": -1,
            "elements": [
                "appliedenergistics2:fluix_slab@0"
            ]
        },
        {
            "x": -7,
            "y": 5,
            "z": -1,
            "elements": [
                "rpsideas:dark_plate@11"
            ]
        },
        {
            "x": -6,
            "y": 0,
            "z": 3,
            "elements": [
                "modularmachinery:blockcasing@5"
            ]
        },
        {
            "x": -1,
            "y": 0,
            "z": 3,
            "elements": [
                "modularmachinery:blockcasing@5"
            ]
        },
        {
            "x": 2,
            "y": 4,
            "z": -1,
            "elements": [
                "appliedenergistics2:fluix_slab@0"
            ]
        },
        {
            "x": 1,
            "y": 4,
            "z": -1,
            "elements": [
                "matteroverdrive:industrial_glass@0"
            ]
        },
        {
            "x": 0,
            "y": 4,
            "z": -1,
            "elements": [
                "matteroverdrive:matter_plasma@0"
            ]
        },
        {
            "x": -1,
            "y": 4,
            "z": -1,
            "elements": [
                "rpsideas:dark_plate@10"
            ]
        },
        {
            "x": -2,
            "y": 4,
            "z": -1,
            "elements": [
                "appliedenergistics2:quartz_slab@0"
            ]
        },
        {
            "x": -3,
            "y": 4,
            "z": -1,
            "elements": [
                "appliedenergistics2:quartz_slab@0"
            ]
        },
        {
            "x": -4,
            "y": 4,
            "z": -1,
            "elements": [
                "appliedenergistics2:quartz_slab@0"
            ]
        },
        {
            "x": -5,
            "y": 4,
            "z": -1,
            "elements": [
                "appliedenergistics2:quartz_slab@0"
            ]
        },
        {
            "x": -6,
            "y": 4,
            "z": -1,
            "elements": [
                "rpsideas:dark_plate@10"
            ]
        },
        {
            "x": -7,
            "y": 4,
            "z": -1,
            "elements": [
                "matteroverdrive:matter_plasma@0"
            ]
        },
        {
            "x": -8,
            "y": 4,
            "z": -1,
            "elements": [
                "matteroverdrive:industrial_glass@0"
            ]
        },
        {
            "x": -9,
            "y": 4,
            "z": -1,
            "elements": [
                "appliedenergistics2:fluix_slab@0"
            ]
        },
        {
            "x": -6,
            "y": 1,
            "z": 3,
            "elements": [
                "modularmachinery:blockcasing@5"
            ]
        },
        {
            "x": 3,
            "y": 3,
            "z": -1,
            "elements": [
                "matteroverdrive:fusion_reactor_coil@0"
            ]
        },
        {
            "x": -1,
            "y": 1,
            "z": 3,
            "elements": [
                "modularmachinery:blockcasing@5"
            ]
        },
        {
            "x": 2,
            "y": 3,
            "z": -1,
            "elements": [
                "mekanismgenerators:generator@9"
            ]
        },
        {
            "x": 1,
            "y": 3,
            "z": -1,
            "elements": [
                "nuclearcraft:fluid_plasma@0"
            ]
        },
        {
            "x": 0,
            "y": 3,
            "z": -1,
            "elements": [
                "thermalfoundation:storage_alloy@7"
            ]
        },
        {
            "x": -1,
            "y": 3,
            "z": -1,
            "elements": [
                "mekanism:plasticfence@15"
            ]
        },
        {
            "x": -2,
            "y": 3,
            "z": -1,
            "elements": [
                "ebwizardry:crystal_block@7"
            ]
        },
        {
            "x": -3,
            "y": 3,
            "z": -1,
            "elements": [
                "tconevo:metal_block@7"
            ]
        },
        {
            "x": -4,
            "y": 3,
            "z": -1,
            "elements": [
                "tconevo:metal_block@7"
            ]
        },
        {
            "x": -5,
            "y": 3,
            "z": -1,
            "elements": [
                "ebwizardry:crystal_block@3"
            ]
        },
        {
            "x": -6,
            "y": 3,
            "z": -1,
            "elements": [
                "mekanism:plasticfence@15"
            ]
        },
        {
            "x": -7,
            "y": 3,
            "z": -1,
            "elements": [
                "thermalfoundation:storage_alloy@7"
            ]
        },
        {
            "x": -8,
            "y": 3,
            "z": -1,
            "elements": [
                "nuclearcraft:fluid_plasma@0"
            ]
        },
        {
            "x": -9,
            "y": 3,
            "z": -1,
            "elements": [
                "mekanismgenerators:generator@9"
            ]
        },
        {
            "x": -10,
            "y": 3,
            "z": -1,
            "elements": [
                "matteroverdrive:fusion_reactor_coil@0"
            ]
        },
        {
            "x": -11,
            "y": -2,
            "z": 1,
            "elements": [
                "matteroverdrive:decorative.tritanium_plate_stripe@0"
            ]
        },
        {
            "x": -10,
            "y": -2,
            "z": 1,
            "elements": [
                "matteroverdrive:decorative.clean@0"
            ]
        },
        {
            "x": -9,
            "y": -2,
            "z": 1,
            "elements": [
                "chisel:technical@9"
            ]
        },
        {
            "x": -8,
            "y": -2,
            "z": 1,
            "elements": [
                "chisel:technical@9"
            ]
        },
        {
            "x": -6,
            "y": 2,
            "z": 3,
            "elements": [
                "matteroverdrive:decorative.separator@0"
            ]
        },
        {
            "x": -7,
            "y": -2,
            "z": 1,
            "elements": [
                "chisel:technical@9"
            ]
        },
        {
            "x": -5,
            "y": 2,
            "z": 3,
            "elements": [
                "appliedenergistics2:fluix_slab@8"
            ]
        },
        {
            "x": 4,
            "y": -2,
            "z": -3,
            "elements": [
                "matteroverdrive:decorative.tritanium_plate_stripe@0"
            ]
        },
        {
            "x": 3,
            "y": -2,
            "z": -3,
            "elements": [
                "matteroverdrive:decorative.clean@0"
            ]
        },
        {
            "x": -6,
            "y": -2,
            "z": 1,
            "elements": [
                "chisel:technical@9"
            ]
        },
        {
            "x": -4,
            "y": 2,
            "z": 3,
            "elements": [
                "appliedenergistics2:fluix_slab@8"
            ]
        },
        {
            "x": -5,
            "y": -2,
            "z": 1,
            "elements": [
                "matteroverdrive:decorative.floor_tiles@8"
            ]
        },
        {
            "x": -3,
            "y": 2,
            "z": 3,
            "elements": [
                "appliedenergistics2:fluix_slab@8"
            ]
        },
        {
            "x": 2,
            "y": -2,
            "z": -3,
            "elements": [
                "matteroverdrive:decorative.clean@0"
            ]
        },
        {
            "x": 3,
            "y": 2,
            "z": -1,
            "elements": [
                "matteroverdrive:decorative.separator@0"
            ]
        },
        {
            "x": 1,
            "y": -2,
            "z": -3,
            "elements": [
                "matteroverdrive:decorative.clean@0"
            ]
        },
        {
            "x": -4,
            "y": -2,
            "z": 1,
            "elements": [
                "matteroverdrive:decorative.clean@0"
            ]
        },
        {
            "x": -2,
            "y": 2,
            "z": 3,
            "elements": [
                "appliedenergistics2:fluix_slab@8"
            ]
        },
        {
            "x": 0,
            "y": -2,
            "z": -3,
            "elements": [
                "matteroverdrive:decorative.clean@0"
            ]
        },
        {
            "x": -3,
            "y": -2,
            "z": 1,
            "elements": [
                "matteroverdrive:decorative.clean@0"
            ]
        },
        {
            "x": -1,
            "y": 2,
            "z": 3,
            "elements": [
                "matteroverdrive:decorative.separator@0"
            ]
        },
        {
            "x": 2,
            "y": 2,
            "z": -1,
            "elements": [
                "appliedenergistics2:fluix_slab@8"
            ]
        },
        {
            "x": -1,
            "y": -2,
            "z": -3,
            "elements": [
                "matteroverdrive:decorative.clean@0"
            ]
        },
        {
            "x": 1,
            "y": 2,
            "z": -1,
            "elements": [
                "matteroverdrive:industrial_glass@0"
            ]
        },
        {
            "x": -2,
            "y": -2,
            "z": 1,
            "elements": [
                "matteroverdrive:decorative.floor_tiles@8"
            ]
        },
        {
            "x": 0,
            "y": 2,
            "z": -1,
            "elements": [
                "matteroverdrive:matter_plasma@0"
            ]
        },
        {
            "x": -1,
            "y": -2,
            "z": 1,
            "elements": [
                "chisel:technical@9"
            ]
        },
        {
            "x": -2,
            "y": -2,
            "z": -3,
            "elements": [
                "matteroverdrive:decorative.clean@0"
            ]
        },
        {
            "x": 0,
            "y": -2,
            "z": 1,
            "elements": [
                "chisel:technical@9"
            ]
        },
        {
            "x": -3,
            "y": -2,
            "z": -3,
            "elements": [
                "matteroverdrive:decorative.clean@0"
            ]
        },
        {
            "x": -1,
            "y": 2,
            "z": -1,
            "elements": [
                "rpsideas:dark_plate@10"
            ]
        },
        {
            "x": 1,
            "y": -2,
            "z": 1,
            "elements": [
                "chisel:technical@9"
            ]
        },
        {
            "x": -4,
            "y": -2,
            "z": -3,
            "elements": [
                "matteroverdrive:decorative.clean@0"
            ]
        },
        {
            "x": -2,
            "y": 2,
            "z": -1,
            "elements": [
                "appliedenergistics2:quartz_slab@8"
            ]
        },
        {
            "x": -5,
            "y": -2,
            "z": -3,
            "elements": [
                "matteroverdrive:decorative.clean@0"
            ]
        },
        {
            "x": -3,
            "y": 2,
            "z": -1,
            "elements": [
                "appliedenergistics2:quartz_slab@8"
            ]
        },
        {
            "x": 2,
            "y": -2,
            "z": 1,
            "elements": [
                "chisel:technical@9"
            ]
        },
        {
            "x": 3,
            "y": -2,
            "z": 1,
            "elements": [
                "matteroverdrive:decorative.clean@0"
            ]
        },
        {
            "x": -6,
            "y": -2,
            "z": -3,
            "elements": [
                "matteroverdrive:decorative.clean@0"
            ]
        },
        {
            "x": -4,
            "y": 2,
            "z": -1,
            "elements": [
                "appliedenergistics2:quartz_slab@8"
            ]
        },
        {
            "x": -7,
            "y": -2,
            "z": -3,
            "elements": [
                "matteroverdrive:decorative.clean@0"
            ]
        },
        {
            "x": -5,
            "y": 2,
            "z": -1,
            "elements": [
                "appliedenergistics2:quartz_slab@8"
            ]
        },
        {
            "x": 4,
            "y": -2,
            "z": 1,
            "elements": [
                "matteroverdrive:decorative.tritanium_plate_stripe@0"
            ]
        },
        {
            "x": -8,
            "y": -2,
            "z": -3,
            "elements": [
                "matteroverdrive:decorative.clean@0"
            ]
        },
        {
            "x": -6,
            "y": 2,
            "z": -1,
            "elements": [
                "rpsideas:dark_plate@10"
            ]
        },
        {
            "x": -9,
            "y": -2,
            "z": -3,
            "elements": [
                "matteroverdrive:decorative.clean@0"
            ]
        },
        {
            "x": -7,
            "y": 2,
            "z": -1,
            "elements": [
                "matteroverdrive:matter_plasma@0"
            ]
        },
        {
            "x": -10,
            "y": -2,
            "z": -3,
            "elements": [
                "matteroverdrive:decorative.clean@0"
            ]
        },
        {
            "x": -8,
            "y": 2,
            "z": -1,
            "elements": [
                "matteroverdrive:industrial_glass@0"
            ]
        },
        {
            "x": -11,
            "y": -2,
            "z": -3,
            "elements": [
                "matteroverdrive:decorative.tritanium_plate_stripe@0"
            ]
        },
        {
            "x": -9,
            "y": 2,
            "z": -1,
            "elements": [
                "appliedenergistics2:fluix_slab@8"
            ]
        },
        {
            "x": -10,
            "y": 2,
            "z": -1,
            "elements": [
                "matteroverdrive:decorative.separator@0"
            ]
        },
        {
            "x": -7,
            "y": 3,
            "z": 3,
            "elements": [
                "matteroverdrive:fusion_reactor_coil@0"
            ]
        },
        {
            "x": -6,
            "y": 3,
            "z": 3,
            "elements": [
                "matteroverdrive:fusion_reactor_coil@0"
            ]
        },
        {
            "x": -7,
            "y": -1,
            "z": 1,
            "elements": [
                "chisel:technicalnew@2"
            ]
        },
        {
            "x": -5,
            "y": 3,
            "z": 3,
            "elements": [
                "mekanismgenerators:generator@9"
            ]
        },
        {
            "x": -4,
            "y": 3,
            "z": 3,
            "elements": [
                "mekanismgenerators:generator@9"
            ]
        },
        {
            "x": -3,
            "y": 3,
            "z": 3,
            "elements": [
                "mekanismgenerators:generator@9"
            ]
        },
        {
            "x": 3,
            "y": 1,
            "z": -1,
            "elements": [
                "modularmachinery:blockcasing@5"
            ]
        },
        {
            "x": -2,
            "y": 3,
            "z": 3,
            "elements": [
                "mekanismgenerators:generator@9"
            ]
        },
        {
            "x": -1,
            "y": 3,
            "z": 3,
            "elements": [
                "matteroverdrive:fusion_reactor_coil@0"
            ]
        },
        {
            "x": 0,
            "y": 3,
            "z": 3,
            "elements": [
                "matteroverdrive:fusion_reactor_coil@0"
            ]
        },
        {
            "x": 0,
            "y": 1,
            "z": -1,
            "elements": [
                "rpsideas:dark_plate@11"
            ]
        },
        {
            "x": 0,
            "y": -1,
            "z": 1,
            "elements": [
                "chisel:technicalnew@2"
            ]
        },
        {
            "x": -1,
            "y": 1,
            "z": -1,
            "elements": [
                "appliedenergistics2:fluix_slab@8"
            ]
        },
        {
            "x": -6,
            "y": 1,
            "z": -1,
            "elements": [
                "appliedenergistics2:fluix_slab@8"
            ]
        },
        {
            "x": -7,
            "y": 1,
            "z": -1,
            "elements": [
                "rpsideas:dark_plate@11"
            ]
        },
        {
            "x": -10,
            "y": 1,
            "z": -1,
            "elements": [
                "modularmachinery:blockcasing@5"
            ]
        },
        {
            "x": -7,
            "y": 0,
            "z": 1,
            "elements": [
                "chisel:technicalnew@2"
            ]
        },
        {
            "x": -5,
            "y": 4,
            "z": 3,
            "elements": [
                "appliedenergistics2:fluix_slab@0"
            ]
        },
        {
            "x": -4,
            "y": 4,
            "z": 3,
            "elements": [
                "appliedenergistics2:fluix_slab@0"
            ]
        },
        {
            "x": -3,
            "y": 4,
            "z": 3,
            "elements": [
                "appliedenergistics2:fluix_slab@0"
            ]
        },
        {
            "x": 3,
            "y": 0,
            "z": -1,
            "elements": [
                "modularmachinery:blockcasing@5"
            ]
        },
        {
            "x": -2,
            "y": 4,
            "z": 3,
            "elements": [
                "appliedenergistics2:fluix_slab@0"
            ]
        },
        {
            "x": 0,
            "y": 0,
            "z": 1,
            "elements": [
                "chisel:technicalnew@2"
            ]
        },
        {
            "x": -10,
            "y": 0,
            "z": -1,
            "elements": [
                "modularmachinery:blockcasing@5"
            ]
        },
        {
            "x": -7,
            "y": 1,
            "z": 1,
            "elements": [
                "chisel:technicalnew@2"
            ]
        },
        {
            "x": -5,
            "y": 1,
            "z": 1,
            "elements": [
                "rpsideas:dark_plate@11"
            ]
        },
        {
            "x": 3,
            "y": -1,
            "z": -1,
            "elements": [
                "matteroverdrive:decorative.separator@0"
            ]
        },
        {
            "x": -4,
            "y": 1,
            "z": 1,
            "elements": [
                "rpsideas:dark_plate@11"
            ]
        },
        {
            "x": -3,
            "y": 1,
            "z": 1,
            "elements": [
                "rpsideas:dark_plate@11"
            ]
        },
        {
            "x": -2,
            "y": 1,
            "z": 1,
            "elements": [
                "rpsideas:dark_plate@11"
            ]
        },
        {
            "x": 0,
            "y": 1,
            "z": 1,
            "elements": [
                "chisel:technicalnew@2"
            ]
        },
        {
            "x": -10,
            "y": -1,
            "z": -1,
            "elements": [
                "matteroverdrive:decorative.separator@0"
            ]
        },
        {
            "x": -7,
            "y": 2,
            "z": 1,
            "elements": [
                "matteroverdrive:industrial_glass@0"
            ]
        },
        {
            "x": -6,
            "y": 2,
            "z": 1,
            "elements": [
                "matteroverdrive:industrial_glass@0"
            ]
        },
        {
            "x": -5,
            "y": 2,
            "z": 1,
            "elements": [
                "matteroverdrive:matter_plasma@0"
            ]
        },
        {
            "x": 4,
            "y": -2,
            "z": -1,
            "elements": [
                "matteroverdrive:decorative.tritanium_plate_stripe@0"
            ]
        },
        {
            "x": 3,
            "y": -2,
            "z": -1,
            "elements": [
                "matteroverdrive:decorative.clean@0"
            ]
        },
        {
            "x": -4,
            "y": 2,
            "z": 1,
            "elements": [
                "matteroverdrive:matter_plasma@0"
            ]
        },
        {
            "x": -3,
            "y": 2,
            "z": 1,
            "elements": [
                "matteroverdrive:matter_plasma@0"
            ]
        },
        {
            "x": 2,
            "y": -2,
            "z": -1,
            "elements": [
                "chisel:technical@9"
            ]
        },
        {
            "x": 1,
            "y": -2,
            "z": -1,
            "elements": [
                "chisel:technical@9"
            ]
        },
        {
            "x": -2,
            "y": 2,
            "z": 1,
            "elements": [
                "matteroverdrive:matter_plasma@0"
            ]
        },
        {
            "x": 0,
            "y": -2,
            "z": -1,
            "elements": [
                "chisel:technical@9"
            ]
        },
        {
            "x": -1,
            "y": 2,
            "z": 1,
            "elements": [
                "matteroverdrive:industrial_glass@0"
            ]
        },
        {
            "x": 0,
            "y": 2,
            "z": 1,
            "elements": [
                "matteroverdrive:industrial_glass@0"
            ]
        },
        {
            "x": -1,
            "y": -2,
            "z": -1,
            "elements": [
                "chisel:technical@9"
            ]
        },
        {
            "x": -2,
            "y": -2,
            "z": -1,
            "elements": [
                "matteroverdrive:decorative.floor_tiles@8"
            ]
        },
        {
            "x": -3,
            "y": -2,
            "z": -1,
            "elements": [
                "matteroverdrive:decorative.clean@0"
            ]
        },
        {
            "x": -4,
            "y": -2,
            "z": -1,
            "elements": [
                "matteroverdrive:decorative.clean@0"
            ]
        },
        {
            "x": -5,
            "y": -2,
            "z": -1,
            "elements": [
                "matteroverdrive:decorative.floor_tiles@8"
            ]
        },
        {
            "x": -6,
            "y": -2,
            "z": -1,
            "elements": [
                "chisel:technical@9"
            ]
        },
        {
            "x": -7,
            "y": -2,
            "z": -1,
            "elements": [
                "chisel:technical@9"
            ]
        },
        {
            "x": -8,
            "y": -2,
            "z": -1,
            "elements": [
                "chisel:technical@9"
            ]
        },
        {
            "x": -9,
            "y": -2,
            "z": -1,
            "elements": [
                "chisel:technical@9"
            ]
        },
        {
            "x": -10,
            "y": -2,
            "z": -1,
            "elements": [
                "matteroverdrive:decorative.clean@0"
            ]
        },
        {
            "x": -11,
            "y": -2,
            "z": -1,
            "elements": [
                "matteroverdrive:decorative.tritanium_plate_stripe@0"
            ]
        },
        {
            "x": -9,
            "y": 3,
            "z": 1,
            "elements": [
                "matteroverdrive:fusion_reactor_coil@0"
            ]
        },
        {
            "x": -8,
            "y": 3,
            "z": 1,
            "elements": [
                "modularmachinery:blockfluidinputhatch"
            ]
        },
        {
            "x": -7,
            "y": 3,
            "z": 1,
            "elements": [
                "nuclearcraft:fluid_plasma@0"
            ]
        },
        {
            "x": -6,
            "y": 3,
            "z": 1,
            "elements": [
                "nuclearcraft:fluid_plasma@0"
            ]
        },
        {
            "x": -5,
            "y": 3,
            "z": 1,
            "elements": [
                "thermalfoundation:storage_alloy@7"
            ]
        },
        {
            "x": -4,
            "y": 3,
            "z": 1,
            "elements": [
                "thermalfoundation:storage_alloy@7"
            ]
        },
        {
            "x": -3,
            "y": 3,
            "z": 1,
            "elements": [
                "thermalfoundation:storage_alloy@7"
            ]
        },
        {
            "x": -2,
            "y": 3,
            "z": 1,
            "elements": [
                "thermalfoundation:storage_alloy@7"
            ]
        },
        {
            "x": -1,
            "y": 3,
            "z": 1,
            "elements": [
                "nuclearcraft:fluid_plasma@0"
            ]
        },
        {
            "x": 0,
            "y": 3,
            "z": 1,
            "elements": [
                "nuclearcraft:fluid_plasma@0"
            ]
        },
        {
            "x": 1,
            "y": 3,
            "z": 1,
            "elements": [
                "modularmachinery:blockfluidinputhatch"
            ]
        },
        {
            "x": 2,
            "y": 3,
            "z": 1,
            "elements": [
                "matteroverdrive:fusion_reactor_coil@0"
            ]
        },
        {
            "x": -7,
            "y": 4,
            "z": 1,
            "elements": [
                "matteroverdrive:industrial_glass@0"
            ]
        },
        {
            "x": -6,
            "y": 4,
            "z": 1,
            "elements": [
                "matteroverdrive:industrial_glass@0"
            ]
        },
        {
            "x": -5,
            "y": 4,
            "z": 1,
            "elements": [
                "matteroverdrive:matter_plasma@0"
            ]
        },
        {
            "x": -4,
            "y": 4,
            "z": 1,
            "elements": [
                "matteroverdrive:matter_plasma@0"
            ]
        },
        {
            "x": -3,
            "y": 4,
            "z": 1,
            "elements": [
                "matteroverdrive:matter_plasma@0"
            ]
        },
        {
            "x": -2,
            "y": 4,
            "z": 1,
            "elements": [
                "matteroverdrive:matter_plasma@0"
            ]
        },
        {
            "x": -1,
            "y": 4,
            "z": 1,
            "elements": [
                "matteroverdrive:industrial_glass@0"
            ]
        },
        {
            "x": 0,
            "y": 4,
            "z": 1,
            "elements": [
                "matteroverdrive:industrial_glass@0"
            ]
        },
        {
            "x": -5,
            "y": 5,
            "z": 1,
            "elements": [
                "rpsideas:dark_plate@11"
            ]
        },
        {
            "x": -4,
            "y": 5,
            "z": 1,
            "elements": [
                "rpsideas:dark_plate@11"
            ]
        },
        {
            "x": -3,
            "y": 5,
            "z": 1,
            "elements": [
                "rpsideas:dark_plate@11"
            ]
        },
        {
            "x": -2,
            "y": 5,
            "z": 1,
            "elements": [
                "rpsideas:dark_plate@11"
            ]
        },
        {
            "x": -2,
            "y": 4,
            "z": -10,
            "elements": [
                "appliedenergistics2:fluix_slab@0"
            ]
        },
        {
            "x": -3,
            "y": 4,
            "z": -10,
            "elements": [
                "appliedenergistics2:fluix_slab@0"
            ]
        },
        {
            "x": -4,
            "y": 4,
            "z": -10,
            "elements": [
                "appliedenergistics2:fluix_slab@0"
            ]
        },
        {
            "x": -5,
            "y": 4,
            "z": -10,
            "elements": [
                "appliedenergistics2:fluix_slab@0"
            ]
        },
        {
            "x": 0,
            "y": 3,
            "z": -10,
            "elements": [
                "matteroverdrive:fusion_reactor_coil@0"
            ]
        },
        {
            "x": -1,
            "y": 3,
            "z": -10,
            "elements": [
                "matteroverdrive:fusion_reactor_coil@0"
            ]
        },
        {
            "x": -2,
            "y": 3,
            "z": -10,
            "elements": [
                "mekanismgenerators:generator@9"
            ]
        },
        {
            "x": -3,
            "y": 3,
            "z": -10,
            "elements": [
                "mekanismgenerators:generator@9"
            ]
        },
        {
            "x": -4,
            "y": 3,
            "z": -10,
            "elements": [
                "mekanismgenerators:generator@9"
            ]
        },
        {
            "x": -5,
            "y": 3,
            "z": -10,
            "elements": [
                "mekanismgenerators:generator@9"
            ]
        },
        {
            "x": -6,
            "y": 3,
            "z": -10,
            "elements": [
                "matteroverdrive:fusion_reactor_coil@0"
            ]
        },
        {
            "x": -7,
            "y": 3,
            "z": -10,
            "elements": [
                "matteroverdrive:fusion_reactor_coil@0"
            ]
        },
        {
            "x": -1,
            "y": 2,
            "z": -10,
            "elements": [
                "matteroverdrive:decorative.separator@0"
            ]
        },
        {
            "x": -2,
            "y": 2,
            "z": -10,
            "elements": [
                "appliedenergistics2:fluix_slab@8"
            ]
        },
        {
            "x": -3,
            "y": 2,
            "z": -10,
            "elements": [
                "appliedenergistics2:fluix_slab@8"
            ]
        },
        {
            "x": -4,
            "y": 2,
            "z": -10,
            "elements": [
                "appliedenergistics2:fluix_slab@8"
            ]
        },
        {
            "x": -5,
            "y": 2,
            "z": -10,
            "elements": [
                "appliedenergistics2:fluix_slab@8"
            ]
        },
        {
            "x": -6,
            "y": 2,
            "z": -10,
            "elements": [
                "matteroverdrive:decorative.separator@0"
            ]
        },
        {
            "x": -1,
            "y": 1,
            "z": -10,
            "elements": [
                "modularmachinery:blockcasing@5"
            ]
        },
        {
            "x": -2,
            "y": 5,
            "z": -8,
            "elements": [
                "rpsideas:dark_plate@11"
            ]
        },
        {
            "x": -3,
            "y": 5,
            "z": -8,
            "elements": [
                "rpsideas:dark_plate@11"
            ]
        },
        {
            "x": -6,
            "y": 1,
            "z": -10,
            "elements": [
                "modularmachinery:blockcasing@5"
            ]
        },
        {
            "x": -4,
            "y": 5,
            "z": -8,
            "elements": [
                "rpsideas:dark_plate@11"
            ]
        },
        {
            "x": -5,
            "y": 5,
            "z": -8,
            "elements": [
                "rpsideas:dark_plate@11"
            ]
        },
        {
            "x": -1,
            "y": 0,
            "z": -10,
            "elements": [
                "modularmachinery:blockcasing@5"
            ]
        },
        {
            "x": 0,
            "y": 4,
            "z": -8,
            "elements": [
                "matteroverdrive:industrial_glass@0"
            ]
        },
        {
            "x": -1,
            "y": 4,
            "z": -8,
            "elements": [
                "matteroverdrive:industrial_glass@0"
            ]
        },
        {
            "x": -2,
            "y": 4,
            "z": -8,
            "elements": [
                "matteroverdrive:matter_plasma@0"
            ]
        },
        {
            "x": -3,
            "y": 4,
            "z": -8,
            "elements": [
                "matteroverdrive:matter_plasma@0"
            ]
        },
        {
            "x": -6,
            "y": 0,
            "z": -10,
            "elements": [
                "modularmachinery:blockcasing@5"
            ]
        },
        {
            "x": -4,
            "y": 4,
            "z": -8,
            "elements": [
                "matteroverdrive:matter_plasma@0"
            ]
        },
        {
            "x": -5,
            "y": 4,
            "z": -8,
            "elements": [
                "matteroverdrive:matter_plasma@0"
            ]
        },
        {
            "x": -6,
            "y": 4,
            "z": -8,
            "elements": [
                "matteroverdrive:industrial_glass@0"
            ]
        },
        {
            "x": -7,
            "y": 4,
            "z": -8,
            "elements": [
                "matteroverdrive:industrial_glass@0"
            ]
        },
        {
            "x": 2,
            "y": 3,
            "z": -8,
            "elements": [
                "matteroverdrive:fusion_reactor_coil@0"
            ]
        },
        {
            "x": -1,
            "y": -1,
            "z": -10,
            "elements": [
                "matteroverdrive:decorative.separator@0"
            ]
        },
        {
            "x": 1,
            "y": 3,
            "z": -8,
            "elements": [
                "modularmachinery:blockfluidinputhatch"
            ]
        },
        {
            "x": 0,
            "y": 3,
            "z": -8,
            "elements": [
                "nuclearcraft:fluid_plasma@0"
            ]
        },
        {
            "x": -1,
            "y": 3,
            "z": -8,
            "elements": [
                "nuclearcraft:fluid_plasma@0"
            ]
        },
        {
            "x": -2,
            "y": 3,
            "z": -8,
            "elements": [
                "thermalfoundation:storage_alloy@7"
            ]
        },
        {
            "x": -3,
            "y": 3,
            "z": -8,
            "elements": [
                "thermalfoundation:storage_alloy@7"
            ]
        },
        {
            "x": -6,
            "y": -1,
            "z": -10,
            "elements": [
                "matteroverdrive:decorative.separator@0"
            ]
        },
        {
            "x": -4,
            "y": 3,
            "z": -8,
            "elements": [
                "thermalfoundation:storage_alloy@7"
            ]
        },
        {
            "x": -5,
            "y": 3,
            "z": -8,
            "elements": [
                "thermalfoundation:storage_alloy@7"
            ]
        },
        {
            "x": -6,
            "y": 3,
            "z": -8,
            "elements": [
                "nuclearcraft:fluid_plasma@0"
            ]
        },
        {
            "x": -7,
            "y": 3,
            "z": -8,
            "elements": [
                "nuclearcraft:fluid_plasma@0"
            ]
        },
        {
            "x": -8,
            "y": 3,
            "z": -8,
            "elements": [
                "modularmachinery:blockfluidinputhatch"
            ]
        },
        {
            "x": -9,
            "y": 3,
            "z": -8,
            "elements": [
                "matteroverdrive:fusion_reactor_coil@0"
            ]
        },
        {
            "x": 3,
            "y": -2,
            "z": -10,
            "elements": [
                "matteroverdrive:decorative.tritanium_plate_stripe@0"
            ]
        },
        {
            "x": 2,
            "y": -2,
            "z": -10,
            "elements": [
                "matteroverdrive:decorative.tritanium_plate_stripe@0"
            ]
        },
        {
            "x": 1,
            "y": -2,
            "z": -10,
            "elements": [
                "matteroverdrive:decorative.clean@0"
            ]
        },
        {
            "x": 0,
            "y": -2,
            "z": -10,
            "elements": [
                "matteroverdrive:decorative.clean@0"
            ]
        },
        {
            "x": -1,
            "y": -2,
            "z": -10,
            "elements": [
                "matteroverdrive:decorative.clean@0"
            ]
        },
        {
            "x": 0,
            "y": 2,
            "z": -8,
            "elements": [
                "matteroverdrive:industrial_glass@0"
            ]
        },
        {
            "x": -2,
            "y": -2,
            "z": -10,
            "elements": [
                "matteroverdrive:decorative.floor_tiles@8"
            ]
        },
        {
            "x": -3,
            "y": -2,
            "z": -10,
            "elements": [
                "matteroverdrive:decorative.clean@0"
            ]
        },
        {
            "x": -1,
            "y": 2,
            "z": -8,
            "elements": [
                "matteroverdrive:industrial_glass@0"
            ]
        },
        {
            "x": -4,
            "y": -2,
            "z": -10,
            "elements": [
                "matteroverdrive:decorative.clean@0"
            ]
        },
        {
            "x": -2,
            "y": 2,
            "z": -8,
            "elements": [
                "matteroverdrive:matter_plasma@0"
            ]
        },
        {
            "x": -5,
            "y": -2,
            "z": -10,
            "elements": [
                "matteroverdrive:decorative.floor_tiles@8"
            ]
        },
        {
            "x": -3,
            "y": 2,
            "z": -8,
            "elements": [
                "matteroverdrive:matter_plasma@0"
            ]
        },
        {
            "x": -4,
            "y": 2,
            "z": -8,
            "elements": [
                "matteroverdrive:matter_plasma@0"
            ]
        },
        {
            "x": -7,
            "y": -2,
            "z": -10,
            "elements": [
                "matteroverdrive:decorative.clean@0"
            ]
        },
        {
            "x": -5,
            "y": 2,
            "z": -8,
            "elements": [
                "matteroverdrive:matter_plasma@0"
            ]
        },
        {
            "x": -8,
            "y": -2,
            "z": -10,
            "elements": [
                "matteroverdrive:decorative.clean@0"
            ]
        },
        {
            "x": -6,
            "y": 2,
            "z": -8,
            "elements": [
                "matteroverdrive:industrial_glass@0"
            ]
        },
        {
            "x": -9,
            "y": -2,
            "z": -10,
            "elements": [
                "matteroverdrive:decorative.tritanium_plate_stripe@0"
            ]
        },
        {
            "x": -7,
            "y": 2,
            "z": -8,
            "elements": [
                "matteroverdrive:industrial_glass@0"
            ]
        },
        {
            "x": -10,
            "y": -2,
            "z": -10,
            "elements": [
                "matteroverdrive:decorative.tritanium_plate_stripe@0"
            ]
        },
        {
            "x": 0,
            "y": 1,
            "z": -8,
            "elements": [
                "chisel:technicalnew@2"
            ]
        },
        {
            "x": 0,
            "y": 5,
            "z": -6,
            "elements": [
                "rpsideas:dark_plate@11"
            ]
        },
        {
            "x": -2,
            "y": 1,
            "z": -8,
            "elements": [
                "rpsideas:dark_plate@11"
            ]
        },
        {
            "x": -3,
            "y": 1,
            "z": -8,
            "elements": [
                "rpsideas:dark_plate@11"
            ]
        },
        {
            "x": -1,
            "y": 5,
            "z": -6,
            "elements": [
                "appliedenergistics2:fluix_slab@0"
            ]
        },
        {
            "x": -4,
            "y": 1,
            "z": -8,
            "elements": [
                "rpsideas:dark_plate@11"
            ]
        },
        {
            "x": -5,
            "y": 1,
            "z": -8,
            "elements": [
                "rpsideas:dark_plate@11"
            ]
        },
        {
            "x": -7,
            "y": 1,
            "z": -8,
            "elements": [
                "chisel:technicalnew@2"
            ]
        },
        {
            "x": -6,
            "y": 5,
            "z": -6,
            "elements": [
                "appliedenergistics2:fluix_slab@0"
            ]
        },
        {
            "x": -7,
            "y": 5,
            "z": -6,
            "elements": [
                "rpsideas:dark_plate@11"
            ]
        },
        {
            "x": 2,
            "y": 4,
            "z": -6,
            "elements": [
                "appliedenergistics2:fluix_slab@0"
            ]
        },
        {
            "x": 0,
            "y": 0,
            "z": -8,
            "elements": [
                "chisel:technicalnew@2"
            ]
        },
        {
            "x": 1,
            "y": 4,
            "z": -6,
            "elements": [
                "matteroverdrive:industrial_glass@0"
            ]
        },
        {
            "x": 0,
            "y": 4,
            "z": -6,
            "elements": [
                "matteroverdrive:matter_plasma@0"
            ]
        },
        {
            "x": -1,
            "y": 4,
            "z": -6,
            "elements": [
                "rpsideas:dark_plate@10"
            ]
        },
        {
            "x": -2,
            "y": 4,
            "z": -6,
            "elements": [
                "appliedenergistics2:quartz_slab@0"
            ]
        },
        {
            "x": -3,
            "y": 4,
            "z": -6,
            "elements": [
                "appliedenergistics2:quartz_slab@0"
            ]
        },
        {
            "x": -4,
            "y": 4,
            "z": -6,
            "elements": [
