{
    "registryname": "Light-speed_material_accelerator",
    "localizedname": "§b超§a光§c速§d物§6质§e加速器",
    "failure-action": "still",
    "requires-blueprint": false,
    "parts": [
        {
            "x": -13,
            "y": -6,
            "z": 13,
            "elements": [
                "ic2:resource@6"
            ]
        },
        {
            "x": -12,
            "y": -6,
            "z": 13,
            "elements": [
                "thermalfoundation:storage@7"
            ]
        },
        {
            "x": 20,
            "y": -1,
            "z": 0,
            "elements": [
                "tconstruct:metal@0"
            ]
        },
        {
            "x": -9,
            "y": -6,
            "z": 13,
            "elements": [
                "thermalfoundation:storage@7"
            ]
        },
        {
            "x": -8,
            "y": -6,
            "z": 13,
            "elements": [
                "thermalfoundation:storage@7"
            ]
        },
        {
            "x": 2,
            "y": -2,
            "z": -17,
            "elements": [
                "thermalfoundation:storage@7"
            ]
        },
        {
            "x": -13,
            "y": 0,
            "z": 0,
            "elements": [
                "tconstruct:metal@0"
            ]
        },
        {
            "x": -7,
            "y": -6,
            "z": 13,
            "elements": [
                "thermalfoundation:storage@7"
            ]
        },
        {
            "x": 1,
            "y": -2,
            "z": -17,
            "elements": [
                "thermalfoundation:storage@7"
            ]
        },
        {
            "x": 13,
            "y": 0,
            "z": 0,
            "elements": [
                "tconstruct:metal@0"
            ]
        },
        {
            "x": -18,
            "y": 1,
            "z": 0,
            "elements": [
                "tconstruct:metal@0"
            ]
        },
        {
            "x": 0,
            "y": -2,
            "z": -17,
            "elements": [
                "psi:psi_decorative@2"
            ]
        },
        {
            "x": 16,
            "y": -1,
            "z": 0,
            "elements": [
                "tconstruct:metal@0"
            ]
        },
        {
            "x": -17,
            "y": 1,
            "z": 0,
            "elements": [
                "tconstruct:metal@0"
            ]
        },
        {
            "x": -1,
            "y": -2,
            "z": -17,
            "elements": [
                "thermalfoundation:storage@7"
            ]
        },
        {
            "x": -16,
            "y": 0,
            "z": 0,
            "elements": [
                "tconstruct:metal@0"
            ]
        },
        {
            "x": -16,
            "y": 1,
            "z": 0,
            "elements": [
                "tconstruct:metal@0"
            ]
        },
        {
            "x": -2,
            "y": -2,
            "z": -17,
            "elements": [
                "thermalfoundation:storage@7"
            ]
        },
        {
            "x": 16,
            "y": 0,
            "z": 0,
            "elements": [
                "tconstruct:metal@0"
            ]
        },
        {
            "x": -15,
            "y": 1,
            "z": 0,
            "elements": [
                "tconstruct:metal@0"
            ]
        },
        {
            "x": -14,
            "y": 1,
            "z": 0,
            "elements": [
                "tconstruct:metal@0"
            ]
        },
        {
            "x": 12,
            "y": -1,
            "z": 0,
            "elements": [
                "tconstruct:metal@0"
            ]
        },
        {
            "x": -19,
            "y": 0,
            "z": 0,
            "elements": [
                "tconstruct:metal@0"
            ]
        },
        {
            "x": 19,
            "y": 0,
            "z": 0,
            "elements": [
                "tconstruct:metal@0"
            ]
        },
        {
            "x": 7,
            "y": -6,
            "z": 13,
            "elements": [
                "thermalfoundation:storage@7"
            ]
        },
        {
            "x": 8,
            "y": -6,
            "z": 13,
            "elements": [
                "thermalfoundation:storage@7"
            ]
        },
        {
            "x": 9,
            "y": -6,
            "z": 13,
            "elements": [
                "thermalfoundation:storage@7"
            ]
        },
        {
            "x": 1,
            "y": -1,
            "z": 0,
            "elements": [
                "avaritia:block_resource@1"
            ]
        },
        {
            "x": 0,
            "y": -1,
            "z": 0,
            "elements": [
                "avaritia:block_resource@1"
            ]
        },
        {
            "x": -1,
            "y": -1,
            "z": 0,
            "elements": [
                "avaritia:block_resource@1"
            ]
        },
        {
            "x": 12,
            "y": -6,
            "z": 13,
            "elements": [
                "thermalfoundation:storage@7"
            ]
        },
        {
            "x": 13,
            "y": -6,
            "z": 13,
            "elements": [
                "ic2:resource@6"
            ]
        },
        {
            "x": -14,
            "y": -5,
            "z": 13,
            "elements": [
                "thermalfoundation:storage@7"
            ]
        },
        {
            "x": 6,
            "y": -3,
            "z": -17,
            "elements": [
                "thermalfoundation:storage@7"
            ]
        },
        {
            "x": 5,
            "y": -3,
            "z": -17,
            "elements": [
                "ic2:resource@6"
            ]
        },
        {
            "x": 21,
            "y": -2,
            "z": 0,
            "elements": [
                "tconstruct:metal@0"
            ]
        },
        {
            "x": 4,
            "y": -3,
            "z": -17,
            "elements": [
                "thermalfoundation:storage@7"
            ]
        },
        {
            "x": 3,
            "y": -3,
            "z": -17,
            "elements": [
                "thermalfoundation:storage@7"
            ]
        },
        {
            "x": -12,
            "y": -1,
            "z": 0,
            "elements": [
                "tconstruct:metal@0"
            ]
        },
        {
            "x": 17,
            "y": -2,
            "z": 0,
            "elements": [
                "psi:psi_decorative@2"
            ]
        },
        {
            "x": -6,
            "y": -5,
            "z": 13,
            "elements": [
                "thermalfoundation:storage@7"
            ]
        },
        {
            "x": 16,
            "y": -2,
            "z": 0,
            "elements": [
                "psi:psi_decorative@2"
            ]
        },
        {
            "x": 14,
            "y": 1,
            "z": 0,
            "elements": [
                "tconstruct:metal@0"
            ]
        },
        {
            "x": -5,
            "y": -5,
            "z": 13,
            "elements": [
                "ic2:resource@6"
            ]
        },
        {
            "x": 15,
            "y": -2,
            "z": 0,
            "elements": [
                "psi:psi_decorative@2"
            ]
        },
        {
            "x": -16,
            "y": -1,
            "z": 0,
            "elements": [
                "tconstruct:metal@0"
            ]
        },
        {
            "x": 15,
            "y": 1,
            "z": 0,
            "elements": [
                "tconstruct:metal@0"
            ]
        },
        {
            "x": -4,
            "y": -5,
            "z": 13,
            "elements": [
                "thermalfoundation:storage@7"
            ]
        },
        {
            "x": 16,
            "y": 1,
            "z": 0,
            "elements": [
                "tconstruct:metal@0"
            ]
        },
        {
            "x": -3,
            "y": -5,
            "z": 13,
            "elements": [
                "thermalfoundation:storage@7"
            ]
        },
        {
            "x": -3,
            "y": -3,
            "z": -17,
            "elements": [
                "thermalfoundation:storage@7"
            ]
        },
        {
            "x": 17,
            "y": 1,
            "z": 0,
            "elements": [
                "tconstruct:metal@0"
            ]
        },
        {
            "x": -4,
            "y": -3,
            "z": -17,
            "elements": [
                "thermalfoundation:storage@7"
            ]
        },
        {
            "x": 18,
            "y": 1,
            "z": 0,
            "elements": [
                "tconstruct:metal@0"
            ]
        },
        {
            "x": -5,
            "y": -3,
            "z": -17,
            "elements": [
                "ic2:resource@6"
            ]
        },
        {
            "x": 11,
            "y": -2,
            "z": 0,
            "elements": [
                "tconstruct:metal@0"
            ]
        },
        {
            "x": -20,
            "y": -1,
            "z": 0,
            "elements": [
                "tconstruct:metal@0"
            ]
        },
        {
            "x": -6,
            "y": -3,
            "z": -17,
            "elements": [
                "thermalfoundation:storage@7"
            ]
        },
        {
            "x": 3,
            "y": -5,
            "z": 13,
            "elements": [
                "thermalfoundation:storage@7"
            ]
        },
        {
            "x": 4,
            "y": -5,
            "z": 13,
            "elements": [
                "thermalfoundation:storage@7"
            ]
        },
        {
            "x": 5,
            "y": -5,
            "z": 13,
            "elements": [
                "ic2:resource@6"
            ]
        },
        {
            "x": 6,
            "y": -5,
            "z": 13,
            "elements": [
                "thermalfoundation:storage@7"
            ]
        },
        {
            "x": 1,
            "y": -2,
            "z": 0,
            "elements": [
                "modularmachinery:blockfluidoutputhatch"
            ]
        },
        {
            "x": 0,
            "y": -2,
            "z": 0,
            "elements": [
                "avaritia:block_resource@1"
            ]
        },
        {
            "x": -1,
            "y": -2,
            "z": 0,
            "elements": [
                "modularmachinery:blockfluidoutputhatch"
            ]
        },
        {
            "x": 14,
            "y": -5,
            "z": 13,
            "elements": [
                "thermalfoundation:storage@7"
            ]
        },
        {
            "x": 10,
            "y": -4,
            "z": -17,
            "elements": [
                "enderio:block_alloy_endergy@1"
            ]
        },
        {
            "x": -15,
            "y": -4,
            "z": 13,
            "elements": [
                "enderio:block_alloy_endergy@2"
            ]
        },
        {
            "x": 9,
            "y": -4,
            "z": -17,
            "elements": [
                "enderio:block_alloy_endergy@1"
            ]
        },
        {
            "x": 8,
            "y": -4,
            "z": -17,
            "elements": [
                "enderio:block_alloy_endergy@1"
            ]
        },
        {
            "x": 7,
            "y": -4,
            "z": -17,
            "elements": [
                "enderio:block_alloy_endergy@1"
            ]
        },
        {
            "x": -11,
            "y": -4,
            "z": 13,
            "elements": [
                "enderio:block_alloy_endergy@3"
            ]
        },
        {
            "x": 21,
            "y": -3,
            "z": 0,
            "elements": [
                "tconstruct:metal@0"
            ]
        },
        {
            "x": -10,
            "y": -4,
            "z": 13,
            "elements": [
                "enderio:block_alloy_endergy@3"
            ]
        },
        {
            "x": -11,
            "y": -2,
            "z": 0,
            "elements": [
                "tconstruct:metal@0"
            ]
        },
        {
            "x": 18,
            "y": -3,
            "z": 0,
            "elements": [
                "draconicevolution:draconic_block@0"
            ]
        },
        {
            "x": -15,
            "y": -2,
            "z": 0,
            "elements": [
                "psi:psi_decorative@2"
            ]
        },
        {
            "x": -16,
            "y": -2,
            "z": 0,
            "elements": [
                "psi:psi_decorative@2"
            ]
        },
        {
            "x": 14,
            "y": -3,
            "z": 0,
            "elements": [
                "avaritia:block_resource@0"
            ]
        },
        {
            "x": -17,
            "y": -2,
            "z": 0,
            "elements": [
                "psi:psi_decorative@2"
            ]
        },
        {
            "x": -2,
            "y": -4,
            "z": 13,
            "elements": [
                "tconstruct:metal@0"
            ]
        },
        {
            "x": -1,
            "y": -4,
            "z": 13,
            "elements": [
                "enderio:block_alloy_endergy@2"
            ]
        },
        {
            "x": 11,
            "y": -3,
            "z": 0,
            "elements": [
                "tconstruct:metal@0"
            ]
        },
        {
            "x": 0,
            "y": -4,
            "z": 13,
            "elements": [
                "tconstruct:metal@0"
            ]
        },
        {
            "x": 10,
            "y": -3,
            "z": 0,
            "elements": [
                "thermalfoundation:glass_alloy@6"
            ]
        },
        {
            "x": -21,
            "y": -2,
            "z": 0,
            "elements": [
                "tconstruct:metal@0"
            ]
        },
        {
            "x": 1,
            "y": -4,
            "z": 13,
            "elements": [
                "enderio:block_alloy_endergy@6"
            ]
        },
        {
            "x": -7,
            "y": -4,
            "z": -17,
            "elements": [
                "enderio:block_alloy@2"
            ]
        },
        {
            "x": 9,
            "y": -3,
            "z": 0,
            "elements": [
                "thermalfoundation:glass_alloy@6"
            ]
        },
        {
            "x": 2,
            "y": -4,
            "z": 13,
            "elements": [
                "tconstruct:metal@0"
            ]
        },
        {
            "x": -8,
            "y": -4,
            "z": -17,
            "elements": [
                "enderio:block_alloy@2"
            ]
        },
        {
            "x": 8,
            "y": -3,
            "z": 0,
            "elements": [
                "thermalfoundation:glass_alloy@6"
            ]
        },
        {
            "x": -9,
            "y": -4,
            "z": -17,
            "elements": [
                "enderio:block_alloy@2"
            ]
        },
        {
            "x": 7,
            "y": -3,
            "z": 0,
            "elements": [
                "thermalfoundation:glass_alloy@6"
            ]
        },
        {
            "x": -10,
            "y": -4,
            "z": -17,
            "elements": [
                "enderio:block_alloy@2"
            ]
        },
        {
            "x": 6,
            "y": -3,
            "z": 0,
            "elements": [
                "thermalfoundation:glass_alloy@6"
            ]
        },
        {
            "x": 5,
            "y": -3,
            "z": 0,
            "elements": [
                "thermalfoundation:glass_alloy@6"
            ]
        },
        {
            "x": 4,
            "y": -3,
            "z": 0,
            "elements": [
                "thermalfoundation:glass_alloy@6"
            ]
        },
        {
            "x": 3,
            "y": -3,
            "z": 0,
            "elements": [
                "thermalfoundation:glass_alloy@6"
            ]
        },
        {
            "x": 2,
            "y": -3,
            "z": 0,
            "elements": [
                "thermalfoundation:glass_alloy@6"
            ]
        },
        {
            "x": 1,
            "y": -3,
            "z": 0,
            "elements": [
                "avaritia:block_resource@1"
            ]
        },
        {
            "x": 10,
            "y": -4,
            "z": 13,
            "elements": [
                "enderio:block_alloy_endergy@3"
            ]
        },
        {
            "x": 0,
            "y": -3,
            "z": 0,
            "elements": [
                "avaritia:block_resource@1"
            ]
        },
        {
            "x": 11,
            "y": -4,
            "z": 13,
            "elements": [
                "enderio:block_alloy_endergy@3"
            ]
        },
        {
            "x": -1,
            "y": -3,
            "z": 0,
            "elements": [
                "avaritia:block_resource@1"
            ]
        },
        {
            "x": -2,
            "y": -3,
            "z": 0,
            "elements": [
                "thermalfoundation:glass_alloy@6"
            ]
        },
        {
            "x": -3,
            "y": -3,
            "z": 0,
            "elements": [
                "thermalfoundation:glass_alloy@6"
            ]
        },
        {
            "x": -4,
            "y": -3,
            "z": 0,
            "elements": [
                "thermalfoundation:glass_alloy@6"
            ]
        },
        {
            "x": 15,
            "y": -4,
            "z": 13,
            "elements": [
                "enderio:block_alloy_endergy@6"
            ]
        },
        {
            "x": -5,
            "y": -3,
            "z": 0,
            "elements": [
                "thermalfoundation:glass_alloy@6"
            ]
        },
        {
            "x": -6,
            "y": -3,
            "z": 0,
            "elements": [
                "thermalfoundation:glass_alloy@6"
            ]
        },
        {
            "x": -14,
            "y": -3,
            "z": 13,
            "elements": [
                "thermalfoundation:storage@7"
            ]
        },
        {
            "x": -7,
            "y": -3,
            "z": 0,
            "elements": [
                "thermalfoundation:glass_alloy@6"
            ]
        },
        {
            "x": -13,
            "y": -3,
            "z": 13,
            "elements": [
                "thermalfoundation:storage@7"
            ]
        },
        {
            "x": -8,
            "y": -3,
            "z": 0,
            "elements": [
                "thermalfoundation:glass_alloy@6"
            ]
        },
        {
            "x": 6,
            "y": -5,
            "z": -17,
            "elements": [
                "thermalfoundation:storage@7"
            ]
        },
        {
            "x": -9,
            "y": -3,
            "z": 0,
            "elements": [
                "thermalfoundation:glass_alloy@6"
            ]
        },
        {
            "x": 5,
            "y": -5,
            "z": -17,
            "elements": [
                "ic2:resource@6"
            ]
        },
        {
            "x": 21,
            "y": -4,
            "z": 0,
            "elements": [
                "tconstruct:metal@0"
            ]
        },
        {
            "x": -10,
            "y": -3,
            "z": 0,
            "elements": [
                "thermalfoundation:glass_alloy@6"
            ]
        },
        {
            "x": 4,
            "y": -5,
            "z": -17,
            "elements": [
                "thermalfoundation:storage@7"
            ]
        },
        {
            "x": 20,
            "y": -4,
            "z": 0,
            "elements": [
                "tconstruct:metal@0"
            ]
        },
        {
            "x": -11,
            "y": -3,
            "z": 0,
            "elements": [
                "tconstruct:metal@0"
            ]
        },
        {
            "x": 3,
            "y": -5,
            "z": -17,
            "elements": [
                "thermalfoundation:storage@7"
            ]
        },
        {
            "x": 19,
            "y": -4,
            "z": 0,
            "elements": [
                "tconstruct:metal@0"
            ]
        },
        {
            "x": 18,
            "y": -4,
            "z": 0,
            "elements": [
                "draconicevolution:draconic_block@0"
            ]
        },
        {
            "x": -14,
            "y": -3,
            "z": 0,
            "elements": [
                "avaritia:block_resource@0"
            ]
        },
        {
            "x": -6,
            "y": -3,
            "z": 13,
            "elements": [
                "thermalfoundation:storage@7"
            ]
        },
        {
            "x": 16,
            "y": -4,
            "z": 0,
            "elements": [
                "thermalfoundation:storage_alloy@6"
            ]
        },
        {
            "x": -5,
            "y": -3,
            "z": 13,
            "elements": [
                "ic2:resource@6"
            ]
        },
        {
            "x": -4,
            "y": -3,
            "z": 13,
            "elements": [
                "thermalfoundation:storage@7"
            ]
        },
        {
            "x": 14,
            "y": -4,
            "z": 0,
            "elements": [
                "avaritia:block_resource@0"
            ]
        },
        {
            "x": -3,
            "y": -3,
            "z": 13,
            "elements": [
                "thermalfoundation:storage@7"
            ]
        },
        {
            "x": -3,
            "y": -5,
            "z": -17,
            "elements": [
                "thermalfoundation:storage@7"
            ]
        },
        {
            "x": 13,
            "y": -4,
            "z": 0,
            "elements": [
                "tconstruct:metal@0"
            ]
        },
        {
            "x": -18,
            "y": -3,
            "z": 0,
            "elements": [
                "draconicevolution:draconic_block@0"
            ]
        },
        {
            "x": -4,
            "y": -5,
            "z": -17,
            "elements": [
                "thermalfoundation:storage@7"
            ]
        },
        {
            "x": 12,
            "y": -4,
            "z": 0,
            "elements": [
                "tconstruct:metal@0"
            ]
        },
        {
            "x": -5,
            "y": -5,
            "z": -17,
            "elements": [
                "ic2:resource@6"
            ]
        },
        {
            "x": 11,
            "y": -4,
            "z": 0,
            "elements": [
                "avaritia:block_resource@1"
            ]
        },
        {
            "x": -6,
            "y": -5,
            "z": -17,
            "elements": [
                "thermalfoundation:storage@7"
            ]
        },
        {
            "x": 10,
            "y": -4,
            "z": 0,
            "elements": [
                "avaritia:block_resource@2"
            ]
        },
        {
            "x": -21,
            "y": -3,
            "z": 0,
            "elements": [
                "tconstruct:metal@0"
            ]
        },
        {
            "x": 9,
            "y": -4,
            "z": 0,
            "elements": [
                "avaritia:block_resource@2"
            ]
        },
        {
            "x": 8,
            "y": -4,
            "z": 0,
            "elements": [
                "avaritia:block_resource@2"
            ]
        },
        {
            "x": 3,
            "y": -3,
            "z": 13,
            "elements": [
                "thermalfoundation:storage@7"
            ]
        },
        {
            "x": 7,
            "y": -4,
            "z": 0,
            "elements": [
                "avaritia:block_resource@2"
            ]
        },
        {
            "x": 4,
            "y": -3,
            "z": 13,
            "elements": [
                "thermalfoundation:storage@7"
            ]
        },
        {
            "x": 6,
            "y": -4,
            "z": 0,
            "elements": [
                "avaritia:block_resource@2"
            ]
        },
        {
            "x": 5,
            "y": -3,
            "z": 13,
            "elements": [
                "ic2:resource@6"
            ]
        },
        {
            "x": 5,
            "y": -4,
            "z": 0,
            "elements": [
                "avaritia:block_resource@2"
            ]
        },
        {
            "x": 6,
            "y": -3,
            "z": 13,
            "elements": [
                "thermalfoundation:storage@7"
            ]
        },
        {
            "x": 4,
            "y": -4,
            "z": 0,
            "elements": [
                "avaritia:block_resource@2"
            ]
        },
        {
            "x": 3,
            "y": -4,
            "z": 0,
            "elements": [
                "avaritia:block_resource@2"
            ]
        },
        {
            "x": 2,
            "y": -4,
            "z": 0,
            "elements": [
                "avaritia:block_resource@2"
            ]
        },
        {
            "x": 1,
            "y": -4,
            "z": 0,
            "elements": [
                "avaritia:block_resource@1"
            ]
        },
        {
            "x": 0,
            "y": -4,
            "z": 0,
            "elements": [
                "avaritia:block_resource@1"
            ]
        },
        {
            "x": -1,
            "y": -4,
            "z": 0,
            "elements": [
                "avaritia:block_resource@1"
            ]
        },
        {
            "x": -2,
            "y": -4,
            "z": 0,
            "elements": [
                "psi:psi_decorative@2"
            ]
        },
        {
            "x": -3,
            "y": -4,
            "z": 0,
            "elements": [
                "psi:psi_decorative@2"
            ]
        },
        {
            "x": 14,
            "y": -3,
            "z": 13,
            "elements": [
                "thermalfoundation:storage@7"
            ]
        },
        {
            "x": -4,
            "y": -4,
            "z": 0,
            "elements": [
                "psi:psi_decorative@2"
            ]
        },
        {
            "x": -5,
            "y": -4,
            "z": 0,
            "elements": [
                "psi:psi_decorative@2"
            ]
        },
        {
            "x": -6,
            "y": -4,
            "z": 0,
            "elements": [
                "psi:psi_decorative@2"
            ]
        },
        {
            "x": -7,
            "y": -4,
            "z": 0,
            "elements": [
                "psi:psi_decorative@2"
            ]
        },
        {
            "x": -13,
            "y": -2,
            "z": 13,
            "elements": [
                "ic2:resource@6"
            ]
        },
        {
            "x": -8,
            "y": -4,
            "z": 0,
            "elements": [
                "psi:psi_decorative@2"
            ]
        },
        {
            "x": -12,
            "y": -2,
            "z": 13,
            "elements": [
                "thermalfoundation:storage@7"
            ]
        },
        {
            "x": -9,
            "y": -4,
            "z": 0,
            "elements": [
                "psi:psi_decorative@2"
            ]
        },
        {
            "x": 21,
            "y": -5,
            "z": 0,
            "elements": [
                "tconstruct:metal@0"
            ]
        },
        {
            "x": -10,
            "y": -4,
            "z": 0,
            "elements": [
                "psi:psi_decorative@2"
            ]
        },
        {
            "x": -11,
            "y": -4,
            "z": 0,
            "elements": [
                "avaritia:block_resource@1"
            ]
        },
        {
            "x": -9,
            "y": -2,
            "z": 13,
            "elements": [
                "thermalfoundation:storage@7"
            ]
        },
        {
            "x": -12,
            "y": -4,
            "z": 0,
            "elements": [
                "tconstruct:metal@0"
            ]
        },
        {
            "x": -8,
            "y": -2,
            "z": 13,
            "elements": [
                "thermalfoundation:storage@7"
            ]
        },
        {
            "x": 2,
            "y": -6,
            "z": -17,
            "elements": [
                "thermalfoundation:storage@7"
            ]
        },
        {
            "x": 18,
            "y": -5,
            "z": 0,
            "elements": [
                "draconicevolution:draconic_block@0"
            ]
        },
        {
            "x": -13,
            "y": -4,
            "z": 0,
            "elements": [
                "tconstruct:metal@0"
            ]
        },
        {
            "x": -7,
            "y": -2,
            "z": 13,
            "elements": [
                "thermalfoundation:storage@7"
            ]
        },
        {
            "x": 1,
            "y": -6,
            "z": -17,
            "elements": [
                "thermalfoundation:storage@7"
            ]
        },
        {
            "x": -14,
            "y": -4,
            "z": 0,
            "elements": [
                "avaritia:block_resource@0"
            ]
        },
        {
            "x": 0,
            "y": -6,
            "z": -17,
            "elements": [
                "avaritia:block_resource@2"
            ]
        },
        {
            "x": -1,
            "y": -6,
            "z": -17,
            "elements": [
                "thermalfoundation:storage@7"
            ]
        },
        {
            "x": -16,
            "y": -4,
            "z": 0,
            "elements": [
                "thermalfoundation:storage_alloy@6"
            ]
        },
        {
            "x": -2,
            "y": -6,
            "z": -17,
            "elements": [
                "thermalfoundation:storage@7"
            ]
        },
        {
            "x": 14,
            "y": -5,
            "z": 0,
            "elements": [
                "avaritia:block_resource@0"
            ]
        },
        {
            "x": -18,
            "y": -4,
            "z": 0,
            "elements": [
                "draconicevolution:draconic_block@0"
            ]
        },
        {
            "x": -19,
            "y": -4,
            "z": 0,
            "elements": [
                "tconstruct:metal@0"
            ]
        },
        {
            "x": 11,
            "y": -5,
            "z": 0,
            "elements": [
                "tconstruct:metal@0"
            ]
        },
        {
            "x": -20,
            "y": -4,
            "z": 0,
            "elements": [
                "tconstruct:metal@0"
            ]
        },
        {
            "x": 10,
            "y": -5,
            "z": 0,
            "elements": [
                "thermalfoundation:glass_alloy@6"
            ]
        },
        {
            "x": -21,
            "y": -4,
            "z": 0,
            "elements": [
                "tconstruct:metal@0"
            ]
        },
        {
            "x": 9,
            "y": -5,
            "z": 0,
            "elements": [
                "thermalfoundation:glass_alloy@6"
            ]
        },
        {
            "x": 8,
            "y": -5,
            "z": 0,
            "elements": [
                "thermalfoundation:glass_alloy@6"
            ]
        },
        {
            "x": 7,
            "y": -5,
            "z": 0,
            "elements": [
                "thermalfoundation:glass_alloy@6"
            ]
        },
        {
            "x": 6,
            "y": -5,
            "z": 0,
            "elements": [
                "thermalfoundation:glass_alloy@6"
            ]
        },
        {
            "x": 5,
            "y": -5,
            "z": 0,
            "elements": [
                "thermalfoundation:glass_alloy@6"
            ]
        },
        {
            "x": 4,
            "y": -5,
            "z": 0,
            "elements": [
                "thermalfoundation:glass_alloy@6"
            ]
        },
        {
            "x": 7,
            "y": -2,
            "z": 13,
            "elements": [
                "thermalfoundation:storage@7"
            ]
        },
        {
            "x": 3,
            "y": -5,
            "z": 0,
            "elements": [
                "thermalfoundation:glass_alloy@6"
            ]
        },
        {
            "x": 8,
            "y": -2,
            "z": 13,
            "elements": [
                "thermalfoundation:storage@7"
            ]
        },
        {
            "x": 2,
            "y": -5,
            "z": 0,
            "elements": [
                "thermalfoundation:glass_alloy@6"
            ]
        },
        {
            "x": 9,
            "y": -2,
            "z": 13,
            "elements": [
                "thermalfoundation:storage@7"
            ]
        },
        {
            "x": 1,
            "y": -5,
            "z": 0,
            "elements": [
                "avaritia:block_resource@1"
            ]
        },
        {
            "x": 0,
            "y": -5,
            "z": 0,
            "elements": [
                "avaritia:block_resource@1"
            ]
        },
        {
            "x": -1,
            "y": -5,
            "z": 0,
            "elements": [
                "avaritia:block_resource@1"
            ]
        },
        {
            "x": 12,
            "y": -2,
            "z": 13,
            "elements": [
                "thermalfoundation:storage@7"
            ]
        },
        {
            "x": -2,
            "y": -5,
            "z": 0,
            "elements": [
                "thermalfoundation:glass_alloy@6"
            ]
        },
        {
            "x": 13,
            "y": -2,
            "z": 13,
            "elements": [
                "ic2:resource@6"
            ]
        },
        {
            "x": -3,
            "y": -5,
            "z": 0,
            "elements": [
                "thermalfoundation:glass_alloy@6"
            ]
        },
        {
            "x": -4,
            "y": -5,
            "z": 0,
            "elements": [
                "thermalfoundation:glass_alloy@6"
            ]
        },
        {
            "x": -5,
            "y": -5,
            "z": 0,
            "elements": [
                "thermalfoundation:glass_alloy@6"
            ]
        },
        {
            "x": -6,
            "y": -5,
            "z": 0,
            "elements": [
                "thermalfoundation:glass_alloy@6"
            ]
        },
        {
            "x": -7,
            "y": -5,
            "z": 0,
            "elements": [
                "thermalfoundation:glass_alloy@6"
            ]
        },
        {
            "x": -8,
            "y": -5,
            "z": 0,
            "elements": [
                "thermalfoundation:glass_alloy@6"
            ]
        },
        {
            "x": -9,
            "y": -5,
            "z": 0,
            "elements": [
                "thermalfoundation:glass_alloy@6"
            ]
        },
        {
            "x": -11,
            "y": -1,
            "z": 13,
            "elements": [
                "appliedenergistics2:chiseled_quartz_block@0"
            ]
        },
        {
            "x": 21,
            "y": -6,
            "z": 0,
            "elements": [
                "tconstruct:metal@0"
            ]
        },
        {
            "x": -10,
            "y": -5,
            "z": 0,
            "elements": [
                "thermalfoundation:glass_alloy@6"
            ]
        },
        {
            "x": -10,
            "y": -1,
            "z": 13,
            "elements": [
                "appliedenergistics2:chiseled_quartz_block@0"
            ]
        },
        {
            "x": -11,
            "y": -5,
            "z": 0,
            "elements": [
                "tconstruct:metal@0"
            ]
        },
        {
            "x": 17,
            "y": -6,
            "z": 0,
            "elements": [
                "avaritia:block_resource@2"
            ]
        },
        {
            "x": -14,
            "y": -5,
            "z": 0,
            "elements": [
                "avaritia:block_resource@0"
            ]
        },
        {
            "x": 16,
            "y": -6,
            "z": 0,
            "elements": [
                "avaritia:block_resource@2"
            ]
        },
        {
            "x": 15,
            "y": -6,
            "z": 0,
            "elements": [
                "avaritia:block_resource@2"
            ]
        },
        {
            "x": -18,
            "y": -5,
            "z": 0,
            "elements": [
                "draconicevolution:draconic_block@0"
            ]
        },
        {
            "x": -2,
            "y": -1,
            "z": 13,
            "elements": [
                "tconstruct:metal@0"
            ]
        },
        {
            "x": 11,
            "y": -6,
            "z": 0,
            "elements": [
                "tconstruct:metal@0"
            ]
        },
        {
            "x": -21,
            "y": -5,
            "z": 0,
            "elements": [
                "tconstruct:metal@0"
            ]
        },
        {
            "x": 2,
            "y": -1,
            "z": 13,
            "elements": [
                "tconstruct:metal@0"
            ]
        },
        {
            "x": 1,
            "y": -6,
            "z": 0,
            "elements": [
                "modularmachinery:blockfluidinputhatch"
            ]
        },
        {
            "x": 10,
            "y": -1,
            "z": 13,
            "elements": [
                "appliedenergistics2:chiseled_quartz_block@0"
            ]
        },
        {
            "x": 0,
            "y": -6,
            "z": 0,
            "elements": [
                "avaritia:block_resource@1"
            ]
        },
        {
            "x": 11,
            "y": -1,
            "z": 13,
            "elements": [
                "appliedenergistics2:chiseled_quartz_block@0"
            ]
        },
        {
            "x": -1,
            "y": -6,
            "z": 0,
            "elements": [
                "modularmachinery:blockfluidinputhatch"
            ]
        },
        {
            "x": 20,
            "y": -7,
            "z": 0,
            "elements": [
                "tconstruct:metal@0"
            ]
        },
        {
            "x": -11,
            "y": -6,
            "z": 0,
            "elements": [
                "tconstruct:metal@0"
            ]
        },
        {
            "x": 2,
            "y": -8,
            "z": -17,
            "elements": [
                "tconstruct:metal@0"
            ]
        },
        {
            "x": 16,
            "y": -7,
            "z": 0,
            "elements": [
                "tconstruct:metal@0"
            ]
        },
        {
            "x": -15,
            "y": -6,
            "z": 0,
            "elements": [
                "avaritia:block_resource@2"
            ]
        },
        {
            "x": -16,
            "y": -6,
            "z": 0,
            "elements": [
                "avaritia:block_resource@2"
            ]
        },
        {
            "x": -2,
            "y": -8,
            "z": -17,
            "elements": [
                "tconstruct:metal@0"
            ]
        },
        {
            "x": -17,
            "y": -6,
            "z": 0,
            "elements": [
                "avaritia:block_resource@2"
            ]
        },
        {
            "x": 0,
            "y": 0,
            "z": -13,
            "elements": [
                "tconstruct:metal@0"
            ]
        },
        {
            "x": 12,
            "y": -7,
            "z": 0,
            "elements": [
                "tconstruct:metal@0"
            ]
        },
        {
            "x": 0,
            "y": 0,
            "z": 13,
            "elements": [
                "tconstruct:metal@0"
            ]
        },
        {
            "x": -21,
            "y": -6,
            "z": 0,
            "elements": [
                "tconstruct:metal@0"
            ]
        },
        {
            "x": 1,
            "y": -7,
            "z": 0,
            "elements": [
                "avaritia:block_resource@1"
            ]
        },
        {
            "x": 0,
            "y": -7,
            "z": 0,
            "elements": [
                "avaritia:block_resource@1"
            ]
        },
        {
            "x": -1,
            "y": -7,
            "z": 0,
            "elements": [
                "avaritia:block_resource@1"
            ]
        },
        {
            "x": 11,
            "y": -1,
            "z": -13,
            "elements": [
                "appliedenergistics2:chiseled_quartz_block@0"
            ]
        },
        {
            "x": 10,
            "y": -1,
            "z": -13,
            "elements": [
                "appliedenergistics2:chiseled_quartz_block@0"
            ]
        },
        {
            "x": -14,
            "y": -7,
            "z": 9,
            "elements": [
                "appliedenergistics2:chiseled_quartz_block@0"
            ]
        },
        {
            "x": 19,
            "y": -8,
            "z": 0,
            "elements": [
                "tconstruct:metal@0"
            ]
        },
        {
            "x": -12,
            "y": -7,
            "z": 0,
            "elements": [
                "tconstruct:metal@0"
            ]
        },
        {
            "x": 0,
            "y": -9,
            "z": -17,
            "elements": [
                "tconstruct:metal@0"
            ]
        },
        {
            "x": 16,
            "y": -8,
            "z": 0,
            "elements": [
                "tconstruct:metal@0"
            ]
        },
        {
            "x": -16,
            "y": -7,
            "z": 0,
            "elements": [
                "tconstruct:metal@0"
            ]
        },
        {
            "x": 2,
            "y": -1,
            "z": -13,
            "elements": [
                "tconstruct:metal@0"
            ]
        },
        {
            "x": 13,
            "y": -8,
            "z": 0,
            "elements": [
                "tconstruct:metal@0"
            ]
        },
        {
            "x": -20,
            "y": -7,
            "z": 0,
            "elements": [
                "tconstruct:metal@0"
            ]
        },
        {
            "x": -2,
            "y": -1,
            "z": -13,
            "elements": [
                "tconstruct:metal@0"
            ]
        },
        {
            "x": -10,
            "y": -1,
            "z": -13,
            "elements": [
                "appliedenergistics2:chiseled_quartz_block@0"
            ]
        },
        {
            "x": -11,
            "y": -1,
            "z": -13,
            "elements": [
                "appliedenergistics2:chiseled_quartz_block@0"
            ]
        },
        {
            "x": 0,
            "y": -8,
            "z": 0,
            "elements": [
                "avaritia:block_resource@1"
            ]
        },
        {
            "x": 13,
            "y": -2,
            "z": -13,
            "elements": [
                "ic2:resource@6"
            ]
        },
        {
            "x": 12,
            "y": -2,
            "z": -13,
            "elements": [
                "thermalfoundation:storage@7"
            ]
        },
        {
            "x": 14,
            "y": -7,
            "z": 9,
            "elements": [
                "appliedenergistics2:chiseled_quartz_block@0"
            ]
        },
        {
            "x": -15,
            "y": -6,
            "z": 9,
            "elements": [
                "thermalfoundation:storage@7"
            ]
        },
        {
            "x": 9,
            "y": -2,
            "z": -13,
            "elements": [
                "thermalfoundation:storage@7"
            ]
        },
        {
            "x": 8,
            "y": -2,
            "z": -13,
            "elements": [
                "thermalfoundation:storage@7"
            ]
        },
        {
            "x": -13,
            "y": -6,
            "z": 9,
            "elements": [
                "thermalfoundation:storage@7"
            ]
        },
        {
            "x": 7,
            "y": -2,
            "z": -13,
            "elements": [
                "thermalfoundation:storage@7"
            ]
        },
        {
            "x": 18,
            "y": -9,
            "z": 0,
            "elements": [
                "tconstruct:metal@0"
            ]
        },
        {
            "x": -13,
            "y": -8,
            "z": 0,
            "elements": [
                "tconstruct:metal@0"
            ]
        },
        {
            "x": 17,
            "y": -9,
            "z": 0,
            "elements": [
                "tconstruct:metal@0"
            ]
        },
        {
            "x": 16,
            "y": -9,
            "z": 0,
            "elements": [
                "tconstruct:metal@0"
            ]
        },
        {
            "x": 15,
            "y": -9,
            "z": 0,
            "elements": [
                "tconstruct:metal@0"
            ]
        },
        {
            "x": -16,
            "y": -8,
            "z": 0,
            "elements": [
                "tconstruct:metal@0"
            ]
        },
        {
            "x": 14,
            "y": -9,
            "z": 0,
            "elements": [
                "tconstruct:metal@0"
            ]
        },
        {
            "x": -19,
            "y": -8,
            "z": 0,
            "elements": [
                "tconstruct:metal@0"
            ]
        },
        {
            "x": -7,
            "y": -2,
            "z": -13,
            "elements": [
                "thermalfoundation:storage@7"
            ]
        },
        {
            "x": -8,
            "y": -2,
            "z": -13,
            "elements": [
                "thermalfoundation:storage@7"
            ]
        },
        {
            "x": -9,
            "y": -2,
            "z": -13,
            "elements": [
                "thermalfoundation:storage@7"
            ]
        },
        {
            "x": -12,
            "y": -2,
            "z": -13,
            "elements": [
                "thermalfoundation:storage@7"
            ]
        },
        {
            "x": -13,
            "y": -2,
            "z": -13,
            "elements": [
                "ic2:resource@6"
            ]
        },
        {
            "x": 14,
            "y": -3,
            "z": -13,
            "elements": [
                "thermalfoundation:storage@7"
            ]
        },
        {
            "x": 13,
            "y": -6,
            "z": 9,
            "elements": [
                "thermalfoundation:storage@7"
            ]
        },
        {
            "x": 15,
            "y": -6,
            "z": 9,
            "elements": [
                "thermalfoundation:storage@7"
            ]
        },
        {
            "x": -16,
            "y": -5,
            "z": 9,
            "elements": [
                "thermalfoundation:storage@7"
            ]
        },
        {
            "x": -12,
            "y": -5,
            "z": 9,
            "elements": [
                "thermalfoundation:storage@7"
            ]
        },
        {
            "x": 6,
            "y": -3,
            "z": -13,
            "elements": [
                "thermalfoundation:storage@7"
            ]
        },
        {
            "x": 5,
            "y": -3,
            "z": -13,
            "elements": [
                "ic2:resource@6"
            ]
        },
        {
            "x": -14,
            "y": -9,
            "z": 0,
            "elements": [
                "tconstruct:metal@0"
            ]
        },
        {
            "x": 4,
            "y": -3,
            "z": -13,
            "elements": [
                "thermalfoundation:storage@7"
            ]
        },
        {
            "x": -15,
            "y": -9,
            "z": 0,
            "elements": [
                "tconstruct:metal@0"
            ]
        },
        {
            "x": 3,
            "y": -3,
            "z": -13,
            "elements": [
                "thermalfoundation:storage@7"
            ]
        },
        {
            "x": -16,
            "y": -9,
            "z": 0,
            "elements": [
                "tconstruct:metal@0"
            ]
        },
        {
            "x": -17,
            "y": -9,
            "z": 0,
            "elements": [
                "tconstruct:metal@0"
            ]
        },
        {
            "x": -18,
            "y": -9,
            "z": 0,
            "elements": [
                "tconstruct:metal@0"
            ]
        },
        {
            "x": -3,
            "y": -3,
            "z": -13,
            "elements": [
                "thermalfoundation:storage@7"
            ]
        },
        {
            "x": -4,
            "y": -3,
            "z": -13,
            "elements": [
                "thermalfoundation:storage@7"
            ]
        },
        {
            "x": -5,
            "y": -3,
            "z": -13,
            "elements": [
                "ic2:resource@6"
            ]
        },
        {
            "x": 0,
            "y": -5,
            "z": 9,
            "elements": [
                "thermalfoundation:glass_alloy@6"
            ]
        },
        {
            "x": -6,
            "y": -3,
            "z": -13,
            "elements": [
                "thermalfoundation:storage@7"
            ]
        },
        {
            "x": -14,
            "y": -3,
            "z": -13,
            "elements": [
                "thermalfoundation:storage@7"
            ]
        },
        {
            "x": 15,
            "y": -4,
            "z": -13,
            "elements": [
                "enderio:block_alloy_endergy@1"
            ]
        },
        {
            "x": 12,
            "y": -5,
            "z": 9,
            "elements": [
                "thermalfoundation:storage@7"
            ]
        },
        {
            "x": -17,
            "y": -4,
            "z": 9,
            "elements": [
                "enderio:block_alloy_endergy@2"
            ]
        },
        {
            "x": 11,
            "y": -4,
            "z": -13,
            "elements": [
                "enderio:block_alloy_endergy@3"
            ]
        },
        {
            "x": 10,
            "y": -4,
            "z": -13,
            "elements": [
                "enderio:block_alloy_endergy@3"
            ]
        },
        {
            "x": 16,
            "y": -5,
            "z": 9,
            "elements": [
                "thermalfoundation:storage@7"
            ]
        },
        {
            "x": -14,
            "y": -4,
            "z": 9,
            "elements": [
                "enderio:block_alloy_endergy@3"
            ]
        },
        {
            "x": -11,
            "y": -4,
            "z": 9,
            "elements": [
                "enderio:block_alloy_endergy@2"
            ]
        },
        {
            "x": 2,
            "y": -4,
            "z": -13,
            "elements": [
                "enderio:block_alloy_endergy@1"
            ]
        },
        {
            "x": 1,
            "y": -4,
            "z": -13,
            "elements": [
                "enderio:block_alloy_endergy@1"
            ]
        },
        {
            "x": 0,
            "y": -4,
            "z": -13,
            "elements": [
                "tconstruct:metal@0"
            ]
        },
        {
            "x": -1,
            "y": -4,
            "z": -13,
            "elements": [
                "enderio:block_alloy@2"
            ]
        },
        {
            "x": -2,
            "y": -4,
            "z": -13,
            "elements": [
                "tconstruct:metal@0"
            ]
        },
        {
            "x": -1,
            "y": -4,
            "z": 9,
            "elements": [
                "thermalfoundation:glass_alloy@6"
            ]
        },
        {
            "x": 0,
            "y": -4,
            "z": 9,
            "elements": [
                "avaritia:block_resource@0"
            ]
        },
        {
            "x": 1,
            "y": -4,
            "z": 9,
            "elements": [
                "thermalfoundation:glass_alloy@6"
            ]
        },
        {
            "x": -10,
            "y": -4,
            "z": -13,
            "elements": [
                "enderio:block_alloy_endergy@3"
            ]
        },
        {
            "x": -11,
            "y": -4,
            "z": -13,
            "elements": [
                "enderio:block_alloy_endergy@3"
            ]
        },
        {
            "x": -15,
            "y": -4,
            "z": -13,
            "elements": [
                "enderio:block_alloy@2"
            ]
        },
        {
            "x": 11,
            "y": -4,
            "z": 9,
            "elements": [
                "enderio:block_alloy_endergy@6"
            ]
        },
        {
            "x": 14,
            "y": -5,
            "z": -13,
            "elements": [
                "thermalfoundation:storage@7"
            ]
        },
        {
            "x": 14,
            "y": -4,
            "z": 9,
            "elements": [
                "enderio:block_alloy_endergy@3"
            ]
        },
        {
            "x": -16,
            "y": -3,
            "z": 9,
            "elements": [
                "thermalfoundation:storage@7"
            ]
        },
        {
            "x": 17,
            "y": -4,
            "z": 9,
            "elements": [
                "enderio:block_alloy_endergy@6"
            ]
        },
        {
            "x": -12,
            "y": -3,
            "z": 9,
            "elements": [
                "thermalfoundation:storage@7"
            ]
        },
        {
            "x": 5,
            "y": -5,
            "z": -13,
            "elements": [
                "ic2:resource@6"
            ]
        },
        {
            "x": 4,
            "y": -5,
            "z": -13,
            "elements": [
                "thermalfoundation:storage@7"
            ]
        },
        {
            "x": 3,
            "y": -5,
            "z": -13,
            "elements": [
                "thermalfoundation:storage@7"
            ]
        },
        {
            "x": -3,
            "y": -5,
            "z": -13,
            "elements": [
                "thermalfoundation:storage@7"
            ]
        },
        {
            "x": -4,
            "y": -5,
            "z": -13,
            "elements": [
                "thermalfoundation:storage@7"
            ]
        },
        {
            "x": -5,
            "y": -5,
            "z": -13,
            "elements": [
                "ic2:resource@6"
            ]
        },
        {
            "x": 0,
            "y": -3,
            "z": 9,
            "elements": [
                "thermalfoundation:glass_alloy@6"
            ]
        },
        {
            "x": -6,
            "y": -5,
            "z": -13,
            "elements": [
                "thermalfoundation:storage@7"
            ]
        },
        {
            "x": -14,
            "y": -5,
            "z": -13,
            "elements": [
                "thermalfoundation:storage@7"
            ]
        },
        {
            "x": 12,
            "y": -3,
            "z": 9,
            "elements": [
                "thermalfoundation:storage@7"
            ]
        },
        {
            "x": 13,
            "y": -6,
            "z": -13,
            "elements": [
                "ic2:resource@6"
            ]
        },
        {
            "x": 12,
            "y": -6,
            "z": -13,
            "elements": [
                "thermalfoundation:storage@7"
            ]
        },
        {
            "x": 16,
            "y": -3,
            "z": 9,
            "elements": [
                "thermalfoundation:storage@7"
            ]
        },
        {
            "x": -15,
            "y": -2,
            "z": 9,
            "elements": [
                "thermalfoundation:storage@7"
            ]
        },
        {
            "x": 9,
            "y": -6,
            "z": -13,
            "elements": [
                "thermalfoundation:storage@7"
            ]
        },
        {
            "x": 8,
            "y": -6,
            "z": -13,
            "elements": [
                "thermalfoundation:storage@7"
            ]
        },
        {
            "x": -13,
            "y": -2,
            "z": 9,
            "elements": [
                "thermalfoundation:storage@7"
            ]
        },
        {
            "x": 7,
            "y": -6,
            "z": -13,
            "elements": [
                "thermalfoundation:storage@7"
            ]
        },
        {
            "x": 6,
            "y": -6,
            "z": -13,
            "elements": [
                "thermalfoundation:storage@7"
            ]
        },
        {
            "x": -7,
            "y": -6,
            "z": -13,
            "elements": [
                "thermalfoundation:storage@7"
            ]
        },
        {
            "x": -8,
            "y": -6,
            "z": -13,
            "elements": [
                "thermalfoundation:storage@7"
            ]
        },
        {
            "x": -9,
            "y": -6,
            "z": -13,
            "elements": [
                "thermalfoundation:storage@7"
            ]
        },
        {
            "x": -12,
            "y": -6,
            "z": -13,
            "elements": [
                "thermalfoundation:storage@7"
            ]
        },
        {
            "x": -13,
            "y": -6,
            "z": -13,
            "elements": [
                "ic2:resource@6"
            ]
        },
        {
            "x": 13,
            "y": -2,
            "z": 9,
            "elements": [
                "thermalfoundation:storage@7"
            ]
        },
        {
            "x": 11,
            "y": -7,
            "z": -13,
            "elements": [
                "appliedenergistics2:chiseled_quartz_block@0"
            ]
        },
        {
            "x": 15,
            "y": -2,
            "z": 9,
            "elements": [
                "thermalfoundation:storage@7"
            ]
        },
        {
            "x": 10,
            "y": -7,
            "z": -13,
            "elements": [
                "appliedenergistics2:chiseled_quartz_block@0"
            ]
        },
        {
            "x": -14,
            "y": -1,
            "z": 9,
            "elements": [
                "appliedenergistics2:chiseled_quartz_block@0"
            ]
        },
        {
            "x": 2,
            "y": -7,
            "z": -13,
            "elements": [
                "tconstruct:metal@0"
            ]
        },
        {
            "x": -2,
            "y": -7,
            "z": -13,
            "elements": [
                "tconstruct:metal@0"
            ]
        },
        {
            "x": -10,
            "y": -7,
            "z": -13,
            "elements": [
                "appliedenergistics2:chiseled_quartz_block@0"
            ]
        },
        {
            "x": -11,
            "y": -7,
            "z": -13,
            "elements": [
                "appliedenergistics2:chiseled_quartz_block@0"
            ]
        },
        {
            "x": 14,
            "y": -1,
            "z": 9,
            "elements": [
                "appliedenergistics2:chiseled_quartz_block@0"
            ]
        },
        {
            "x": 0,
            "y": -8,
            "z": -13,
            "elements": [
                "tconstruct:metal@0"
            ]
        },
        {
            "x": 14,
            "y": -1,
            "z": -9,
            "elements": [
                "appliedenergistics2:chiseled_quartz_block@0"
            ]
        },
        {
            "x": -15,
            "y": -7,
            "z": 5,
            "elements": [
                "ic2:resource@6"
            ]
        },
        {
            "x": -14,
            "y": -1,
            "z": -9,
            "elements": [
                "appliedenergistics2:chiseled_quartz_block@0"
            ]
        },
        {
            "x": 15,
            "y": -2,
            "z": -9,
            "elements": [
                "thermalfoundation:storage@7"
            ]
        },
        {
            "x": 13,
            "y": -2,
            "z": -9,
            "elements": [
                "thermalfoundation:storage@7"
            ]
        },
        {
            "x": 15,
            "y": -7,
            "z": 5,
            "elements": [
                "ic2:resource@6"
            ]
        },
        {
            "x": -16,
            "y": -6,
            "z": 5,
            "elements": [
                "ic2:resource@6"
            ]
        },
        {
            "x": -14,
            "y": -6,
            "z": 5,
            "elements": [
                "ic2:resource@6"
            ]
        },
        {
            "x": -13,
            "y": -2,
            "z": -9,
            "elements": [
                "thermalfoundation:storage@7"
            ]
        },
        {
            "x": 16,
            "y": -3,
            "z": -9,
            "elements": [
                "thermalfoundation:storage@7"
            ]
        },
        {
            "x": -15,
            "y": -2,
            "z": -9,
            "elements": [
                "thermalfoundation:storage@7"
            ]
        },
        {
            "x": 12,
            "y": -3,
            "z": -9,
            "elements": [
                "thermalfoundation:storage@7"
            ]
        },
        {
            "x": 14,
            "y": -6,
            "z": 5,
            "elements": [
                "ic2:resource@6"
            ]
        },
        {
            "x": -17,
            "y": -5,
            "z": 5,
            "elements": [
                "ic2:resource@6"
            ]
        },
        {
            "x": 16,
            "y": -6,
            "z": 5,
            "elements": [
                "ic2:resource@6"
            ]
        },
        {
            "x": -13,
            "y": -5,
            "z": 5,
            "elements": [
                "ic2:resource@6"
            ]
        },
        {
            "x": 0,
            "y": -3,
            "z": -9,
            "elements": [
                "thermalfoundation:glass_alloy@6"
            ]
        },
        {
            "x": 0,
            "y": -5,
            "z": 5,
            "elements": [
                "thermalfoundation:glass_alloy@6"
            ]
        },
        {
            "x": -12,
            "y": -3,
            "z": -9,
            "elements": [
                "thermalfoundation:storage@7"
            ]
        },
        {
            "x": 17,
            "y": -4,
            "z": -9,
            "elements": [
                "enderio:block_alloy_endergy@1"
            ]
        },
        {
            "x": -16,
            "y": -3,
            "z": -9,
            "elements": [
                "thermalfoundation:storage@7"
            ]
        },
        {
            "x": 14,
            "y": -4,
            "z": -9,
            "elements": [
                "enderio:block_alloy_endergy@3"
            ]
        },
        {
            "x": 13,
            "y": -5,
            "z": 5,
            "elements": [
                "ic2:resource@6"
            ]
        },
        {
            "x": -18,
            "y": -4,
            "z": 5,
            "elements": [
                "ic2:resource@6"
            ]
        },
        {
            "x": 11,
            "y": -4,
            "z": -9,
            "elements": [
                "enderio:block_alloy_endergy@1"
            ]
        },
        {
            "x": -15,
            "y": -4,
            "z": 5,
            "elements": [
                "enderio:block_alloy_endergy@3"
            ]
        },
        {
            "x": 17,
            "y": -5,
            "z": 5,
            "elements": [
                "ic2:resource@6"
            ]
        },
        {
            "x": -12,
            "y": -4,
            "z": 5,
            "elements": [
                "ic2:resource@6"
            ]
        },
        {
            "x": 1,
            "y": -4,
            "z": -9,
            "elements": [
                "thermalfoundation:glass_alloy@6"
            ]
        },
        {
            "x": 0,
            "y": -4,
            "z": -9,
            "elements": [
                "draconicevolution:draconic_block@0"
            ]
        },
        {
            "x": -1,
            "y": -4,
            "z": -9,
            "elements": [
                "thermalfoundation:glass_alloy@6"
            ]
        },
        {
            "x": -1,
            "y": -4,
            "z": 5,
            "elements": [
                "thermalfoundation:glass_alloy@6"
            ]
        },
        {
            "x": 0,
            "y": -4,
            "z": 5,
            "elements": [
                "avaritia:block_resource@0"
            ]
        },
        {
            "x": 1,
            "y": -4,
            "z": 5,
            "elements": [
                "thermalfoundation:glass_alloy@6"
            ]
        },
        {
            "x": -11,
            "y": -4,
            "z": -9,
            "elements": [
                "enderio:block_alloy@2"
            ]
        },
        {
            "x": -14,
            "y": -4,
            "z": -9,
            "elements": [
                "enderio:block_alloy_endergy@3"
            ]
        },
        {
            "x": 16,
            "y": -5,
            "z": -9,
            "elements": [
                "thermalfoundation:storage@7"
            ]
        },
        {
            "x": -17,
            "y": -4,
            "z": -9,
            "elements": [
                "enderio:block_alloy@2"
            ]
        },
        {
            "x": 12,
            "y": -4,
            "z": 5,
            "elements": [
                "ic2:resource@6"
            ]
        },
        {
            "x": 12,
            "y": -5,
            "z": -9,
            "elements": [
                "thermalfoundation:storage@7"
            ]
        },
        {
            "x": -17,
            "y": -3,
            "z": 5,
            "elements": [
                "ic2:resource@6"
            ]
        },
        {
            "x": 15,
            "y": -4,
            "z": 5,
            "elements": [
                "enderio:block_alloy_endergy@3"
            ]
        },
        {
            "x": 18,
            "y": -4,
            "z": 5,
            "elements": [
                "ic2:resource@6"
            ]
        },
        {
            "x": -13,
            "y": -3,
            "z": 5,
            "elements": [
                "ic2:resource@6"
            ]
        },
        {
            "x": 0,
            "y": -5,
            "z": -9,
            "elements": [
                "thermalfoundation:glass_alloy@6"
            ]
        },
        {
            "x": 0,
            "y": -3,
            "z": 5,
            "elements": [
                "thermalfoundation:glass_alloy@6"
            ]
        },
        {
            "x": -12,
            "y": -5,
            "z": -9,
            "elements": [
                "thermalfoundation:storage@7"
            ]
        },
        {
            "x": 15,
            "y": -6,
            "z": -9,
            "elements": [
                "thermalfoundation:storage@7"
            ]
        },
        {
            "x": -16,
            "y": -5,
            "z": -9,
            "elements": [
                "thermalfoundation:storage@7"
            ]
        },
        {
            "x": 13,
            "y": -6,
            "z": -9,
            "elements": [
                "thermalfoundation:storage@7"
            ]
        },
        {
            "x": 13,
            "y": -3,
            "z": 5,
            "elements": [
                "ic2:resource@6"
            ]
        },
        {
            "x": -16,
            "y": -2,
            "z": 5,
            "elements": [
                "ic2:resource@6"
            ]
        },
        {
            "x": 17,
            "y": -3,
            "z": 5,
            "elements": [
                "ic2:resource@6"
            ]
        },
        {
            "x": -14,
            "y": -2,
            "z": 5,
            "elements": [
                "ic2:resource@6"
            ]
        },
        {
            "x": 0,
            "y": -9,
            "z": 18,
            "elements": [
                "tconstruct:metal@0"
            ]
        },
        {
            "x": -13,
            "y": -6,
            "z": -9,
            "elements": [
                "thermalfoundation:storage@7"
            ]
        },
        {
            "x": -15,
            "y": -6,
            "z": -9,
            "elements": [
                "thermalfoundation:storage@7"
            ]
        },
        {
            "x": 14,
            "y": -7,
            "z": -9,
            "elements": [
                "appliedenergistics2:chiseled_quartz_block@0"
            ]
        },
        {
            "x": 14,
            "y": -2,
            "z": 5,
            "elements": [
                "ic2:resource@6"
            ]
        },
        {
            "x": 16,
            "y": -2,
            "z": 5,
            "elements": [
                "ic2:resource@6"
            ]
        },
        {
            "x": -15,
            "y": -1,
            "z": 5,
            "elements": [
                "ic2:resource@6"
            ]
        },
        {
            "x": -2,
            "y": -8,
            "z": 18,
            "elements": [
                "tconstruct:metal@0"
            ]
        },
        {
            "x": 2,
            "y": -8,
            "z": 18,
            "elements": [
                "tconstruct:metal@0"
            ]
        },
        {
            "x": -14,
            "y": -7,
            "z": -9,
            "elements": [
                "appliedenergistics2:chiseled_quartz_block@0"
            ]
        },
        {
            "x": 15,
            "y": -1,
            "z": 5,
            "elements": [
                "ic2:resource@6"
            ]
        },
        {
            "x": -16,
            "y": -8,
            "z": 1,
            "elements": [
                "tconstruct:metal@0"
            ]
        },
        {
            "x": 15,
            "y": -1,
            "z": -5,
            "elements": [
                "ic2:resource@6"
            ]
        },
        {
            "x": -16,
            "y": -7,
            "z": 1,
            "elements": [
                "appliedenergistics2:chiseled_quartz_block@0"
            ]
        },
        {
            "x": 16,
            "y": -8,
            "z": 1,
            "elements": [
                "tconstruct:metal@0"
            ]
        },
        {
            "x": 0,
            "y": -7,
            "z": 1,
            "elements": [
                "avaritia:block_resource@1"
            ]
        },
        {
            "x": 16,
            "y": -2,
            "z": -5,
            "elements": [
                "ic2:resource@6"
            ]
        },
        {
            "x": -15,
            "y": -1,
            "z": -5,
            "elements": [
                "ic2:resource@6"
            ]
        },
        {
            "x": 14,
            "y": -2,
            "z": -5,
            "elements": [
                "ic2:resource@6"
            ]
        },
        {
            "x": -2,
            "y": -5,
            "z": 18,
            "elements": [
                "thermalfoundation:storage@7"
            ]
        },
        {
            "x": -17,
            "y": -6,
            "z": 1,
            "elements": [
                "thermalfoundation:storage@7"
            ]
        },
        {
            "x": -1,
            "y": -5,
            "z": 18,
            "elements": [
                "thermalfoundation:storage@7"
            ]
        },
        {
            "x": 0,
            "y": -5,
            "z": 18,
            "elements": [
                "draconicevolution:draconic_block@0"
            ]
        },
        {
            "x": 16,
            "y": -7,
            "z": 1,
            "elements": [
                "appliedenergistics2:chiseled_quartz_block@0"
            ]
        },
        {
            "x": -15,
            "y": -6,
            "z": 1,
            "elements": [
                "thermalfoundation:storage@7"
            ]
        },
        {
            "x": 1,
            "y": -5,
            "z": 18,
            "elements": [
                "thermalfoundation:storage@7"
            ]
        },
        {
            "x": 2,
            "y": -5,
            "z": 18,
            "elements": [
                "thermalfoundation:storage@7"
            ]
        },
        {
            "x": -1,
            "y": -6,
            "z": 1,
            "elements": [
                "avaritia:block_resource@1"
            ]
        },
        {
            "x": 0,
            "y": -6,
            "z": 1,
            "elements": [
                "modularmachinery:blockenergyinputhatch"
            ]
        },
        {
            "x": 1,
            "y": -6,
            "z": 1,
            "elements": [
                "avaritia:block_resource@1"
            ]
        },
        {
            "x": 17,
            "y": -3,
            "z": -5,
            "elements": [
                "ic2:resource@6"
            ]
        },
        {
            "x": -14,
            "y": -2,
            "z": -5,
            "elements": [
                "ic2:resource@6"
            ]
        },
        {
            "x": -6,
            "y": -4,
            "z": 18,
            "elements": [
                "enderio:block_alloy_endergy@2"
            ]
        },
        {
            "x": -5,
            "y": -4,
            "z": 18,
            "elements": [
                "ic2:resource@6"
            ]
        },
        {
            "x": -16,
            "y": -2,
            "z": -5,
            "elements": [
                "ic2:resource@6"
            ]
        },
        {
            "x": -4,
            "y": -4,
            "z": 18,
            "elements": [
                "enderio:block_alloy_endergy@2"
            ]
        },
        {
            "x": -3,
            "y": -4,
            "z": 18,
            "elements": [
                "enderio:block_alloy_endergy@2"
            ]
        },
        {
            "x": 13,
            "y": -3,
            "z": -5,
            "elements": [
                "ic2:resource@6"
            ]
        },
        {
            "x": -18,
            "y": -5,
            "z": 1,
            "elements": [
                "thermalfoundation:storage@7"
            ]
        },
        {
            "x": 15,
            "y": -6,
            "z": 1,
            "elements": [
                "thermalfoundation:storage@7"
            ]
        },
        {
            "x": 0,
            "y": -4,
            "z": 18,
            "elements": [
                "draconicevolution:draconic_block@0"
            ]
        },
        {
            "x": 17,
            "y": -6,
            "z": 1,
            "elements": [
                "thermalfoundation:storage@7"
            ]
        },
        {
            "x": -14,
            "y": -5,
            "z": 1,
            "elements": [
                "thermalfoundation:storage@7"
            ]
        },
        {
            "x": 3,
            "y": -4,
            "z": 18,
            "elements": [
                "enderio:block_alloy_endergy@6"
            ]
        },
        {
            "x": 4,
            "y": -4,
            "z": 18,
            "elements": [
                "enderio:block_alloy_endergy@6"
            ]
        },
        {
            "x": 5,
            "y": -4,
            "z": 18,
            "elements": [
                "ic2:resource@6"
            ]
        },
        {
            "x": 6,
            "y": -4,
            "z": 18,
            "elements": [
                "enderio:block_alloy_endergy@6"
            ]
        },
        {
            "x": 0,
            "y": -3,
            "z": -5,
            "elements": [
                "thermalfoundation:glass_alloy@6"
            ]
        },
        {
            "x": -1,
            "y": -5,
            "z": 1,
            "elements": [
                "avaritia:block_resource@1"
            ]
        },
        {
            "x": 0,
            "y": -5,
            "z": 1,
            "elements": [
                "avaritia:block_resource@1"
            ]
        },
        {
            "x": 1,
            "y": -5,
            "z": 1,
            "elements": [
                "avaritia:block_resource@1"
            ]
        },
        {
            "x": 18,
            "y": -4,
            "z": -5,
            "elements": [
                "ic2:resource@6"
            ]
        },
        {
            "x": -13,
            "y": -3,
            "z": -5,
            "elements": [
                "ic2:resource@6"
            ]
        },
        {
            "x": 15,
            "y": -4,
            "z": -5,
            "elements": [
                "enderio:block_alloy_endergy@3"
            ]
        },
        {
            "x": -20,
            "y": -4,
            "z": 1,
            "elements": [
                "tconstruct:metal@0"
            ]
        },
        {
            "x": -17,
            "y": -3,
            "z": -5,
            "elements": [
                "ic2:resource@6"
            ]
        },
        {
            "x": -19,
            "y": -4,
            "z": 1,
            "elements": [
                "enderio:block_alloy_endergy@2"
            ]
        },
        {
            "x": -2,
            "y": -3,
            "z": 18,
            "elements": [
                "thermalfoundation:storage@7"
            ]
        },
        {
            "x": 12,
            "y": -4,
            "z": -5,
            "elements": [
                "ic2:resource@6"
            ]
        },
        {
            "x": 14,
            "y": -5,
            "z": 1,
            "elements": [
                "thermalfoundation:storage@7"
            ]
        },
        {
            "x": -1,
            "y": -3,
            "z": 18,
            "elements": [
                "thermalfoundation:storage@7"
            ]
        },
        {
            "x": -16,
            "y": -4,
            "z": 1,
            "elements": [
                "enderio:block_alloy_endergy@3"
            ]
        },
        {
            "x": 0,
            "y": -3,
            "z": 18,
            "elements": [
                "draconicevolution:draconic_block@0"
            ]
        },
        {
            "x": 1,
            "y": -3,
            "z": 18,
            "elements": [
                "thermalfoundation:storage@7"
            ]
        },
        {
            "x": 2,
            "y": -3,
            "z": 18,
            "elements": [
                "thermalfoundation:storage@7"
            ]
        },
        {
            "x": 18,
            "y": -5,
            "z": 1,
            "elements": [
                "thermalfoundation:storage@7"
            ]
        },
        {
            "x": -13,
            "y": -4,
            "z": 1,
            "elements": [
                "enderio:block_alloy_endergy@2"
            ]
        },
        {
            "x": -12,
            "y": -4,
            "z": 1,
            "elements": [
                "tconstruct:metal@0"
            ]
        },
        {
            "x": -11,
            "y": -4,
            "z": 1,
            "elements": [
                "thermalfoundation:glass_alloy@6"
            ]
        },
        {
            "x": -10,
            "y": -4,
            "z": 1,
            "elements": [
                "thermalfoundation:glass_alloy@6"
            ]
        },
        {
            "x": -9,
            "y": -4,
            "z": 1,
            "elements": [
                "thermalfoundation:glass_alloy@6"
            ]
        },
        {
            "x": -8,
            "y": -4,
            "z": 1,
            "elements": [
                "thermalfoundation:glass_alloy@6"
            ]
        },
        {
            "x": -7,
            "y": -4,
            "z": 1,
            "elements": [
                "thermalfoundation:glass_alloy@6"
            ]
        },
        {
            "x": 1,
            "y": -4,
            "z": -5,
            "elements": [
                "thermalfoundation:glass_alloy@6"
            ]
        },
        {
            "x": -6,
            "y": -4,
            "z": 1,
            "elements": [
                "thermalfoundation:glass_alloy@6"
            ]
        },
        {
            "x": 0,
            "y": -4,
            "z": -5,
            "elements": [
                "draconicevolution:draconic_block@0"
            ]
        },
        {
            "x": -5,
            "y": -4,
            "z": 1,
            "elements": [
                "thermalfoundation:glass_alloy@6"
            ]
        },
        {
            "x": -1,
            "y": -4,
            "z": -5,
            "elements": [
                "thermalfoundation:glass_alloy@6"
            ]
        },
        {
            "x": -4,
            "y": -4,
            "z": 1,
            "elements": [
                "thermalfoundation:glass_alloy@6"
            ]
        },
        {
            "x": -3,
            "y": -4,
            "z": 1,
            "elements": [
                "thermalfoundation:glass_alloy@6"
            ]
        },
        {
            "x": -2,
            "y": -4,
            "z": 1,
            "elements": [
                "thermalfoundation:glass_alloy@6"
            ]
        },
        {
            "x": -1,
            "y": -4,
            "z": 1,
            "elements": [
                "avaritia:block_resource@1"
            ]
        },
        {
            "x": 0,
            "y": -4,
            "z": 1,
            "elements": [
                "avaritia:block_resource@1"
            ]
        },
        {
            "x": 1,
            "y": -4,
            "z": 1,
            "elements": [
                "avaritia:block_resource@1"
            ]
        },
        {
            "x": 2,
            "y": -4,
            "z": 1,
            "elements": [
                "thermalfoundation:glass_alloy@6"
            ]
        },
        {
            "x": 3,
            "y": -4,
            "z": 1,
            "elements": [
                "thermalfoundation:glass_alloy@6"
            ]
        },
        {
            "x": 4,
            "y": -4,
            "z": 1,
            "elements": [
                "thermalfoundation:glass_alloy@6"
            ]
        },
        {
            "x": 5,
            "y": -4,
            "z": 1,
            "elements": [
                "thermalfoundation:glass_alloy@6"
            ]
        },
        {
            "x": 6,
            "y": -4,
            "z": 1,
            "elements": [
                "thermalfoundation:glass_alloy@6"
            ]
        },
        {
            "x": -12,
            "y": -4,
            "z": -5,
            "elements": [
                "ic2:resource@6"
            ]
        },
        {
            "x": 7,
            "y": -4,
            "z": 1,
            "elements": [
                "thermalfoundation:glass_alloy@6"
            ]
        },
        {
            "x": 8,
            "y": -4,
            "z": 1,
            "elements": [
                "thermalfoundation:glass_alloy@6"
            ]
        },
        {
            "x": 17,
            "y": -5,
            "z": -5,
            "elements": [
                "ic2:resource@6"
            ]
        },
        {
            "x": 9,
            "y": -4,
            "z": 1,
            "elements": [
                "thermalfoundation:glass_alloy@6"
            ]
        },
        {
            "x": -15,
            "y": -4,
            "z": -5,
            "elements": [
                "enderio:block_alloy_endergy@3"
            ]
        },
        {
            "x": 10,
            "y": -4,
            "z": 1,
            "elements": [
                "thermalfoundation:glass_alloy@6"
            ]
        },
        {
            "x": 11,
            "y": -4,
            "z": 1,
            "elements": [
                "thermalfoundation:glass_alloy@6"
            ]
        },
        {
            "x": 12,
            "y": -4,
            "z": 1,
            "elements": [
                "tconstruct:metal@0"
            ]
        },
        {
            "x": 13,
            "y": -5,
            "z": -5,
            "elements": [
                "ic2:resource@6"
            ]
        },
        {
            "x": -18,
            "y": -4,
            "z": -5,
            "elements": [
                "ic2:resource@6"
            ]
        },
        {
            "x": 13,
            "y": -4,
            "z": 1,
            "elements": [
                "enderio:block_alloy_endergy@6"
            ]
        },
        {
            "x": -18,
            "y": -3,
            "z": 1,
            "elements": [
                "thermalfoundation:storage@7"
            ]
        },
        {
            "x": 16,
            "y": -4,
            "z": 1,
            "elements": [
                "enderio:block_alloy_endergy@3"
            ]
        },
        {
            "x": -14,
            "y": -3,
            "z": 1,
            "elements": [
                "thermalfoundation:storage@7"
            ]
        },
        {
            "x": 19,
            "y": -4,
            "z": 1,
            "elements": [
                "enderio:block_alloy_endergy@6"
            ]
        },
        {
            "x": 20,
            "y": -4,
            "z": 1,
            "elements": [
                "tconstruct:metal@0"
            ]
        },
        {
            "x": 0,
            "y": -5,
            "z": -5,
            "elements": [
                "thermalfoundation:glass_alloy@6"
            ]
        },
        {
            "x": -1,
            "y": -3,
            "z": 1,
            "elements": [
                "avaritia:block_resource@1"
            ]
        },
        {
            "x": 0,
            "y": -3,
            "z": 1,
            "elements": [
                "avaritia:block_resource@1"
            ]
        },
        {
            "x": 1,
            "y": -3,
            "z": 1,
            "elements": [
                "avaritia:block_resource@1"
            ]
        },
        {
            "x": -13,
            "y": -5,
            "z": -5,
            "elements": [
                "ic2:resource@6"
            ]
        },
        {
            "x": 16,
            "y": -6,
            "z": -5,
            "elements": [
                "ic2:resource@6"
            ]
        },
        {
            "x": 14,
            "y": -6,
            "z": -5,
            "elements": [
                "ic2:resource@6"
            ]
        },
        {
            "x": -17,
            "y": -5,
            "z": -5,
            "elements": [
                "ic2:resource@6"
            ]
        },
        {
            "x": 0,
            "y": 1,
            "z": -18,
            "elements": [
                "tconstruct:metal@0"
            ]
        },
        {
            "x": 14,
            "y": -3,
            "z": 1,
            "elements": [
                "thermalfoundation:storage@7"
            ]
        },
        {
            "x": -17,
            "y": -2,
            "z": 1,
            "elements": [
                "thermalfoundation:storage@7"
            ]
        },
        {
            "x": -15,
            "y": -2,
            "z": 1,
            "elements": [
                "thermalfoundation:storage@7"
            ]
        },
        {
            "x": 18,
            "y": -3,
            "z": 1,
            "elements": [
                "thermalfoundation:storage@7"
            ]
        },
        {
            "x": 0,
            "y": -9,
            "z": 14,
            "elements": [
                "tconstruct:metal@0"
            ]
        },
        {
            "x": -1,
            "y": -2,
            "z": 1,
            "elements": [
                "avaritia:block_resource@1"
            ]
        },
        {
            "x": 0,
            "y": -2,
            "z": 1,
            "elements": [
                "modularmachinery:blockoutputbus"
            ]
        },
        {
            "x": 1,
            "y": -2,
            "z": 1,
            "elements": [
                "avaritia:block_resource@1"
            ]
        },
        {
            "x": -14,
            "y": -6,
            "z": -5,
            "elements": [
                "ic2:resource@6"
            ]
        },
        {
            "x": 15,
            "y": -7,
            "z": -5,
            "elements": [
                "ic2:resource@6"
            ]
        },
        {
            "x": -16,
            "y": -6,
            "z": -5,
            "elements": [
                "ic2:resource@6"
            ]
        },
        {
            "x": 2,
            "y": 0,
            "z": -18,
            "elements": [
                "tconstruct:metal@0"
            ]
        },
        {
            "x": -2,
            "y": 0,
            "z": 18,
            "elements": [
                "tconstruct:metal@0"
            ]
        },
        {
            "x": 15,
            "y": -2,
            "z": 1,
            "elements": [
                "thermalfoundation:storage@7"
            ]
        },
        {
            "x": -16,
            "y": -1,
            "z": 1,
            "elements": [
                "appliedenergistics2:chiseled_quartz_block@0"
            ]
        },
        {
            "x": -2,
            "y": 0,
            "z": -18,
            "elements": [
                "tconstruct:metal@0"
            ]
        },
        {
            "x": 17,
            "y": -2,
            "z": 1,
            "elements": [
                "thermalfoundation:storage@7"
            ]
        },
        {
            "x": -2,
            "y": -8,
            "z": 14,
            "elements": [
                "tconstruct:metal@0"
            ]
        },
        {
            "x": 2,
            "y": 0,
            "z": 18,
            "elements": [
                "tconstruct:metal@0"
            ]
        },
        {
            "x": 2,
            "y": -8,
            "z": 14,
            "elements": [
                "tconstruct:metal@0"
            ]
        },
        {
            "x": 0,
            "y": -1,
            "z": 1,
            "elements": [
                "avaritia:block_resource@1"
            ]
        },
        {
            "x": -15,
            "y": -7,
            "z": -5,
            "elements": [
                "ic2:resource@6"
            ]
        },
        {
            "x": -9,
            "y": -7,
            "z": 14,
            "elements": [
                "appliedenergistics2:chiseled_quartz_block@0"
            ]
        },
        {
            "x": -8,
            "y": -7,
            "z": 14,
            "elements": [
                "appliedenergistics2:chiseled_quartz_block@0"
            ]
        },
        {
            "x": -7,
            "y": -7,
            "z": 14,
            "elements": [
                "appliedenergistics2:chiseled_quartz_block@0"
            ]
        },
        {
            "x": 16,
            "y": 0,
            "z": -1,
            "elements": [
                "tconstruct:metal@0"
            ]
        },
        {
            "x": -16,
            "y": 0,
            "z": 1,
            "elements": [
                "tconstruct:metal@0"
            ]
        },
        {
            "x": 0,
            "y": 1,
            "z": 18,
            "elements": [
                "tconstruct:metal@0"
            ]
        },
        {
            "x": 16,
            "y": -1,
            "z": 1,
            "elements": [
                "appliedenergistics2:chiseled_quartz_block@0"
            ]
        },
        {
            "x": 7,
            "y": -7,
            "z": 14,
            "elements": [
                "appliedenergistics2:chiseled_quartz_block@0"
            ]
        },
        {
            "x": 8,
            "y": -7,
            "z": 14,
            "elements": [
                "appliedenergistics2:chiseled_quartz_block@0"
            ]
        },
        {
            "x": 9,
            "y": -7,
            "z": 14,
            "elements": [
                "appliedenergistics2:chiseled_quartz_block@0"
            ]
        },
        {
            "x": -12,
            "y": -6,
            "z": 14,
            "elements": [
                "thermalfoundation:storage@7"
            ]
        },
        {
            "x": -11,
            "y": -6,
            "z": 14,
            "elements": [
                "thermalfoundation:storage@7"
            ]
        },
        {
            "x": -10,
            "y": -6,
            "z": 14,
            "elements": [
                "thermalfoundation:storage@7"
            ]
        },
        {
            "x": -6,
            "y": -6,
            "z": 14,
            "elements": [
                "thermalfoundation:storage@7"
            ]
        },
        {
            "x": 16,
            "y": -1,
            "z": -1,
            "elements": [
                "appliedenergistics2:chiseled_quartz_block@0"
            ]
        },
        {
            "x": -5,
            "y": -6,
            "z": 14,
            "elements": [
                "ic2:resource@6"
            ]
        },
        {
            "x": -16,
            "y": 0,
            "z": -1,
            "elements": [
                "tconstruct:metal@0"
            ]
        },
        {
            "x": -4,
            "y": -6,
            "z": 14,
            "elements": [
                "thermalfoundation:storage@7"
            ]
        },
        {
            "x": 16,
            "y": 0,
            "z": 1,
            "elements": [
                "tconstruct:metal@0"
            ]
        },
        {
            "x": -3,
            "y": -6,
            "z": 14,
            "elements": [
                "thermalfoundation:storage@7"
            ]
        },
        {
            "x": 3,
            "y": -6,
            "z": 14,
            "elements": [
                "thermalfoundation:storage@7"
            ]
        },
        {
            "x": 4,
            "y": -6,
            "z": 14,
            "elements": [
                "thermalfoundation:storage@7"
            ]
        },
        {
            "x": 5,
            "y": -6,
            "z": 14,
            "elements": [
                "ic2:resource@6"
            ]
        },
        {
            "x": 6,
            "y": -6,
            "z": 14,
            "elements": [
                "thermalfoundation:storage@7"
            ]
        },
        {
            "x": 10,
            "y": -6,
            "z": 14,
            "elements": [
                "thermalfoundation:storage@7"
            ]
        },
        {
            "x": 0,
            "y": -1,
            "z": -1,
            "elements": [
                "avaritia:block_resource@1"
            ]
        },
        {
            "x": 11,
            "y": -6,
            "z": 14,
            "elements": [
                "thermalfoundation:storage@7"
            ]
        },
        {
            "x": 12,
            "y": -6,
            "z": 14,
            "elements": [
                "thermalfoundation:storage@7"
            ]
        },
        {
            "x": -14,
            "y": -5,
            "z": 14,
            "elements": [
                "ic2:resource@6"
            ]
        },
        {
            "x": -13,
            "y": -5,
            "z": 14,
            "elements": [
                "thermalfoundation:storage@7"
            ]
        },
        {
            "x": 2,
            "y": -3,
            "z": -18,
            "elements": [
                "thermalfoundation:storage@7"
            ]
        },
        {
            "x": 1,
            "y": -3,
            "z": -18,
            "elements": [
                "thermalfoundation:storage@7"
            ]
        },
        {
            "x": 17,
            "y": -2,
            "z": -1,
            "elements": [
                "thermalfoundation:storage@7"
            ]
        },
        {
            "x": 0,
            "y": -3,
            "z": -18,
            "elements": [
                "draconicevolution:draconic_block@0"
            ]
        },
        {
            "x": -1,
            "y": -3,
            "z": -18,
            "elements": [
                "thermalfoundation:storage@7"
            ]
        },
        {
            "x": 15,
            "y": -2,
            "z": -1,
            "elements": [
                "thermalfoundation:storage@7"
            ]
        },
        {
            "x": -16,
            "y": -1,
            "z": -1,
            "elements": [
                "appliedenergistics2:chiseled_quartz_block@0"
            ]
        },
        {
            "x": -2,
            "y": -3,
            "z": -18,
            "elements": [
                "thermalfoundation:storage@7"
            ]
        },
        {
            "x": -2,
            "y": -5,
