{
    "registryname": "solar_panel_0",
    "localizedname": "§b聚焦型太阳能热发电机",
    "requires-blueprint": false,
    "parts": [
        {
            "x": -1,
            "y": 0,
            "z": 0,
            "elements": [
                "minecraft:quartz_block@1"
            ]
        },
        {
            "x": 1,
            "y": 0,
            "z": 0,
            "elements": [
                "minecraft:quartz_block@1"
            ]
        },
        {
            "x": -6,
            "y": -2,
            "z": 7,
            "elements": [
                "minecraft:quartz_block@2"
            ]
        },
        {
            "x": -5,
            "y": 0,
            "z": 8,
            "elements": [
                "thermalfoundation:glass@2"
            ]
        },
        {
            "x": -4,
            "y": 0,
            "z": 8,
            "elements": [
                "thermalfoundation:glass@2"
            ]
        },
        {
            "x": 0,
            "y": 0,
            "z": 8,
            "elements": [
                "ic2:fence@0"
            ]
        },
        {
            "x": 4,
            "y": 0,
            "z": 8,
            "elements": [
                "thermalfoundation:glass@2"
            ]
        },
        {
            "x": 5,
            "y": 0,
            "z": 8,
            "elements": [
                "thermalfoundation:glass@2"
            ]
        },
        {
            "x": 6,
            "y": -2,
            "z": 7,
            "elements": [
                "minecraft:quartz_block@2"
            ]
        },
        {
            "x": -3,
            "y": 1,
            "z": 0,
            "elements": [
                "thermalfoundation:glass@2"
            ]
        },
        {
            "x": 1,
            "y": -1,
            "z": 0,
            "elements": [
                "minecraft:quartz_block@1"
            ]
        },
        {
            "x": -2,
            "y": 1,
            "z": 0,
            "elements": [
                "thermalfoundation:glass@2"
            ]
        },
        {
            "x": 0,
            "y": -1,
            "z": 0,
            "elements": [
                "casings_energy"
            ]
        },
        {
            "x": -1,
            "y": 1,
            "z": 0,
            "elements": [
                "thermalfoundation:glass@2"
            ]
        },
        {
            "x": -1,
            "y": -1,
            "z": 0,
            "elements": [
                "minecraft:quartz_block@1"
            ]
        },
        {
            "x": 0,
            "y": 1,
            "z": 0,
            "elements": [
                "thermalfoundation:glass@2"
            ]
        },
        {
            "x": 1,
            "y": 1,
            "z": 0,
            "elements": [
                "thermalfoundation:glass@2"
            ]
        },
        {
            "x": 2,
            "y": 1,
            "z": 0,
            "elements": [
                "thermalfoundation:glass@2"
            ]
        },
        {
            "x": -6,
            "y": 1,
            "z": 8,
            "elements": [
                "thermalfoundation:glass@2"
            ]
        },
        {
            "x": 3,
            "y": 1,
            "z": 0,
            "elements": [
                "thermalfoundation:glass@2"
            ]
        },
        {
            "x": -6,
            "y": -1,
            "z": 7,
            "elements": [
                "minecraft:quartz_block@1"
            ]
        },
        {
            "x": -5,
            "y": -1,
            "z": 7,
            "elements": [
                "minecraft:iron_block@0"
            ]
        },
        {
            "x": -4,
            "y": -1,
            "z": 7,
            "elements": [
                "minecraft:iron_block@0"
            ]
        },
        {
            "x": -3,
            "y": -1,
            "z": 7,
            "elements": [
                "minecraft:iron_block@0"
            ]
        },
        {
            "x": -2,
            "y": -1,
            "z": 7,
            "elements": [
                "minecraft:iron_block@0"
            ]
        },
        {
            "x": -1,
            "y": -1,
            "z": 7,
            "elements": [
                "minecraft:iron_block@0"
            ]
        },
        {
            "x": 0,
            "y": -1,
            "z": 7,
            "elements": [
                "minecraft:iron_block@0"
            ]
        },
        {
            "x": 1,
            "y": -1,
            "z": 7,
            "elements": [
                "minecraft:iron_block@0"
            ]
        },
        {
            "x": 2,
            "y": -1,
            "z": 7,
            "elements": [
                "minecraft:iron_block@0"
            ]
        },
        {
            "x": 3,
            "y": -1,
            "z": 7,
            "elements": [
                "minecraft:iron_block@0"
            ]
        },
        {
            "x": 4,
            "y": -1,
            "z": 7,
            "elements": [
                "minecraft:iron_block@0"
            ]
        },
        {
            "x": 5,
            "y": -1,
            "z": 7,
            "elements": [
                "minecraft:iron_block@0"
            ]
        },
        {
            "x": 6,
            "y": 1,
            "z": 8,
            "elements": [
                "thermalfoundation:glass@2"
            ]
        },
        {
            "x": 6,
            "y": -1,
            "z": 7,
            "elements": [
                "minecraft:quartz_block@1"
            ]
        },
        {
            "x": 1,
            "y": -2,
            "z": 0,
            "elements": [
                "minecraft:quartz_block@2"
            ]
        },
        {
            "x": 0,
            "y": -2,
            "z": 0,
            "elements": [
                "gugu-utils:environmenthatch@0"
            ]
        },
        {
            "x": -1,
            "y": -2,
            "z": 0,
            "elements": [
                "minecraft:quartz_block@2"
            ]
        },
        {
            "x": 0,
            "y": 2,
            "z": 0,
            "elements": [
                "thermalfoundation:glass@2"
            ]
        },
        {
            "x": -6,
            "y": 0,
            "z": 7,
            "elements": [
                "minecraft:quartz_block@1"
            ]
        },
        {
            "x": -6,
            "y": -2,
            "z": 6,
            "elements": [
                "minecraft:quartz_block@2"
            ]
        },
        {
            "x": -5,
            "y": 0,
            "z": 7,
            "elements": [
                "thermalfoundation:glass@2"
            ]
        },
        {
            "x": 0,
            "y": 0,
            "z": 7,
            "elements": [
                "ic2:fence@0"
            ]
        },
        {
            "x": 5,
            "y": 0,
            "z": 7,
            "elements": [
                "thermalfoundation:glass@2"
            ]
        },
        {
            "x": 6,
            "y": 0,
            "z": 7,
            "elements": [
                "minecraft:quartz_block@1"
            ]
        },
        {
            "x": 6,
            "y": -2,
            "z": 6,
            "elements": [
                "minecraft:quartz_block@2"
            ]
        },
        {
            "x": -6,
            "y": 1,
            "z": 7,
            "elements": [
                "thermalfoundation:glass@2"
            ]
        },
        {
            "x": -6,
            "y": -1,
            "z": 6,
            "elements": [
                "minecraft:quartz_block@1"
            ]
        },
        {
            "x": -5,
            "y": -1,
            "z": 6,
            "elements": [
                "minecraft:iron_block@0"
            ]
        },
        {
            "x": -4,
            "y": -1,
            "z": 6,
            "elements": [
                "minecraft:iron_block@0"
            ]
        },
        {
            "x": -3,
            "y": -1,
            "z": 6,
            "elements": [
                "minecraft:iron_block@0"
            ]
        },
        {
            "x": -2,
            "y": -1,
            "z": 6,
            "elements": [
                "minecraft:iron_block@0"
            ]
        },
        {
            "x": -1,
            "y": -1,
            "z": 6,
            "elements": [
                "minecraft:iron_block@0"
            ]
        },
        {
            "x": 0,
            "y": 1,
            "z": 7,
            "elements": [
                "ic2:fence@0"
            ]
        },
        {
            "x": 0,
            "y": -1,
            "z": 6,
            "elements": [
                "minecraft:iron_block@0"
            ]
        },
        {
            "x": 1,
            "y": -1,
            "z": 6,
            "elements": [
                "minecraft:iron_block@0"
            ]
        },
        {
            "x": 2,
            "y": -1,
            "z": 6,
            "elements": [
                "minecraft:iron_block@0"
            ]
        },
        {
            "x": 3,
            "y": -1,
            "z": 6,
            "elements": [
                "minecraft:iron_block@0"
            ]
        },
        {
            "x": 4,
            "y": -1,
            "z": 6,
            "elements": [
                "minecraft:iron_block@0"
            ]
        },
        {
            "x": 5,
            "y": -1,
            "z": 6,
            "elements": [
                "minecraft:iron_block@0"
            ]
        },
        {
            "x": 6,
            "y": 1,
            "z": 7,
            "elements": [
                "thermalfoundation:glass@2"
            ]
        },
        {
            "x": 6,
            "y": -1,
            "z": 6,
            "elements": [
                "minecraft:quartz_block@1"
            ]
        },
        {
            "x": -6,
            "y": 0,
            "z": 6,
            "elements": [
                "minecraft:quartz_block@1"
            ]
        },
        {
            "x": -6,
            "y": -2,
            "z": 5,
            "elements": [
                "minecraft:quartz_block@2"
            ]
        },
        {
            "x": -5,
            "y": 0,
            "z": 6,
            "elements": [
                "thermalfoundation:glass@2"
            ]
        },
        {
            "x": -4,
            "y": 0,
            "z": 6,
            "elements": [
                "thermalfoundation:glass@2"
            ]
        },
        {
            "x": -2,
            "y": 0,
            "z": 6,
            "elements": [
                "ic2:fence@0"
            ]
        },
        {
            "x": -1,
            "y": 0,
            "z": 6,
            "elements": [
                "ic2:fence@0"
            ]
        },
        {
            "x": 0,
            "y": 0,
            "z": 6,
            "elements": [
                "ic2:fence@0"
            ]
        },
        {
            "x": 1,
            "y": 0,
            "z": 6,
            "elements": [
                "ic2:fence@0"
            ]
        },
        {
            "x": 2,
            "y": 0,
            "z": 6,
            "elements": [
                "ic2:fence@0"
            ]
        },
        {
            "x": 4,
            "y": 0,
            "z": 6,
            "elements": [
                "thermalfoundation:glass@2"
            ]
        },
        {
            "x": 5,
            "y": 0,
            "z": 6,
            "elements": [
                "thermalfoundation:glass@2"
            ]
        },
        {
            "x": 6,
            "y": 0,
            "z": 6,
            "elements": [
                "minecraft:quartz_block@1"
            ]
        },
        {
            "x": 6,
            "y": -2,
            "z": 5,
            "elements": [
                "minecraft:quartz_block@2"
            ]
        },
        {
            "x": -6,
            "y": 1,
            "z": 6,
            "elements": [
                "thermalfoundation:glass@2"
            ]
        },
        {
            "x": -6,
            "y": -1,
            "z": 5,
            "elements": [
                "minecraft:quartz_block@1"
            ]
        },
        {
            "x": -5,
            "y": 1,
            "z": 6,
            "elements": [
                "thermalfoundation:glass@2"
            ]
        },
        {
            "x": -5,
            "y": -1,
            "z": 5,
            "elements": [
                "minecraft:iron_block@0"
            ]
        },
        {
            "x": -4,
            "y": -1,
            "z": 5,
            "elements": [
                "minecraft:iron_block@0"
            ]
        },
        {
            "x": -3,
            "y": -1,
            "z": 5,
            "elements": [
                "minecraft:iron_block@0"
            ]
        },
        {
            "x": -2,
            "y": -1,
            "z": 5,
            "elements": [
                "minecraft:iron_block@0"
            ]
        },
        {
            "x": -1,
            "y": 1,
            "z": 6,
            "elements": [
                "ic2:fence@0"
            ]
        },
        {
            "x": 0,
            "y": 3,
            "z": 7,
            "elements": [
                "thermalfoundation:glass@2"
            ]
        },
        {
            "x": -1,
            "y": -1,
            "z": 5,
            "elements": [
                "minecraft:iron_block@0"
            ]
        },
        {
            "x": 0,
            "y": 1,
            "z": 6,
            "elements": [
                "ic2:fence@0"
            ]
        },
        {
            "x": 0,
            "y": -1,
            "z": 5,
            "elements": [
                "minecraft:iron_block@0"
            ]
        },
        {
            "x": 1,
            "y": 1,
            "z": 6,
            "elements": [
                "ic2:fence@0"
            ]
        },
        {
            "x": 1,
            "y": -1,
            "z": 5,
            "elements": [
                "minecraft:iron_block@0"
            ]
        },
        {
            "x": 2,
            "y": -1,
            "z": 5,
            "elements": [
                "minecraft:iron_block@0"
            ]
        },
        {
            "x": 3,
            "y": -1,
            "z": 5,
            "elements": [
                "minecraft:iron_block@0"
            ]
        },
        {
            "x": 4,
            "y": -1,
            "z": 5,
            "elements": [
                "minecraft:iron_block@0"
            ]
        },
        {
            "x": 5,
            "y": 1,
            "z": 6,
            "elements": [
                "thermalfoundation:glass@2"
            ]
        },
        {
            "x": 5,
            "y": -1,
            "z": 5,
            "elements": [
                "minecraft:iron_block@0"
            ]
        },
        {
            "x": 6,
            "y": 1,
            "z": 6,
            "elements": [
                "thermalfoundation:glass@2"
            ]
        },
        {
            "x": 6,
            "y": -1,
            "z": 5,
            "elements": [
                "minecraft:quartz_block@1"
            ]
        },
        {
            "x": -6,
            "y": 2,
            "z": 6,
            "elements": [
                "thermalfoundation:glass@2"
            ]
        },
        {
            "x": -6,
            "y": 0,
            "z": 5,
            "elements": [
                "minecraft:quartz_block@1"
            ]
        },
        {
            "x": -5,
            "y": 0,
            "z": 5,
            "elements": [
                "thermalfoundation:glass@2"
            ]
        },
        {
            "x": -5,
            "y": -2,
            "z": 4,
            "elements": [
                "minecraft:quartz_block@2"
            ]
        },
        {
            "x": 0,
            "y": 2,
            "z": 6,
            "elements": [
                "ic2:fence@0"
            ]
        },
        {
            "x": 0,
            "y": 0,
            "z": 5,
            "elements": [
                "ic2:fence@0"
            ]
        },
        {
            "x": 5,
            "y": 0,
            "z": 5,
            "elements": [
                "thermalfoundation:glass@2"
            ]
        },
        {
            "x": 6,
            "y": 2,
            "z": 6,
            "elements": [
                "thermalfoundation:glass@2"
            ]
        },
        {
            "x": 5,
            "y": -2,
            "z": 4,
            "elements": [
                "minecraft:quartz_block@2"
            ]
        },
        {
            "x": 6,
            "y": 0,
            "z": 5,
            "elements": [
                "minecraft:quartz_block@1"
            ]
        },
        {
            "x": -1,
            "y": -2,
            "z": 12,
            "elements": [
                "minecraft:quartz_block@2"
            ]
        },
        {
            "x": 0,
            "y": -2,
            "z": 12,
            "elements": [
                "minecraft:quartz_block@2"
            ]
        },
        {
            "x": 1,
            "y": -2,
            "z": 12,
            "elements": [
                "minecraft:quartz_block@2"
            ]
        },
        {
            "x": -6,
            "y": 1,
            "z": 5,
            "elements": [
                "thermalfoundation:glass@2"
            ]
        },
        {
            "x": -5,
            "y": -1,
            "z": 4,
            "elements": [
                "minecraft:iron_block@0"
            ]
        },
        {
            "x": -4,
            "y": -1,
            "z": 4,
            "elements": [
                "minecraft:iron_block@0"
            ]
        },
        {
            "x": -3,
            "y": -1,
            "z": 4,
            "elements": [
                "minecraft:iron_block@0"
            ]
        },
        {
            "x": -1,
            "y": 3,
            "z": 6,
            "elements": [
                "thermalfoundation:glass@2"
            ]
        },
        {
            "x": -2,
            "y": -1,
            "z": 4,
            "elements": [
                "minecraft:iron_block@0"
            ]
        },
        {
            "x": 0,
            "y": 3,
            "z": 6,
            "elements": [
                "mekanism:reinforcedplasticblock@4"
            ]
        },
        {
            "x": -1,
            "y": -1,
            "z": 4,
            "elements": [
                "minecraft:iron_block@0"
            ]
        },
        {
            "x": 0,
            "y": 1,
            "z": 5,
            "elements": [
                "ic2:fence@0"
            ]
        },
        {
            "x": 1,
            "y": 3,
            "z": 6,
            "elements": [
                "thermalfoundation:glass@2"
            ]
        },
        {
            "x": 0,
            "y": -1,
            "z": 4,
            "elements": [
                "minecraft:iron_block@0"
            ]
        },
        {
            "x": 1,
            "y": -1,
            "z": 4,
            "elements": [
                "minecraft:iron_block@0"
            ]
        },
        {
            "x": 2,
            "y": -1,
            "z": 4,
            "elements": [
                "minecraft:iron_block@0"
            ]
        },
        {
            "x": 3,
            "y": -1,
            "z": 4,
            "elements": [
                "minecraft:iron_block@0"
            ]
        },
        {
            "x": 4,
            "y": -1,
            "z": 4,
            "elements": [
                "minecraft:iron_block@0"
            ]
        },
        {
            "x": 5,
            "y": -1,
            "z": 4,
            "elements": [
                "minecraft:iron_block@0"
            ]
        },
        {
            "x": 6,
            "y": 1,
            "z": 5,
            "elements": [
                "thermalfoundation:glass@2"
            ]
        },
        {
            "x": -1,
            "y": -1,
            "z": 12,
            "elements": [
                "minecraft:quartz_block@1"
            ]
        },
        {
            "x": 0,
            "y": -1,
            "z": 12,
            "elements": [
                "minecraft:quartz_block@1"
            ]
        },
        {
            "x": 1,
            "y": -1,
            "z": 12,
            "elements": [
                "minecraft:quartz_block@1"
            ]
        },
        {
            "x": -5,
            "y": 0,
            "z": 4,
            "elements": [
                "thermalfoundation:glass@2"
            ]
        },
        {
            "x": -4,
            "y": 0,
            "z": 4,
            "elements": [
                "thermalfoundation:glass@2"
            ]
        },
        {
            "x": -4,
            "y": -2,
            "z": 3,
            "elements": [
                "minecraft:quartz_block@2"
            ]
        },
        {
            "x": 0,
            "y": 4,
            "z": 6,
            "elements": [
                "thermalfoundation:glass@2"
            ]
        },
        {
            "x": 0,
            "y": 0,
            "z": 4,
            "elements": [
                "ic2:fence@0"
            ]
        },
        {
            "x": 4,
            "y": 0,
            "z": 4,
            "elements": [
                "thermalfoundation:glass@2"
            ]
        },
        {
            "x": 4,
            "y": -2,
            "z": 3,
            "elements": [
                "minecraft:quartz_block@2"
            ]
        },
        {
            "x": 5,
            "y": 0,
            "z": 4,
            "elements": [
                "thermalfoundation:glass@2"
            ]
        },
        {
            "x": -2,
            "y": -2,
            "z": 11,
            "elements": [
                "minecraft:quartz_block@2"
            ]
        },
        {
            "x": -1,
            "y": 0,
            "z": 12,
            "elements": [
                "minecraft:quartz_block@1"
            ]
        },
        {
            "x": 0,
            "y": 0,
            "z": 12,
            "elements": [
                "minecraft:quartz_block@1"
            ]
        },
        {
            "x": 1,
            "y": 0,
            "z": 12,
            "elements": [
                "minecraft:quartz_block@1"
            ]
        },
        {
            "x": 2,
            "y": -2,
            "z": 11,
            "elements": [
                "minecraft:quartz_block@2"
            ]
        },
        {
            "x": -6,
            "y": 1,
            "z": 4,
            "elements": [
                "thermalfoundation:glass@2"
            ]
        },
        {
            "x": -4,
            "y": -1,
            "z": 3,
            "elements": [
                "minecraft:iron_block@0"
            ]
        },
        {
            "x": -3,
            "y": -1,
            "z": 3,
            "elements": [
                "minecraft:iron_block@0"
            ]
        },
        {
            "x": -2,
            "y": -1,
            "z": 3,
            "elements": [
                "minecraft:iron_block@0"
            ]
        },
        {
            "x": 0,
            "y": 3,
            "z": 5,
            "elements": [
                "thermalfoundation:glass@2"
            ]
        },
        {
            "x": -1,
            "y": -1,
            "z": 3,
            "elements": [
                "minecraft:iron_block@0"
            ]
        },
        {
            "x": 0,
            "y": -1,
            "z": 3,
            "elements": [
                "minecraft:iron_block@0"
            ]
        },
        {
            "x": 1,
            "y": -1,
            "z": 3,
            "elements": [
                "minecraft:iron_block@0"
            ]
        },
        {
            "x": 2,
            "y": -1,
            "z": 3,
            "elements": [
                "minecraft:iron_block@0"
            ]
        },
        {
            "x": 3,
            "y": -1,
            "z": 3,
            "elements": [
                "minecraft:iron_block@0"
            ]
        },
        {
            "x": 4,
            "y": -1,
            "z": 3,
            "elements": [
                "minecraft:iron_block@0"
            ]
        },
        {
            "x": -3,
            "y": 1,
            "z": 12,
            "elements": [
                "thermalfoundation:glass@2"
            ]
        },
        {
            "x": 6,
            "y": 1,
            "z": 4,
            "elements": [
                "thermalfoundation:glass@2"
            ]
        },
        {
            "x": -2,
            "y": 1,
            "z": 12,
            "elements": [
                "thermalfoundation:glass@2"
            ]
        },
        {
            "x": -2,
            "y": -1,
            "z": 11,
            "elements": [
                "minecraft:iron_block@0"
            ]
        },
        {
            "x": -1,
            "y": 1,
            "z": 12,
            "elements": [
                "thermalfoundation:glass@2"
            ]
        },
        {
            "x": -1,
            "y": -1,
            "z": 11,
            "elements": [
                "minecraft:iron_block@0"
            ]
        },
        {
            "x": 0,
            "y": 1,
            "z": 12,
            "elements": [
                "thermalfoundation:glass@2"
            ]
        },
        {
            "x": 0,
            "y": -1,
            "z": 11,
            "elements": [
                "minecraft:iron_block@0"
            ]
        },
        {
            "x": 1,
            "y": 1,
            "z": 12,
            "elements": [
                "thermalfoundation:glass@2"
            ]
        },
        {
            "x": 1,
            "y": -1,
            "z": 11,
            "elements": [
                "minecraft:iron_block@0"
            ]
        },
        {
            "x": 2,
            "y": 1,
            "z": 12,
            "elements": [
                "thermalfoundation:glass@2"
            ]
        },
        {
            "x": 2,
            "y": -1,
            "z": 11,
            "elements": [
                "minecraft:iron_block@0"
            ]
        },
        {
            "x": 3,
            "y": 1,
            "z": 12,
            "elements": [
                "thermalfoundation:glass@2"
            ]
        },
        {
            "x": -4,
            "y": 0,
            "z": 3,
            "elements": [
                "thermalfoundation:glass@2"
            ]
        },
        {
            "x": -3,
            "y": 0,
            "z": 3,
            "elements": [
                "thermalfoundation:glass@2"
            ]
        },
        {
            "x": -3,
            "y": -2,
            "z": 2,
            "elements": [
                "minecraft:quartz_block@2"
            ]
        },
        {
            "x": 3,
            "y": 0,
            "z": 3,
            "elements": [
                "thermalfoundation:glass@2"
            ]
        },
        {
            "x": 3,
            "y": -2,
            "z": 2,
            "elements": [
                "minecraft:quartz_block@2"
            ]
        },
        {
            "x": 4,
            "y": 0,
            "z": 3,
            "elements": [
                "thermalfoundation:glass@2"
            ]
        },
        {
            "x": -3,
            "y": -2,
            "z": 10,
            "elements": [
                "minecraft:quartz_block@2"
            ]
        },
        {
            "x": -2,
            "y": 0,
            "z": 11,
            "elements": [
                "thermalfoundation:glass@2"
            ]
        },
        {
            "x": -1,
            "y": 0,
            "z": 11,
            "elements": [
                "thermalfoundation:glass@2"
            ]
        },
        {
            "x": 0,
            "y": 2,
            "z": 12,
            "elements": [
                "thermalfoundation:glass@2"
            ]
        },
        {
            "x": 0,
            "y": 0,
            "z": 11,
            "elements": [
                "thermalfoundation:glass@2"
            ]
        },
        {
            "x": 1,
            "y": 0,
            "z": 11,
            "elements": [
                "thermalfoundation:glass@2"
            ]
        },
        {
            "x": 2,
            "y": 0,
            "z": 11,
            "elements": [
                "thermalfoundation:glass@2"
            ]
        },
        {
            "x": 3,
            "y": -2,
            "z": 10,
            "elements": [
                "minecraft:quartz_block@2"
            ]
        },
        {
            "x": -6,
            "y": 1,
            "z": 3,
            "elements": [
                "thermalfoundation:glass@2"
            ]
        },
        {
            "x": -5,
            "y": 1,
            "z": 3,
            "elements": [
                "thermalfoundation:glass@2"
            ]
        },
        {
            "x": -3,
            "y": -1,
            "z": 2,
            "elements": [
                "minecraft:iron_block@0"
            ]
        },
        {
            "x": -2,
            "y": -1,
            "z": 2,
            "elements": [
                "minecraft:iron_block@0"
            ]
        },
        {
            "x": -1,
            "y": -1,
            "z": 2,
            "elements": [
                "minecraft:iron_block@0"
            ]
        },
        {
            "x": 0,
            "y": -1,
            "z": 2,
            "elements": [
                "minecraft:iron_block@0"
            ]
        },
        {
            "x": 1,
            "y": -1,
            "z": 2,
            "elements": [
                "minecraft:iron_block@0"
            ]
        },
        {
            "x": 2,
            "y": -1,
            "z": 2,
            "elements": [
                "minecraft:iron_block@0"
            ]
        },
        {
            "x": 3,
            "y": -1,
            "z": 2,
            "elements": [
                "minecraft:iron_block@0"
            ]
        },
        {
            "x": -4,
            "y": 1,
            "z": 11,
            "elements": [
                "thermalfoundation:glass@2"
            ]
        },
        {
            "x": 5,
            "y": 1,
            "z": 3,
            "elements": [
                "thermalfoundation:glass@2"
            ]
        },
        {
            "x": -3,
            "y": 1,
            "z": 11,
            "elements": [
                "thermalfoundation:glass@2"
            ]
        },
        {
            "x": 6,
            "y": 1,
            "z": 3,
            "elements": [
                "thermalfoundation:glass@2"
            ]
        },
        {
            "x": -3,
            "y": -1,
            "z": 10,
            "elements": [
                "minecraft:iron_block@0"
            ]
        },
        {
            "x": -2,
            "y": -1,
            "z": 10,
            "elements": [
                "minecraft:iron_block@0"
            ]
        },
        {
            "x": -1,
            "y": -1,
            "z": 10,
            "elements": [
                "minecraft:iron_block@0"
            ]
        },
        {
            "x": 0,
            "y": 1,
            "z": 11,
            "elements": [
                "thermalfoundation:glass@2"
            ]
        },
        {
            "x": 0,
            "y": -1,
            "z": 10,
            "elements": [
                "minecraft:iron_block@0"
            ]
        },
        {
            "x": 1,
            "y": -1,
            "z": 10,
            "elements": [
                "minecraft:iron_block@0"
            ]
        },
        {
            "x": 2,
            "y": -1,
            "z": 10,
            "elements": [
                "minecraft:iron_block@0"
            ]
        },
        {
            "x": 3,
            "y": 1,
            "z": 11,
            "elements": [
                "thermalfoundation:glass@2"
            ]
        },
        {
            "x": 3,
            "y": -1,
            "z": 10,
            "elements": [
                "minecraft:iron_block@0"
            ]
        },
        {
            "x": 4,
            "y": 1,
            "z": 11,
            "elements": [
                "thermalfoundation:glass@2"
            ]
        },
        {
            "x": -3,
            "y": 0,
            "z": 2,
            "elements": [
                "thermalfoundation:glass@2"
            ]
        },
        {
            "x": -2,
            "y": 0,
            "z": 2,
            "elements": [
                "thermalfoundation:glass@2"
            ]
        },
        {
            "x": -2,
            "y": -2,
            "z": 1,
            "elements": [
                "minecraft:quartz_block@2"
            ]
        },
        {
            "x": 0,
            "y": 0,
            "z": 2,
            "elements": [
                "thermalfoundation:glass@2"
            ]
        },
        {
            "x": 2,
            "y": 0,
            "z": 2,
            "elements": [
                "thermalfoundation:glass@2"
            ]
        },
        {
            "x": 2,
            "y": -2,
            "z": 1,
            "elements": [
                "minecraft:quartz_block@2"
            ]
        },
        {
            "x": 3,
            "y": 0,
            "z": 2,
            "elements": [
                "thermalfoundation:glass@2"
            ]
        },
        {
            "x": -4,
            "y": -2,
            "z": 9,
            "elements": [
                "minecraft:quartz_block@2"
            ]
        },
        {
            "x": -3,
            "y": 0,
            "z": 10,
            "elements": [
                "thermalfoundation:glass@2"
            ]
        },
        {
            "x": -2,
            "y": 0,
            "z": 10,
            "elements": [
                "thermalfoundation:glass@2"
            ]
        },
        {
            "x": 0,
            "y": 0,
            "z": 10,
            "elements": [
                "thermalfoundation:glass@2"
            ]
        },
        {
            "x": 2,
            "y": 0,
            "z": 10,
            "elements": [
                "thermalfoundation:glass@2"
            ]
        },
        {
            "x": 3,
            "y": 0,
            "z": 10,
            "elements": [
                "thermalfoundation:glass@2"
            ]
        },
        {
            "x": 4,
            "y": -2,
            "z": 9,
            "elements": [
                "minecraft:quartz_block@2"
            ]
        },
        {
            "x": -5,
            "y": 1,
            "z": 2,
            "elements": [
                "thermalfoundation:glass@2"
            ]
        },
        {
            "x": -4,
            "y": 1,
            "z": 2,
            "elements": [
                "thermalfoundation:glass@2"
            ]
        },
        {
            "x": -2,
            "y": -1,
            "z": 1,
            "elements": [
                "minecraft:iron_block@0"
            ]
        },
        {
            "x": -1,
            "y": -1,
            "z": 1,
            "elements": [
                "minecraft:iron_block@0"
            ]
        },
        {
            "x": 0,
            "y": -1,
            "z": 1,
            "elements": [
                "minecraft:iron_block@0"
            ]
        },
        {
            "x": 1,
            "y": -1,
            "z": 1,
            "elements": [
                "minecraft:iron_block@0"
            ]
        },
        {
            "x": 2,
            "y": -1,
            "z": 1,
            "elements": [
                "minecraft:iron_block@0"
            ]
        },
        {
            "x": -5,
            "y": 1,
            "z": 10,
            "elements": [
                "thermalfoundation:glass@2"
            ]
        },
        {
            "x": 4,
            "y": 1,
            "z": 2,
            "elements": [
                "thermalfoundation:glass@2"
            ]
        },
        {
            "x": -4,
            "y": 1,
            "z": 10,
            "elements": [
                "thermalfoundation:glass@2"
            ]
        },
        {
            "x": 5,
            "y": 1,
            "z": 2,
            "elements": [
                "thermalfoundation:glass@2"
            ]
        },
        {
            "x": -4,
            "y": -1,
            "z": 9,
            "elements": [
                "minecraft:iron_block@0"
            ]
        },
        {
            "x": -3,
            "y": -1,
            "z": 9,
            "elements": [
                "minecraft:iron_block@0"
            ]
        },
        {
            "x": -2,
            "y": -1,
            "z": 9,
            "elements": [
                "minecraft:iron_block@0"
            ]
        },
        {
            "x": -1,
            "y": -1,
            "z": 9,
            "elements": [
                "minecraft:iron_block@0"
            ]
        },
        {
            "x": 0,
            "y": -1,
            "z": 9,
            "elements": [
                "minecraft:iron_block@0"
            ]
        },
        {
            "x": 1,
            "y": -1,
            "z": 9,
            "elements": [
                "minecraft:iron_block@0"
            ]
        },
        {
            "x": 2,
            "y": -1,
            "z": 9,
            "elements": [
                "minecraft:iron_block@0"
            ]
        },
        {
            "x": 3,
            "y": -1,
            "z": 9,
            "elements": [
                "minecraft:iron_block@0"
            ]
        },
        {
            "x": 4,
            "y": 1,
            "z": 10,
            "elements": [
                "thermalfoundation:glass@2"
            ]
        },
        {
            "x": 4,
            "y": -1,
            "z": 9,
            "elements": [
                "minecraft:iron_block@0"
            ]
        },
        {
            "x": 5,
            "y": 1,
            "z": 10,
            "elements": [
                "thermalfoundation:glass@2"
            ]
        },
        {
            "x": -2,
            "y": 0,
            "z": 1,
            "elements": [
                "thermalfoundation:glass@2"
            ]
        },
        {
            "x": -1,
            "y": 0,
            "z": 1,
            "elements": [
                "thermalfoundation:glass@2"
            ]
        },
        {
            "x": 0,
            "y": 0,
            "z": 1,
            "elements": [
                "thermalfoundation:glass@2"
            ]
        },
        {
            "x": 1,
            "y": 0,
            "z": 1,
            "elements": [
                "thermalfoundation:glass@2"
            ]
        },
        {
            "x": 2,
            "y": 0,
            "z": 1,
            "elements": [
                "thermalfoundation:glass@2"
            ]
        },
        {
            "x": -5,
            "y": -2,
            "z": 8,
            "elements": [
                "minecraft:quartz_block@2"
            ]
        },
        {
            "x": -4,
            "y": 0,
            "z": 9,
            "elements": [
                "thermalfoundation:glass@2"
            ]
        },
        {
            "x": -3,
            "y": 0,
            "z": 9,
            "elements": [
                "thermalfoundation:glass@2"
            ]
        },
        {
            "x": 3,
            "y": 0,
            "z": 9,
            "elements": [
                "thermalfoundation:glass@2"
            ]
        },
        {
            "x": 4,
            "y": 0,
            "z": 9,
            "elements": [
                "thermalfoundation:glass@2"
            ]
        },
        {
            "x": 5,
            "y": -2,
            "z": 8,
            "elements": [
                "minecraft:quartz_block@2"
            ]
        },
        {
            "x": -4,
            "y": 1,
            "z": 1,
            "elements": [
                "thermalfoundation:glass@2"
            ]
        },
        {
            "x": -3,
            "y": 1,
            "z": 1,
            "elements": [
                "thermalfoundation:glass@2"
            ]
        },
        {
            "x": 0,
            "y": 1,
            "z": 1,
            "elements": [
                "thermalfoundation:glass@2"
            ]
        },
        {
            "x": -6,
            "y": 1,
            "z": 9,
            "elements": [
                "thermalfoundation:glass@2"
            ]
        },
        {
            "x": 3,
            "y": 1,
            "z": 1,
            "elements": [
                "thermalfoundation:glass@2"
            ]
        },
        {
            "x": -5,
            "y": 1,
            "z": 9,
            "elements": [
                "thermalfoundation:glass@2"
            ]
        },
        {
            "x": 4,
            "y": 1,
            "z": 1,
            "elements": [
                "thermalfoundation:glass@2"
            ]
        },
        {
            "x": -5,
            "y": -1,
            "z": 8,
            "elements": [
                "minecraft:iron_block@0"
            ]
        },
        {
            "x": -4,
            "y": -1,
            "z": 8,
            "elements": [
                "minecraft:iron_block@0"
            ]
        },
        {
            "x": -3,
            "y": -1,
            "z": 8,
            "elements": [
                "minecraft:iron_block@0"
            ]
        },
        {
            "x": -2,
            "y": -1,
            "z": 8,
            "elements": [
                "minecraft:iron_block@0"
            ]
        },
        {
            "x": -1,
            "y": -1,
            "z": 8,
            "elements": [
                "minecraft:iron_block@0"
            ]
        },
        {
            "x": 0,
            "y": -1,
            "z": 8,
            "elements": [
                "minecraft:iron_block@0"
            ]
        },
        {
            "x": 1,
            "y": -1,
            "z": 8,
            "elements": [
                "minecraft:iron_block@0"
            ]
        },
        {
            "x": 2,
            "y": -1,
            "z": 8,
            "elements": [
                "minecraft:iron_block@0"
            ]
        },
        {
            "x": 3,
            "y": -1,
            "z": 8,
            "elements": [
                "minecraft:iron_block@0"
            ]
        },
        {
            "x": 4,
            "y": -1,
            "z": 8,
            "elements": [
                "minecraft:iron_block@0"
            ]
        },
        {
            "x": 5,
            "y": 1,
            "z": 9,
            "elements": [
                "thermalfoundation:glass@2"
            ]
        },
        {
            "x": 5,
            "y": -1,
            "z": 8,
            "elements": [
                "minecraft:iron_block@0"
            ]
        },
        {
            "x": 6,
            "y": 1,
            "z": 9,
            "elements": [
                "thermalfoundation:glass@2"
            ]
        }
    ]}