{
    "registryname": "ECO-T7",
    "localizedname": "§bECO-§aT7 §e魔力收集器",
    "failure-action": "still",
    "requires-blueprint": false,
    "parts": [
        {
            "x": -1,
            "y": 0,
            "z": 0,
            "elements": [
                "minecraft:concrete@3"
            ]
        },
        {
            "x": -2,
            "y": 0,
            "z": 0,
            "elements": [
                "minecraft:concrete@3"
            ]
        },
        {
            "x": 1,
            "y": 0,
            "z": 0,
            "elements": [
                "minecraft:concrete@3"
            ]
        },
        {
            "x": -3,
            "y": 0,
            "z": 0,
            "elements": [
                "minecraft:concrete@3"
            ]
        },
        {
            "x": 2,
            "y": 0,
            "z": 0,
            "elements": [
                "minecraft:concrete@3"
            ]
        },
        {
            "x": -5,
            "y": 2,
            "z": 9,
            "elements": [
                "minecraft:stained_glass_pane@9"
            ]
        },
        {
            "x": -4,
            "y": 0,
            "z": 0,
            "elements": [
                "minecraft:concrete@3"
            ]
        },
        {
            "x": 3,
            "y": 0,
            "z": 0,
            "elements": [
                "minecraft:concrete@3"
            ]
        },
        {
            "x": -5,
            "y": 0,
            "z": 8,
            "elements": [
                "minecraft:concrete@3"
            ]
        },
        {
            "x": -5,
            "y": 0,
            "z": 0,
            "elements": [
                "minecraft:light_blue_glazed_terracotta@1"
            ]
        },
        {
            "x": 4,
            "y": 0,
            "z": 0,
            "elements": [
                "minecraft:concrete@3"
            ]
        },
        {
            "x": 5,
            "y": 2,
            "z": 1,
            "elements": [
                "minecraft:stained_glass_pane@9"
            ]
        },
        {
            "x": -4,
            "y": 0,
            "z": 8,
            "elements": [
                "botania:storage@3"
            ]
        },
        {
            "x": 5,
            "y": 0,
            "z": 0,
            "elements": [
                "minecraft:light_blue_glazed_terracotta@0"
            ]
        },
        {
            "x": -3,
            "y": 0,
            "z": 8,
            "elements": [
                "botania:storage@4"
            ]
        },
        {
            "x": 0,
            "y": 6,
            "z": 11,
            "elements": [
                "modularmachinery:blockcasing@3"
            ]
        },
        {
            "x": -2,
            "y": 0,
            "z": 8,
            "elements": [
                "botania:quartztypemana@0"
            ]
        },
        {
            "x": -1,
            "y": 0,
            "z": 8,
            "elements": [
                "botania:quartztypemana@0"
            ]
        },
        {
            "x": 0,
            "y": 2,
            "z": 9,
            "elements": [
                "modularmachinery:blockcasing@0"
            ]
        },
        {
            "x": 0,
            "y": 0,
            "z": 8,
            "elements": [
                "botania:quartztypemana@0"
            ]
        },
        {
            "x": 1,
            "y": 0,
            "z": 8,
            "elements": [
                "botania:quartztypemana@0"
            ]
        },
        {
            "x": 2,
            "y": 0,
            "z": 8,
            "elements": [
                "botania:quartztypemana@0"
            ]
        },
        {
            "x": 3,
            "y": 0,
            "z": 8,
            "elements": [
                "botania:storage@4"
            ]
        },
        {
            "x": 4,
            "y": 0,
            "z": 8,
            "elements": [
                "botania:storage@3"
            ]
        },
        {
            "x": 5,
            "y": 2,
            "z": 9,
            "elements": [
                "minecraft:stained_glass_pane@9"
            ]
        },
        {
            "x": 5,
            "y": 0,
            "z": 8,
            "elements": [
                "minecraft:concrete@3"
            ]
        },
        {
            "x": -5,
            "y": 3,
            "z": 1,
            "elements": [
                "minecraft:stained_glass_pane@9"
            ]
        },
        {
            "x": -5,
            "y": 1,
            "z": 0,
            "elements": [
                "minecraft:stained_glass_pane@9"
            ]
        },
        {
            "x": -4,
            "y": 1,
            "z": 0,
            "elements": [
                "minecraft:stained_glass_pane@9"
            ]
        },
        {
            "x": -3,
            "y": 1,
            "z": 0,
            "elements": [
                "minecraft:stained_glass_pane@9"
            ]
        },
        {
            "x": -2,
            "y": 1,
            "z": 0,
            "elements": [
                "minecraft:stained_glass_pane@9"
            ]
        },
        {
            "x": 2,
            "y": 1,
            "z": 0,
            "elements": [
                "minecraft:stained_glass_pane@9"
            ]
        },
        {
            "x": -5,
            "y": 3,
            "z": 9,
            "elements": [
                "minecraft:stained_glass_pane@9"
            ]
        },
        {
            "x": 3,
            "y": 1,
            "z": 0,
            "elements": [
                "minecraft:stained_glass_pane@9"
            ]
        },
        {
            "x": -5,
            "y": 1,
            "z": 8,
            "elements": [
                "minecraft:stained_glass_pane@9"
            ]
        },
        {
            "x": 4,
            "y": 1,
            "z": 0,
            "elements": [
                "minecraft:stained_glass_pane@9"
            ]
        },
        {
            "x": 5,
            "y": 3,
            "z": 1,
            "elements": [
                "minecraft:stained_glass_pane@9"
            ]
        },
        {
            "x": 5,
            "y": 1,
            "z": 0,
            "elements": [
                "minecraft:stained_glass_pane@9"
            ]
        },
        {
            "x": -3,
            "y": 1,
            "z": 8,
            "elements": [
                "appliedenergistics2:fluix_stairs@3"
            ]
        },
        {
            "x": -2,
            "y": 1,
            "z": 8,
            "elements": [
                "appliedenergistics2:fluix_stairs@3"
            ]
        },
        {
            "x": -1,
            "y": 1,
            "z": 8,
            "elements": [
                "appliedenergistics2:fluix_stairs@3"
            ]
        },
        {
            "x": 0,
            "y": 3,
            "z": 9,
            "elements": [
                "modularmachinery:blockcasing@0"
            ]
        },
        {
            "x": 0,
            "y": 1,
            "z": 8,
            "elements": [
                "appliedenergistics2:fluix_stairs@3"
            ]
        },
        {
            "x": 1,
            "y": 1,
            "z": 8,
            "elements": [
                "appliedenergistics2:fluix_stairs@3"
            ]
        },
        {
            "x": 2,
            "y": 1,
            "z": 8,
            "elements": [
                "appliedenergistics2:fluix_stairs@3"
            ]
        },
        {
            "x": 3,
            "y": 1,
            "z": 8,
            "elements": [
                "appliedenergistics2:fluix_stairs@1"
            ]
        },
        {
            "x": 5,
            "y": 3,
            "z": 9,
            "elements": [
                "minecraft:stained_glass_pane@9"
            ]
        },
        {
            "x": 5,
            "y": 1,
            "z": 8,
            "elements": [
                "minecraft:stained_glass_pane@9"
            ]
        },
        {
            "x": -5,
            "y": 2,
            "z": 0,
            "elements": [
                "minecraft:stained_glass_pane@9"
            ]
        },
        {
            "x": -4,
            "y": 2,
            "z": 0,
            "elements": [
                "minecraft:stained_glass_pane@9"
            ]
        },
        {
            "x": -3,
            "y": 2,
            "z": 0,
            "elements": [
                "minecraft:stained_glass_pane@9"
            ]
        },
        {
            "x": -1,
            "y": 6,
            "z": 2,
            "elements": [
                "botania:storage@3"
            ]
        },
        {
            "x": 0,
            "y": 6,
            "z": 2,
            "elements": [
                "botania:storage@3"
            ]
        },
        {
            "x": 1,
            "y": 6,
            "z": 2,
            "elements": [
                "botania:storage@3"
            ]
        },
        {
            "x": 3,
            "y": 2,
            "z": 0,
            "elements": [
                "minecraft:stained_glass_pane@9"
            ]
        },
        {
            "x": -5,
            "y": 2,
            "z": 8,
            "elements": [
                "minecraft:stained_glass_pane@9"
            ]
        },
        {
            "x": 4,
            "y": 2,
            "z": 0,
            "elements": [
                "minecraft:stained_glass_pane@9"
            ]
        },
        {
            "x": -5,
            "y": 0,
            "z": 7,
            "elements": [
                "minecraft:concrete@3"
            ]
        },
        {
            "x": 5,
            "y": 2,
            "z": 0,
            "elements": [
                "minecraft:stained_glass_pane@9"
            ]
        },
        {
            "x": -4,
            "y": 0,
            "z": 7,
            "elements": [
                "botania:storage@3"
            ]
        },
        {
            "x": -3,
            "y": 0,
            "z": 7,
            "elements": [
                "botania:quartztypemana@0"
            ]
        },
        {
            "x": 0,
            "y": 6,
            "z": 10,
            "elements": [
                "modularmachinery:blockcasing@3"
            ]
        },
        {
            "x": -2,
            "y": 0,
            "z": 7,
            "elements": [
                "botania:storage@4"
            ]
        },
        {
            "x": 0,
            "y": 4,
            "z": 9,
            "elements": [
                "modularmachinery:blockcasing@0"
            ]
        },
        {
            "x": -1,
            "y": 0,
            "z": 7,
            "elements": [
                "botania:quartztypemana@0"
            ]
        },
        {
            "x": 0,
            "y": 0,
            "z": 7,
            "elements": [
                "botania:quartztypemana@0"
            ]
        },
        {
            "x": 1,
            "y": 0,
            "z": 7,
            "elements": [
                "botania:quartztypemana@0"
            ]
        },
        {
            "x": 2,
            "y": 0,
            "z": 7,
            "elements": [
                "botania:storage@4"
            ]
        },
        {
            "x": 3,
            "y": 0,
            "z": 7,
            "elements": [
                "botania:quartztypemana@0"
            ]
        },
        {
            "x": 4,
            "y": 0,
            "z": 7,
            "elements": [
                "botania:storage@3"
            ]
        },
        {
            "x": 5,
            "y": 2,
            "z": 8,
            "elements": [
                "minecraft:stained_glass_pane@9"
            ]
        },
        {
            "x": 5,
            "y": 0,
            "z": 7,
            "elements": [
                "minecraft:concrete@3"
            ]
        },
        {
            "x": -5,
            "y": 3,
            "z": 0,
            "elements": [
                "minecraft:stained_glass_pane@9"
            ]
        },
        {
            "x": -4,
            "y": 3,
            "z": 0,
            "elements": [
                "minecraft:stained_glass_pane@9"
            ]
        },
        {
            "x": 4,
            "y": 3,
            "z": 0,
            "elements": [
                "minecraft:stained_glass_pane@9"
            ]
        },
        {
            "x": -5,
            "y": 1,
            "z": 7,
            "elements": [
                "minecraft:stained_glass_pane@9"
            ]
        },
        {
            "x": 5,
            "y": 3,
            "z": 0,
            "elements": [
                "minecraft:stained_glass_pane@9"
            ]
        },
        {
            "x": -3,
            "y": 1,
            "z": 7,
            "elements": [
                "appliedenergistics2:fluix_stairs@0"
            ]
        },
        {
            "x": -2,
            "y": 1,
            "z": 7,
            "elements": [
                "avaritia:block_resource@0"
            ]
        },
        {
            "x": 0,
            "y": 5,
            "z": 9,
            "elements": [
                "modularmachinery:blockcasing@0"
            ]
        },
        {
            "x": -1,
            "y": 1,
            "z": 7,
            "elements": [
                "minecraft:light_blue_glazed_terracotta@1"
            ]
        },
        {
            "x": 0,
            "y": 1,
            "z": 7,
            "elements": [
                "minecraft:light_blue_glazed_terracotta@1"
            ]
        },
        {
            "x": 1,
            "y": 1,
            "z": 7,
            "elements": [
                "minecraft:light_blue_glazed_terracotta@1"
            ]
        },
        {
            "x": 2,
            "y": 1,
            "z": 7,
            "elements": [
                "avaritia:block_resource@0"
            ]
        },
        {
            "x": 3,
            "y": 1,
            "z": 7,
            "elements": [
                "appliedenergistics2:fluix_stairs@1"
            ]
        },
        {
            "x": 5,
            "y": 1,
            "z": 7,
            "elements": [
                "minecraft:stained_glass_pane@9"
            ]
        },
        {
            "x": -5,
            "y": 0,
            "z": 6,
            "elements": [
                "minecraft:concrete@3"
            ]
        },
        {
            "x": -4,
            "y": 0,
            "z": 6,
            "elements": [
                "botania:storage@3"
            ]
        },
        {
            "x": -3,
            "y": 0,
            "z": 6,
            "elements": [
                "botania:quartztypemana@0"
            ]
        },
        {
            "x": -2,
            "y": 2,
            "z": 7,
            "elements": [
                "botania:shimmerwoodplanks0stairs@3"
            ]
        },
        {
            "x": 0,
            "y": 6,
            "z": 9,
            "elements": [
                "modularmachinery:blockcasing@3"
            ]
        },
        {
            "x": -2,
            "y": 0,
            "z": 6,
            "elements": [
                "botania:quartztypemana@0"
            ]
        },
        {
            "x": -1,
            "y": 2,
            "z": 7,
            "elements": [
                "botania:shimmerwoodplanks0stairs@3"
            ]
        },
        {
            "x": -1,
            "y": 0,
            "z": 6,
            "elements": [
                "botania:storage@1"
            ]
        },
        {
            "x": 0,
            "y": 2,
            "z": 7,
            "elements": [
                "botania:shimmerwoodplanks0stairs@3"
            ]
        },
        {
            "x": 0,
            "y": 0,
            "z": 6,
            "elements": [
                "botania:storage@1"
            ]
        },
        {
            "x": 1,
            "y": 2,
            "z": 7,
            "elements": [
                "botania:shimmerwoodplanks0stairs@3"
            ]
        },
        {
            "x": 1,
            "y": 0,
            "z": 6,
            "elements": [
                "botania:storage@1"
            ]
        },
        {
            "x": 2,
            "y": 2,
            "z": 7,
            "elements": [
                "botania:shimmerwoodplanks0stairs@3"
            ]
        },
        {
            "x": 2,
            "y": 0,
            "z": 6,
            "elements": [
                "botania:quartztypemana@0"
            ]
        },
        {
            "x": 3,
            "y": 0,
            "z": 6,
            "elements": [
                "botania:quartztypemana@0"
            ]
        },
        {
            "x": 4,
            "y": 0,
            "z": 6,
            "elements": [
                "botania:storage@3"
            ]
        },
        {
            "x": 5,
            "y": 0,
            "z": 6,
            "elements": [
                "minecraft:concrete@3"
            ]
        },
        {
            "x": -3,
            "y": 1,
            "z": 6,
            "elements": [
                "appliedenergistics2:fluix_stairs@0"
            ]
        },
        {
            "x": -2,
            "y": 1,
            "z": 6,
            "elements": [
                "minecraft:light_blue_glazed_terracotta@1"
            ]
        },
        {
            "x": -1,
            "y": 1,
            "z": 6,
            "elements": [
                "tconstruct:metal@0"
            ]
        },
        {
            "x": 0,
            "y": 1,
            "z": 6,
            "elements": [
                "tconstruct:metal@0"
            ]
        },
        {
            "x": 1,
            "y": 1,
            "z": 6,
            "elements": [
                "tconstruct:metal@0"
            ]
        },
        {
            "x": 2,
            "y": 1,
            "z": 6,
            "elements": [
                "minecraft:light_blue_glazed_terracotta@2"
            ]
        },
        {
            "x": 3,
            "y": 1,
            "z": 6,
            "elements": [
                "appliedenergistics2:fluix_stairs@1"
            ]
        },
        {
            "x": -5,
            "y": 0,
            "z": 5,
            "elements": [
                "modularmachinery:blockinputbus"
            ]
        },
        {
            "x": -4,
            "y": 0,
            "z": 5,
            "elements": [
                "botania:storage@3"
            ]
        },
        {
            "x": -1,
            "y": 6,
            "z": 8,
            "elements": [
                "botania:storage@0"
            ]
        },
        {
            "x": -3,
            "y": 0,
            "z": 5,
            "elements": [
                "botania:quartztypemana@0"
            ]
        },
        {
            "x": -2,
            "y": 2,
            "z": 6,
            "elements": [
                "botania:shimmerwoodplanks0stairs@0"
            ]
        },
        {
            "x": 0,
            "y": 6,
            "z": 8,
            "elements": [
                "botania:storage@0"
            ]
        },
        {
            "x": -2,
            "y": 0,
            "z": 5,
            "elements": [
                "botania:quartztypemana@0"
            ]
        },
        {
            "x": -1,
            "y": 2,
            "z": 6,
            "elements": [
                "enderio:block_alloy@2"
            ]
        },
        {
            "x": 1,
            "y": 6,
            "z": 8,
            "elements": [
                "botania:storage@0"
            ]
        },
        {
            "x": -1,
            "y": 0,
            "z": 5,
            "elements": [
                "botania:storage@1"
            ]
        },
        {
            "x": 0,
            "y": 2,
            "z": 6,
            "elements": [
                "enderio:block_alloy@2"
            ]
        },
        {
            "x": 0,
            "y": 0,
            "z": 5,
            "elements": [
                "botania:storage@0"
            ]
        },
        {
            "x": 1,
            "y": 2,
            "z": 6,
            "elements": [
                "enderio:block_alloy@2"
            ]
        },
        {
            "x": 1,
            "y": 0,
            "z": 5,
            "elements": [
                "botania:storage@1"
            ]
        },
        {
            "x": 2,
            "y": 2,
            "z": 6,
            "elements": [
                "botania:shimmerwoodplanks0stairs@1"
            ]
        },
        {
            "x": 2,
            "y": 0,
            "z": 5,
            "elements": [
                "botania:quartztypemana@0"
            ]
        },
        {
            "x": 3,
            "y": 0,
            "z": 5,
            "elements": [
                "botania:quartztypemana@0"
            ]
        },
        {
            "x": 4,
            "y": 0,
            "z": 5,
            "elements": [
                "botania:storage@3"
            ]
        },
        {
            "x": 5,
            "y": 0,
            "z": 5,
            "elements": [
                "modularmachinery:blockenergyinputhatch"
            ]
        },
        {
            "x": -4,
            "y": 1,
            "z": 5,
            "elements": [
                "modularmachinery:blockcasing@0"
            ]
        },
        {
            "x": -3,
            "y": 1,
            "z": 5,
            "elements": [
                "appliedenergistics2:fluix_stairs@0"
            ]
        },
        {
            "x": -2,
            "y": 1,
            "z": 5,
            "elements": [
                "minecraft:light_blue_glazed_terracotta@1"
            ]
        },
        {
            "x": -1,
            "y": 1,
            "z": 5,
            "elements": [
                "tconstruct:metal@0"
            ]
        },
        {
            "x": 0,
            "y": 1,
            "z": 5,
            "elements": [
                "minecraft:beacon@0"
            ]
        },
        {
            "x": 1,
            "y": 1,
            "z": 5,
            "elements": [
                "tconstruct:metal@0"
            ]
        },
        {
            "x": 2,
            "y": 1,
            "z": 5,
            "elements": [
                "minecraft:light_blue_glazed_terracotta@2"
            ]
        },
        {
            "x": 3,
            "y": 1,
            "z": 5,
            "elements": [
                "appliedenergistics2:fluix_stairs@1"
            ]
        },
        {
            "x": 4,
            "y": 1,
            "z": 5,
            "elements": [
                "modularmachinery:blockcasing@0"
            ]
        },
        {
            "x": -5,
            "y": 0,
            "z": 4,
            "elements": [
                "minecraft:concrete@3"
            ]
        },
        {
            "x": -4,
            "y": 2,
            "z": 5,
            "elements": [
                "modularmachinery:blockcasing@0"
            ]
        },
        {
            "x": -4,
            "y": 0,
            "z": 4,
            "elements": [
                "botania:storage@3"
            ]
        },
        {
            "x": -1,
            "y": 6,
            "z": 7,
            "elements": [
                "modularmachinery:blockcasing@3"
            ]
        },
        {
            "x": -3,
            "y": 0,
            "z": 4,
            "elements": [
                "botania:quartztypemana@0"
            ]
        },
        {
            "x": -2,
            "y": 2,
            "z": 5,
            "elements": [
                "botania:shimmerwoodplanks0stairs@0"
            ]
        },
        {
            "x": 0,
            "y": 6,
            "z": 7,
            "elements": [
                "modularmachinery:blockcasing@4"
            ]
        },
        {
            "x": -2,
            "y": 0,
            "z": 4,
            "elements": [
                "botania:quartztypemana@0"
            ]
        },
        {
            "x": -1,
            "y": 2,
            "z": 5,
            "elements": [
                "enderio:block_alloy@2"
            ]
        },
        {
            "x": 1,
            "y": 6,
            "z": 7,
            "elements": [
                "modularmachinery:blockcasing@3"
            ]
        },
        {
            "x": -1,
            "y": 0,
            "z": 4,
            "elements": [
                "botania:storage@1"
            ]
        },
        {
            "x": 0,
            "y": 2,
            "z": 5,
            "elements": [
                "botania:managlass@0"
            ]
        },
        {
            "x": 0,
            "y": 0,
            "z": 4,
            "elements": [
                "botania:storage@1"
            ]
        },
        {
            "x": 1,
            "y": 2,
            "z": 5,
            "elements": [
                "enderio:block_alloy@2"
            ]
        },
        {
            "x": 1,
            "y": 0,
            "z": 4,
            "elements": [
                "botania:storage@1"
            ]
        },
        {
            "x": 2,
            "y": 2,
            "z": 5,
            "elements": [
                "botania:shimmerwoodplanks0stairs@1"
            ]
        },
        {
            "x": 2,
            "y": 0,
            "z": 4,
            "elements": [
                "botania:quartztypemana@0"
            ]
        },
        {
            "x": 3,
            "y": 0,
            "z": 4,
            "elements": [
                "botania:quartztypemana@0"
            ]
        },
        {
            "x": 4,
            "y": 2,
            "z": 5,
            "elements": [
                "modularmachinery:blockcasing@0"
            ]
        },
        {
            "x": 4,
            "y": 0,
            "z": 4,
            "elements": [
                "botania:storage@3"
            ]
        },
        {
            "x": 5,
            "y": 0,
            "z": 4,
            "elements": [
                "minecraft:concrete@3"
            ]
        },
        {
            "x": -4,
            "y": 3,
            "z": 5,
            "elements": [
                "modularmachinery:blockcasing@0"
            ]
        },
        {
            "x": -3,
            "y": 1,
            "z": 4,
            "elements": [
                "appliedenergistics2:fluix_stairs@0"
            ]
        },
        {
            "x": -2,
            "y": 1,
            "z": 4,
            "elements": [
                "minecraft:light_blue_glazed_terracotta@1"
            ]
        },
        {
            "x": -1,
            "y": 1,
            "z": 4,
            "elements": [
                "tconstruct:metal@0"
            ]
        },
        {
            "x": 0,
            "y": 1,
            "z": 4,
            "elements": [
                "tconstruct:metal@0"
            ]
        },
        {
            "x": 1,
            "y": 1,
            "z": 4,
            "elements": [
                "tconstruct:metal@0"
            ]
        },
        {
            "x": 2,
            "y": 1,
            "z": 4,
            "elements": [
                "minecraft:light_blue_glazed_terracotta@2"
            ]
        },
        {
            "x": 3,
            "y": 1,
            "z": 4,
            "elements": [
                "appliedenergistics2:fluix_stairs@1"
            ]
        },
        {
            "x": 4,
            "y": 3,
            "z": 5,
            "elements": [
                "modularmachinery:blockcasing@0"
            ]
        },
        {
            "x": -4,
            "y": 4,
            "z": 5,
            "elements": [
                "modularmachinery:blockcasing@0"
            ]
        },
        {
            "x": -3,
            "y": 6,
            "z": 6,
            "elements": [
                "botania:storage@0"
            ]
        },
        {
            "x": -5,
            "y": 0,
            "z": 3,
            "elements": [
                "minecraft:concrete@3"
            ]
        },
        {
            "x": -2,
            "y": 6,
            "z": 6,
            "elements": [
                "modularmachinery:blockcasing@3"
            ]
        },
        {
            "x": -4,
            "y": 0,
            "z": 3,
            "elements": [
                "botania:storage@3"
            ]
        },
        {
            "x": -1,
            "y": 6,
            "z": 6,
            "elements": [
                "modularmachinery:blockcasing@4"
            ]
        },
        {
            "x": -3,
            "y": 0,
            "z": 3,
            "elements": [
                "botania:quartztypemana@0"
            ]
        },
        {
            "x": -2,
            "y": 2,
            "z": 4,
            "elements": [
                "botania:shimmerwoodplanks0stairs@0"
            ]
        },
        {
            "x": 0,
            "y": 6,
            "z": 6,
            "elements": [
                "modularmachinery:blockcasing@1"
            ]
        },
        {
            "x": -2,
            "y": 0,
            "z": 3,
            "elements": [
                "botania:storage@4"
            ]
        },
        {
            "x": -1,
            "y": 2,
            "z": 4,
            "elements": [
                "enderio:block_alloy@2"
            ]
        },
        {
            "x": 1,
            "y": 6,
            "z": 6,
            "elements": [
                "modularmachinery:blockcasing@4"
            ]
        },
        {
            "x": -1,
            "y": 0,
            "z": 3,
            "elements": [
                "botania:quartztypemana@0"
            ]
        },
        {
            "x": 0,
            "y": 2,
            "z": 4,
            "elements": [
                "enderio:block_alloy@2"
            ]
        },
        {
            "x": 2,
            "y": 6,
            "z": 6,
            "elements": [
                "modularmachinery:blockcasing@3"
            ]
        },
        {
            "x": 0,
            "y": 0,
            "z": 3,
            "elements": [
                "botania:quartztypemana@0"
            ]
        },
        {
            "x": 1,
            "y": 2,
            "z": 4,
            "elements": [
                "enderio:block_alloy@2"
            ]
        },
        {
            "x": 3,
            "y": 6,
            "z": 6,
            "elements": [
                "botania:storage@0"
            ]
        },
        {
            "x": 1,
            "y": 0,
            "z": 3,
            "elements": [
                "botania:quartztypemana@0"
            ]
        },
        {
            "x": 2,
            "y": 2,
            "z": 4,
            "elements": [
                "botania:shimmerwoodplanks0stairs@1"
            ]
        },
        {
            "x": 2,
            "y": 0,
            "z": 3,
            "elements": [
                "botania:storage@4"
            ]
        },
        {
            "x": 4,
            "y": 4,
            "z": 5,
            "elements": [
                "modularmachinery:blockcasing@0"
            ]
        },
        {
            "x": 3,
            "y": 0,
            "z": 3,
            "elements": [
                "botania:quartztypemana@0"
            ]
        },
        {
            "x": 4,
            "y": 0,
            "z": 3,
            "elements": [
                "botania:storage@3"
            ]
        },
        {
            "x": 5,
            "y": 0,
            "z": 3,
            "elements": [
                "minecraft:concrete@3"
            ]
        },
        {
            "x": -4,
            "y": 5,
            "z": 5,
            "elements": [
                "modularmachinery:blockcasing@0"
            ]
        },
        {
            "x": -5,
            "y": 1,
            "z": 3,
            "elements": [
                "minecraft:stained_glass_pane@9"
            ]
        },
        {
            "x": -3,
            "y": 1,
            "z": 3,
            "elements": [
                "appliedenergistics2:fluix_stairs@0"
            ]
        },
        {
            "x": -2,
            "y": 1,
            "z": 3,
            "elements": [
                "avaritia:block_resource@0"
            ]
        },
        {
            "x": -1,
            "y": 3,
            "z": 4,
            "elements": [
                "botania:storage@1"
            ]
        },
        {
            "x": -1,
            "y": 1,
            "z": 3,
            "elements": [
                "minecraft:light_blue_glazed_terracotta@1"
            ]
        },
        {
            "x": 0,
            "y": 3,
            "z": 4,
            "elements": [
                "modularmachinery:blockcasing@3"
            ]
        },
        {
            "x": 0,
            "y": 1,
            "z": 3,
            "elements": [
                "minecraft:light_blue_glazed_terracotta@1"
            ]
        },
        {
            "x": 1,
            "y": 3,
            "z": 4,
            "elements": [
                "botania:storage@1"
            ]
        },
        {
            "x": 1,
            "y": 1,
            "z": 3,
            "elements": [
                "minecraft:light_blue_glazed_terracotta@1"
            ]
        },
        {
            "x": 2,
            "y": 1,
            "z": 3,
            "elements": [
                "avaritia:block_resource@0"
            ]
        },
        {
            "x": 4,
            "y": 5,
            "z": 5,
            "elements": [
                "modularmachinery:blockcasing@0"
            ]
        },
        {
            "x": 3,
            "y": 1,
            "z": 3,
            "elements": [
                "appliedenergistics2:fluix_stairs@1"
            ]
        },
        {
            "x": 5,
            "y": 1,
            "z": 3,
            "elements": [
                "minecraft:stained_glass_pane@9"
            ]
        },
        {
            "x": -6,
            "y": 6,
            "z": 5,
            "elements": [
                "modularmachinery:blockcasing@3"
            ]
        },
        {
            "x": -5,
            "y": 6,
            "z": 5,
            "elements": [
                "modularmachinery:blockcasing@3"
            ]
        },
        {
            "x": -4,
            "y": 6,
            "z": 5,
            "elements": [
                "modularmachinery:blockcasing@3"
            ]
        },
        {
            "x": -3,
            "y": 6,
            "z": 5,
            "elements": [
                "botania:storage@0"
            ]
        },
        {
            "x": -5,
            "y": 0,
            "z": 2,
            "elements": [
                "minecraft:concrete@3"
            ]
        },
        {
            "x": -2,
            "y": 6,
            "z": 5,
            "elements": [
                "modularmachinery:blockcasing@4"
            ]
        },
        {
            "x": -4,
            "y": 0,
            "z": 2,
            "elements": [
                "botania:storage@3"
            ]
        },
        {
            "x": -1,
            "y": 6,
            "z": 5,
            "elements": [
                "modularmachinery:blockcasing@3"
            ]
        },
        {
            "x": -3,
            "y": 0,
            "z": 2,
            "elements": [
                "botania:storage@4"
            ]
        },
        {
            "x": -2,
            "y": 2,
            "z": 3,
            "elements": [
                "botania:shimmerwoodplanks0stairs@2"
            ]
        },
        {
            "x": -1,
            "y": 4,
            "z": 4,
            "elements": [
                "modularmachinery:blockcasing@1"
            ]
        },
        {
            "x": 0,
            "y": 6,
            "z": 5,
            "elements": [
                "extrabotany:blockorichalcos@0"
            ]
        },
        {
            "x": -2,
            "y": 0,
            "z": 2,
            "elements": [
                "botania:quartztypemana@0"
            ]
        },
        {
            "x": -1,
            "y": 2,
            "z": 3,
            "elements": [
                "botania:shimmerwoodplanks0stairs@2"
            ]
        },
        {
            "x": 1,
            "y": 6,
            "z": 5,
            "elements": [
                "modularmachinery:blockcasing@3"
            ]
        },
        {
            "x": -1,
            "y": 0,
            "z": 2,
            "elements": [
                "botania:quartztypemana@0"
            ]
        },
        {
            "x": 0,
            "y": 2,
            "z": 3,
            "elements": [
                "botania:shimmerwoodplanks0stairs@2"
            ]
        },
        {
            "x": 1,
            "y": 4,
            "z": 4,
            "elements": [
                "modularmachinery:blockcasing@1"
            ]
        },
        {
            "x": 2,
            "y": 6,
            "z": 5,
            "elements": [
                "modularmachinery:blockcasing@4"
            ]
        },
        {
            "x": 0,
            "y": 0,
            "z": 2,
            "elements": [
                "botania:quartztypemana@0"
            ]
        },
        {
            "x": 1,
            "y": 2,
            "z": 3,
            "elements": [
                "botania:shimmerwoodplanks0stairs@2"
            ]
        },
        {
            "x": 3,
            "y": 6,
            "z": 5,
            "elements": [
                "botania:storage@0"
            ]
        },
        {
            "x": 1,
            "y": 0,
            "z": 2,
            "elements": [
                "botania:quartztypemana@0"
            ]
        },
        {
            "x": 2,
            "y": 2,
            "z": 3,
            "elements": [
                "botania:shimmerwoodplanks0stairs@1"
            ]
        },
        {
            "x": 4,
            "y": 6,
            "z": 5,
            "elements": [
                "modularmachinery:blockcasing@3"
            ]
        },
        {
            "x": 2,
            "y": 0,
            "z": 2,
            "elements": [
                "botania:quartztypemana@0"
            ]
        },
        {
            "x": 5,
            "y": 6,
            "z": 5,
            "elements": [
                "modularmachinery:blockcasing@3"
            ]
        },
        {
            "x": 3,
            "y": 0,
            "z": 2,
            "elements": [
                "botania:storage@4"
            ]
        },
        {
            "x": 6,
            "y": 6,
            "z": 5,
            "elements": [
                "modularmachinery:blockcasing@3"
            ]
        },
        {
            "x": -5,
            "y": 0,
            "z": 10,
            "elements": [
                "minecraft:light_blue_glazed_terracotta@2"
            ]
        },
        {
            "x": 4,
            "y": 0,
            "z": 2,
            "elements": [
                "botania:storage@3"
            ]
        },
        {
            "x": -4,
            "y": 0,
            "z": 10,
            "elements": [
                "minecraft:concrete@3"
            ]
        },
        {
            "x": 5,
            "y": 0,
            "z": 2,
            "elements": [
                "minecraft:concrete@3"
            ]
        },
        {
            "x": -3,
            "y": 0,
            "z": 10,
            "elements": [
                "minecraft:concrete@3"
            ]
        },
        {
            "x": -2,
            "y": 0,
            "z": 10,
            "elements": [
                "minecraft:concrete@3"
            ]
        },
        {
            "x": -1,
            "y": 0,
            "z": 10,
            "elements": [
                "gugu-utils:sparkmanahatch@1"
            ]
        },
        {
            "x": 0,
            "y": 0,
            "z": 10,
            "elements": [
                "modularmachinery:blockoutputbus"
            ]
        },
        {
            "x": 1,
            "y": 0,
            "z": 10,
            "elements": [
                "gugu-utils:sparkmanahatch@1"
            ]
        },
        {
            "x": 2,
            "y": 0,
            "z": 10,
            "elements": [
                "minecraft:concrete@3"
            ]
        },
        {
            "x": 3,
            "y": 0,
            "z": 10,
            "elements": [
                "minecraft:concrete@3"
            ]
        },
        {
            "x": 4,
            "y": 0,
            "z": 10,
            "elements": [
                "minecraft:concrete@3"
            ]
        },
        {
            "x": 5,
            "y": 0,
            "z": 10,
            "elements": [
                "minecraft:light_blue_glazed_terracotta@1"
            ]
        },
        {
            "x": -5,
            "y": 1,
            "z": 2,
            "elements": [
                "minecraft:stained_glass_pane@9"
            ]
        },
        {
            "x": -3,
            "y": 1,
            "z": 2,
            "elements": [
                "appliedenergistics2:fluix_stairs@2"
            ]
        },
        {
            "x": -1,
            "y": 5,
            "z": 4,
            "elements": [
                "botania:storage@1"
            ]
        },
        {
            "x": -2,
            "y": 1,
            "z": 2,
            "elements": [
                "appliedenergistics2:fluix_stairs@2"
            ]
        },
        {
            "x": 0,
            "y": 5,
            "z": 4,
            "elements": [
                "modularmachinery:blockcasing@4"
            ]
        },
        {
            "x": -1,
            "y": 1,
            "z": 2,
            "elements": [
                "appliedenergistics2:fluix_stairs@2"
            ]
        },
        {
            "x": 1,
            "y": 5,
            "z": 4,
            "elements": [
                "botania:storage@1"
            ]
        },
        {
            "x": 0,
            "y": 1,
            "z": 2,
            "elements": [
                "appliedenergistics2:fluix_stairs@2"
            ]
        },
        {
            "x": 1,
            "y": 1,
            "z": 2,
            "elements": [
                "appliedenergistics2:fluix_stairs@2"
            ]
        },
        {
            "x": 2,
            "y": 1,
            "z": 2,
            "elements": [
                "appliedenergistics2:fluix_stairs@2"
            ]
        },
        {
            "x": 3,
            "y": 1,
            "z": 2,
            "elements": [
                "appliedenergistics2:fluix_stairs@2"
            ]
        },
        {
            "x": -5,
            "y": 1,
            "z": 10,
            "elements": [
                "minecraft:stained_glass_pane@9"
            ]
        },
        {
            "x": -4,
            "y": 1,
            "z": 10,
            "elements": [
                "minecraft:stained_glass_pane@9"
            ]
        },
        {
            "x": 5,
            "y": 1,
            "z": 2,
            "elements": [
                "minecraft:stained_glass_pane@9"
            ]
        },
        {
            "x": -3,
            "y": 1,
            "z": 10,
            "elements": [
                "minecraft:stained_glass_pane@9"
            ]
        },
        {
            "x": -2,
            "y": 1,
            "z": 10,
            "elements": [
                "minecraft:stained_glass_pane@9"
            ]
        },
        {
            "x": 2,
            "y": 1,
            "z": 10,
            "elements": [
                "minecraft:stained_glass_pane@9"
            ]
        },
        {
            "x": 3,
            "y": 1,
            "z": 10,
            "elements": [
                "minecraft:stained_glass_pane@9"
            ]
        },
        {
            "x": 4,
            "y": 1,
            "z": 10,
            "elements": [
                "minecraft:stained_glass_pane@9"
            ]
        },
        {
            "x": 5,
            "y": 1,
            "z": 10,
            "elements": [
                "minecraft:stained_glass_pane@9"
            ]
        },
        {
            "x": -5,
            "y": 2,
            "z": 2,
            "elements": [
                "minecraft:stained_glass_pane@9"
            ]
        },
        {
            "x": -3,
            "y": 6,
            "z": 4,
            "elements": [
                "botania:storage@0"
            ]
        },
        {
            "x": -5,
            "y": 0,
            "z": 1,
            "elements": [
                "minecraft:concrete@3"
            ]
        },
        {
            "x": -2,
            "y": 6,
            "z": 4,
            "elements": [
                "modularmachinery:blockcasing@3"
            ]
        },
        {
            "x": -4,
            "y": 0,
            "z": 1,
            "elements": [
                "botania:storage@3"
            ]
        },
        {
            "x": -1,
            "y": 6,
            "z": 4,
            "elements": [
                "modularmachinery:blockcasing@4"
            ]
        },
        {
            "x": -3,
            "y": 0,
            "z": 1,
            "elements": [
                "botania:storage@3"
            ]
        },
        {
            "x": 0,
            "y": 6,
            "z": 4,
            "elements": [
                "modularmachinery:blockcasing@1"
            ]
        },
        {
            "x": -2,
            "y": 0,
            "z": 1,
            "elements": [
                "botania:storage@3"
            ]
        },
        {
            "x": 1,
            "y": 6,
            "z": 4,
            "elements": [
                "modularmachinery:blockcasing@4"
            ]
        },
        {
            "x": -1,
            "y": 0,
            "z": 1,
            "elements": [
                "botania:storage@3"
            ]
        },
        {
            "x": 2,
            "y": 6,
            "z": 4,
            "elements": [
                "modularmachinery:blockcasing@3"
            ]
        },
        {
            "x": 0,
            "y": 0,
            "z": 1,
            "elements": [
                "botania:storage@3"
            ]
        },
        {
            "x": 3,
            "y": 6,
            "z": 4,
            "elements": [
                "botania:storage@0"
            ]
        },
        {
            "x": 1,
            "y": 0,
            "z": 1,
            "elements": [
                "botania:storage@3"
            ]
        },
        {
            "x": 2,
            "y": 0,
            "z": 1,
            "elements": [
                "botania:storage@3"
            ]
        },
        {
            "x": -5,
            "y": 2,
            "z": 10,
            "elements": [
                "minecraft:stained_glass_pane@9"
            ]
        },
        {
            "x": 3,
            "y": 0,
            "z": 1,
            "elements": [
                "botania:storage@3"
            ]
        },
        {
            "x": -5,
            "y": 0,
            "z": 9,
            "elements": [
                "minecraft:concrete@3"
            ]
        },
        {
            "x": -4,
            "y": 2,
            "z": 10,
            "elements": [
                "minecraft:stained_glass_pane@9"
            ]
        },
        {
            "x": 4,
            "y": 0,
            "z": 1,
            "elements": [
                "botania:storage@3"
            ]
        },
        {
            "x": 5,
            "y": 2,
            "z": 2,
            "elements": [
                "minecraft:stained_glass_pane@9"
            ]
        },
        {
            "x": -4,
            "y": 0,
            "z": 9,
            "elements": [
                "botania:storage@3"
            ]
        },
        {
            "x": -3,
            "y": 2,
            "z": 10,
            "elements": [
                "minecraft:stained_glass_pane@9"
            ]
        },
        {
            "x": 5,
            "y": 0,
            "z": 1,
            "elements": [
                "minecraft:concrete@3"
            ]
        },
        {
            "x": -3,
            "y": 0,
            "z": 9,
            "elements": [
                "botania:storage@3"
            ]
        },
        {
            "x": -2,
            "y": 0,
            "z": 9,
            "elements": [
                "botania:storage@3"
            ]
        },
        {
            "x": -1,
            "y": 0,
            "z": 9,
            "elements": [
                "botania:storage@3"
            ]
        },
        {
            "x": 0,
            "y": 0,
            "z": 9,
            "elements": [
                "botania:storage@3"
            ]
        },
        {
            "x": 1,
            "y": 0,
            "z": 9,
            "elements": [
                "botania:storage@3"
            ]
        },
        {
            "x": 2,
            "y": 0,
            "z": 9,
            "elements": [
                "botania:storage@3"
            ]
        },
        {
            "x": 3,
            "y": 2,
            "z": 10,
            "elements": [
                "minecraft:stained_glass_pane@9"
            ]
        },
        {
            "x": 3,
            "y": 0,
            "z": 9,
            "elements": [
                "botania:storage@3"
            ]
        },
        {
            "x": 4,
            "y": 2,
            "z": 10,
            "elements": [
                "minecraft:stained_glass_pane@9"
            ]
        },
        {
            "x": 4,
            "y": 0,
            "z": 9,
            "elements": [
                "botania:storage@3"
            ]
        },
        {
            "x": 5,
            "y": 2,
            "z": 10,
            "elements": [
                "minecraft:stained_glass_pane@9"
            ]
        },
        {
            "x": 5,
            "y": 0,
            "z": 9,
            "elements": [
                "minecraft:concrete@3"
            ]
        },
        {
            "x": -5,
            "y": 1,
            "z": 1,
            "elements": [
                "minecraft:stained_glass_pane@9"
            ]
        },
        {
            "x": -5,
            "y": 3,
            "z": 10,
            "elements": [
                "minecraft:stained_glass_pane@9"
            ]
        },
        {
            "x": -5,
            "y": 1,
            "z": 9,
            "elements": [
                "minecraft:stained_glass_pane@9"
            ]
        },
        {
            "x": -4,
            "y": 3,
            "z": 10,
            "elements": [
                "minecraft:stained_glass_pane@9"
            ]
        },
        {
            "x": 5,
            "y": 1,
            "z": 1,
            "elements": [
                "minecraft:stained_glass_pane@9"
            ]
        },
        {
            "x": 0,
            "y": 1,
            "z": 9,
            "elements": [
                "modularmachinery:blockcasing@0"
            ]
        },
        {
            "x": 4,
            "y": 3,
            "z": 10,
            "elements": [
                "minecraft:stained_glass_pane@9"
            ]
        },
        {
            "x": 5,
            "y": 3,
            "z": 10,
            "elements": [
                "minecraft:stained_glass_pane@9"
            ]
        },
        {
            "x": 5,
            "y": 1,
            "z": 9,
            "elements": [
                "minecraft:stained_glass_pane@9"
            ]
        },
        {
            "x": -5,
            "y": 2,
            "z": 1,
            "elements": [
                "minecraft:stained_glass_pane@9"
            ]
        },
        {
            "x": -1,
            "y": 6,
            "z": 3,
            "elements": [
                "modularmachinery:blockcasing@3"
            ]
        },
        {
            "x": 0,
            "y": 6,
            "z": 3,
            "elements": [
                "modularmachinery:blockcasing@4"
            ]
        },
        {
            "x": 1,
            "y": 6,
            "z": 3,
            "elements": [
                "modularmachinery:blockcasing@3"
            ]
        }
    ]}